Workbook

Sheet CS2
A1: Cầu số 1 | B1: Triều Lên | C1: HCM_NM_CS1_L | G1: Nơi thực hiện | H1: Vị trí quan trắc | I1: Số lượng mẫu | J1: Số lượng mẫu QC | K1: Ngày | L1: Ký hiệu
A2: Lê Văn Sỹ | B2: Triều Lên | C2: HCM_NM_LVS_L | G2: TBNM15 | H2: Triều Lên | I2: 1 | K2: 4 | L2: {=INDEX($A$1:$C$172,MATCH(1,($G2=$A$1:$A$172)*($H2=$B$1:$B$172),0),3)} -> HCM_NM_TBNM15_L
A3: Hải Đức | B3: Triều Lên | C3: HCM_NM_HĐ_L | G3: TBNM5 | H3: Triều Lên | I3: 1 | K3: 4 | L3: {=INDEX($A$1:$C$172,MATCH(1,($G3=$A$1:$A$172)*($H3=$B$1:$B$172),0),3)} -> HCM_NM_TBNM5_L
A4: Điện Biên Phủ | B4: Triều Lên | C4: HCM_NM_ĐBP_L | G4: Cầu Tân Thái | H4: Triều Lên | I4: 1 | K4: 4 | L4: {=INDEX($A$1:$C$172,MATCH(1,($G4=$A$1:$A$172)*($H4=$B$1:$B$172),0),3)} -> HCM_NM_CTT_L
A5: Bùi Đình Túy | B5: Triều Lên | C5: HCM_NM_BĐT_L | G5: TBNM14 | H5: Triều Lên | I5: 1 | K5: 4 | L5: {=INDEX($A$1:$C$172,MATCH(1,($G5=$A$1:$A$172)*($H5=$B$1:$B$172),0),3)} -> HCM_NM_TBNM14_L
A6: Cầu Đỏ | B6: Triều Lên | C6: HCM_NM_CĐ_L | G6: TBNM15 | H6: Triều Xuống | I6: 1 | K6: 4 | L6: {=INDEX($A$1:$C$172,MATCH(1,($G6=$A$1:$A$172)*($H6=$B$1:$B$172),0),3)} -> HCM_NM_TBNM15_X
A7: Thị Nghè 2 | B7: Triều Lên | C7: HCM_NM_TN2_L | G7: TBNM5 | H7: Triều Xuống | I7: 1 | K7: 4 | L7: {=INDEX($A$1:$C$172,MATCH(1,($G7=$A$1:$A$172)*($H7=$B$1:$B$172),0),3)} -> HCM_NM_TBNM5_X
A8: Bùi Hữu Nghĩa | B8: Triều Lên | C8: HCM_NM_BHN_L | G8: Cầu Tân Thái | H8: Triều Xuống | I8: 1 | J8: 1 | K8: 4 | L8: {=INDEX($A$1:$C$172,MATCH(1,($G8=$A$1:$A$172)*($H8=$B$1:$B$172),0),3)} -> HCM_NM_CTT_X
A9: Cầu Văn Thánh | B9: Triều Lên | C9: HCM_NM_RVT_L | G9: TBNM14 | H9: Triều Xuống | I9: 1 | K9: 4 | L9: {=INDEX($A$1:$C$172,MATCH(1,($G9=$A$1:$A$172)*($H9=$B$1:$B$172),0),3)} -> HCM_NM_TBNM14_X
A10: Cầu Văn Thánh 2 | B10: Triều Lên | C10: HCM_NM_RVT2_L | G10: TBNM9 | H10: Triều Lên | I10: 1 | J10: 1 | K10: 4 | L10: {=INDEX($A$1:$C$172,MATCH(1,($G10=$A$1:$A$172)*($H10=$B$1:$B$172),0),3)} -> HCM_NM_TBNM9_L
A11: Cầu số 1 | B11: Triều Xuống | C11: HCM_NM_CS1_X | G11: TBNM11 | H11: Triều Lên | I11: 1 | K11: 4 | L11: {=INDEX($A$1:$C$172,MATCH(1,($G11=$A$1:$A$172)*($H11=$B$1:$B$172),0),3)} -> HCM_NM_TBNM11_L
A12: Lê Văn Sỹ | B12: Triều Xuống | C12: HCM_NM_LVS_X | G12: TBNM1 | H12: Triều Lên | I12: 1 | K12: 4 | L12: {=INDEX($A$1:$C$172,MATCH(1,($G12=$A$1:$A$172)*($H12=$B$1:$B$172),0),3)} -> HCM_NM_TBNM1_L
A13: Hải Đức | B13: Triều Xuống | C13: HCM_NM_HĐ_X | G13: Thầy Cai | H13: Triều Lên | I13: 1 | K13: 4 | L13: {=INDEX($A$1:$C$172,MATCH(1,($G13=$A$1:$A$172)*($H13=$B$1:$B$172),0),3)} -> HCM_NM_TCa_L
A14: Điện Biên Phủ | B14: Triều Xuống | C14: HCM_NM_ĐBP_X | G14: TBNM9 | H14: Triều Xuống | I14: 1 | K14: 4 | L14: {=INDEX($A$1:$C$172,MATCH(1,($G14=$A$1:$A$172)*($H14=$B$1:$B$172),0),3)} -> HCM_NM_TBNM9_X
A15: Bùi Đình Túy | B15: Triều Xuống | C15: HCM_NM_BĐT_X | G15: TBNM11 | H15: Triều Xuống | I15: 1 | K15: 4 | L15: {=INDEX($A$1:$C$172,MATCH(1,($G15=$A$1:$A$172)*($H15=$B$1:$B$172),0),3)} -> HCM_NM_TBNM11_X
A16: Cầu Đỏ | B16: Triều Xuống | C16: HCM_NM_CĐ_X | G16: TBNM1 | H16: Triều Xuống | I16: 1 | K16: 4 | L16: {=INDEX($A$1:$C$172,MATCH(1,($G16=$A$1:$A$172)*($H16=$B$1:$B$172),0),3)} -> HCM_NM_TBNM1_X
A17: Thị Nghè 2 | B17: Triều Xuống | C17: HCM_NM_TN2_X | G17: Thầy Cai | H17: Triều Xuống | I17: 1 | K17: 4 | L17: {=INDEX($A$1:$C$172,MATCH(1,($G17=$A$1:$A$172)*($H17=$B$1:$B$172),0),3)} -> HCM_NM_TCa_X
A18: Bùi Hữu Nghĩa | B18: Triều Xuống | C18: HCM_NM_BHN_X | G18: Cầu Chữ Y | H18: Triều Lên | I18: 1 | K18: 5 | L18: {=INDEX($A$1:$C$172,MATCH(1,($G18=$A$1:$A$172)*($H18=$B$1:$B$172),0),3)} -> HCM_NM_CCY_L
A19: Cầu Văn Thánh | B19: Triều Xuống | C19: HCM_NM_RVT_X | G19: Chà Và | H19: Triều Lên | I19: 1 | K19: 5 | L19: {=INDEX($A$1:$C$172,MATCH(1,($G19=$A$1:$A$172)*($H19=$B$1:$B$172),0),3)} -> HCM_NM_CV_L
A20: Cầu Văn Thánh 2 | B20: Triều Xuống | C20: HCM_NM_RVT2_X | G20: Chánh Hưng | H20: Triều Lên | I20: 1 | K20: 5 | L20: {=INDEX($A$1:$C$172,MATCH(1,($G20=$A$1:$A$172)*($H20=$B$1:$B$172),0),3)} -> HCM_NM_CH_L
A21: TBNM15 | B21: Triều Lên | C21: HCM_NM_TBNM15_L | G21: Nhị Thiên Đường | H21: Triều Lên | I21: 1 | K21: 5 | L21: {=INDEX($A$1:$C$172,MATCH(1,($G21=$A$1:$A$172)*($H21=$B$1:$B$172),0),3)} -> HCM_NM_NTĐ_L
A22: TBNM5 | B22: Triều Lên | C22: HCM_NM_TBNM5_L | G22: Cầu Chữ Y | H22: Triều Xuống | I22: 1 | K22: 5 | L22: {=INDEX($A$1:$C$172,MATCH(1,($G22=$A$1:$A$172)*($H22=$B$1:$B$172),0),3)} -> HCM_NM_CCY_X
... A30: TBNM5 | B30: Triều Xuống | C30: HCM_NM_TBNM5_X | G30: Tân Thuận | H30: Triều Xuống | I30: 1 | K30: 5 | L30: {=INDEX($A$1:$C$172,MATCH(1,($G30=$A$1:$A$172)*($H30=$B$1:$B$172),0),3)} -> HCM_NM_TThu_X
A31: Cầu Tân Thái | B31: Triều Xuống | C31: HCM_NM_CTT_X | G31: Kênh Tẻ | H31: Triều Xuống | I31: 1 | J31: 2 | K31: 5 | L31: {=INDEX($A$1:$C$172,MATCH(1,($G31=$A$1:$A$172)*($H31=$B$1:$B$172),0),3)} -> HCM_NM_KT_X
A32: TBNM14 | B32: Triều Xuống | C32: HCM_NM_TBNM14_X | G32: Kênh N46 | H32: Triều Lên | I32: 1 | K32: 6 | L32: {=INDEX($A$1:$C$172,MATCH(1,($G32=$A$1:$A$172)*($H32=$B$1:$B$172),0),3)} -> HCM_NM_N46_L
A33: TBNM9 | B33: Triều Xuống | C33: HCM_NM_TBNM9_X | G33: Tân Phú Trung | H33: Triều Lên | I33: 1 | K33: 6 | L33: {=INDEX($A$1:$C$172,MATCH(1,($G33=$A$1:$A$172)*($H33=$B$1:$B$172),0),3)} -> HCM_NM_TPT_L
A34: TBNM11 | B34: Triều Xuống | C34: HCM_NM_TBNM11_X | G34: TC18A | H34: Triều Lên | I34: 1 | K34: 6 | L34: {=INDEX($A$1:$C$172,MATCH(1,($G34=$A$1:$A$172)*($H34=$B$1:$B$172),0),3)} -> HCM_NM_TC18A_L
A35: TBNM1 | B35: Triều Xuống | C35: HCM_NM_TBNM1_X | G35: An Hạ 1 | H35: Triều Lên | I35: 1 | J35: 1 | K35: 6 | L35: {=INDEX($A$1:$C$172,MATCH(1,($G35=$A$1:$A$172)*($H35=$B$1:$B$172),0),3)} -> HCM_NM_AH1_L
A36: Thầy Cai | B36: Triều Xuống | C36: HCM_NM_TCa_X | G36: Kênh N46 | H36: Triều Xuống | I36: 1 | K36: 6 | L36: {=INDEX($A$1:$C$172,MATCH(1,($G36=$A$1:$A$172)*($H36=$B$1:$B$172),0),3)} -> HCM_NM_N46_X
A37: Kênh N46 | B37: Triều Lên | C37: HCM_NM_N46_L | G37: Tân Phú Trung | H37: Triều Xuống | I37: 1 | J37: 1 | K37: 6 | L37: {=INDEX($A$1:$C$172,MATCH(1,($G37=$A$1:$A$172)*($H37=$B$1:$B$172),0),3)} -> HCM_NM_TPT_X
A38: Tân Phú Trung | B38: Triều Lên | C38: HCM_NM_TPT_L | G38: TC18A | H38: Triều Xuống | I38: 1 | K38: 6 | L38: {=INDEX($A$1:$C$172,MATCH(1,($G38=$A$1:$A$172)*($H38=$B$1:$B$172),0),3)} -> HCM_NM_TC18A_X
A39: TC18A | B39: Triều Lên | C39: HCM_NM_TC18A_L | G39: An Hạ 1 | H39: Triều Xuống | I39: 1 | K39: 6 | L39: {=INDEX($A$1:$C$172,MATCH(1,($G39=$A$1:$A$172)*($H39=$B$1:$B$172),0),3)} -> HCM_NM_AH1_X
A40: An Hạ 1 | B40: Triều Lên | C40: HCM_NM_AH1_L | G40: Cầu Đường A | H40: Triều Lên | I40: 1 | K40: 7 | L40: {=INDEX($A$1:$C$172,MATCH(1,($G40=$A$1:$A$172)*($H40=$B$1:$B$172),0),3)} -> HCM_NM_CĐA_L
A41: Cầu TL9 | B41: Triều Lên | C41: HCM_NM_CTL9_L | G41: Trung Tâm | H41: Triều Lên | I41: 1 | K41: 7 | L41: {=INDEX($A$1:$C$172,MATCH(1,($G41=$A$1:$A$172)*($H41=$B$1:$B$172),0),3)} -> HCM_NM_TrT_L
A42: Xuân Thới Sơn | B42: Triều Lên | C42: HCM_NM_XTS_L | G42: Nước Lên | H42: Triều Lên | I42: 1 | K42: 7 | L42: {=INDEX($A$1:$C$172,MATCH(1,($G42=$A$1:$A$172)*($H42=$B$1:$B$172),0),3)} -> HCM_NM_NL_L
A43: Cầu Lớn | B43: Triều Lên | C43: HCM_NM_CLo_L | G43: Lương Bèo | H43: Triều Lên | I43: 1 | K43: 7 | L43: {=INDEX($A$1:$C$172,MATCH(1,($G43=$A$1:$A$172)*($H43=$B$1:$B$172),0),3)} -> HCM_NM_LB_L
A44: An Hạ | B44: Triều Lên | C44: HCM_NM_AH_L | G44: Cầu Đường A | H44: Triều Xuống | I44: 1 | K44: 7 | L44: {=INDEX($A$1:$C$172,MATCH(1,($G44=$A$1:$A$172)*($H44=$B$1:$B$172),0),3)} -> HCM_NM_CĐA_X
A45: Rau Răm | B45: Triều Lên | C45: HCM_NM_RR_L | G45: Trung Tâm | H45: Triều Xuống | I45: 1 | K45: 7 | L45: {=INDEX($A$1:$C$172,MATCH(1,($G45=$A$1:$A$172)*($H45=$B$1:$B$172),0),3)} -> HCM_NM_TrT_X
A46: Kênh N46 | B46: Triều Xuống | C46: HCM_NM_N46_X | G46: Nước Lên | H46: Triều Xuống | I46: 1 | K46: 7 | L46: {=INDEX($A$1:$C$172,MATCH(1,($G46=$A$1:$A$172)*($H46=$B$1:$B$172),0),3)} -> HCM_NM_NL_X
A47: Tân Phú Trung | B47: Triều Xuống | C47: HCM_NM_TPT_X | G47: Lương Bèo | H47: Triều Xuống | I47: 1 | K47: 7 | L47: {=INDEX($A$1:$C$172,MATCH(1,($G47=$A$1:$A$172)*($H47=$B$1:$B$172),0),3)} -> HCM_NM_LB_X
...

Sheet CS3
A1: Bình Lợi | B1: Triều Lên | C1: HCM_NM_BL_L | G1: Nơi thực hiện | H1: Vị trí quan trắc | I1: Số lượng mẫu | J1: Số lượng mẫu QC | K1: Ngày | L1: Ký hiệu
A2: Sài Gòn | B2: Triều Lên | C2: HCM_NM_SG_L | G2: Lòng Tàu 1 | H2: Triều Lên | I2: 1 | K2: 25 | L2: {=INDEX($A$1:$C$172,MATCH(1,($G2=$A$1:$A$172)*($H2=$B$1:$B$172),0),3)} -> HCM_NM_LT1_L
A3: Phú Mỹ | B3: Triều Lên | C3: HCM_NM_PM_L | G3: Lòng Tàu | H3: Triều Lên | I3: 1 | K3: 25 | L3: {=INDEX($A$1:$C$172,MATCH(1,($G3=$A$1:$A$172)*($H3=$B$1:$B$172),0),3)} -> HCM_NM_LT_L
A4: Mũi Đèn Đỏ | B4: Triều Lên | C4: HCM_NM_MĐĐ_L | G4: Tam Thôn Hiệp | H4: Triều Lên | I4: 1 | K4: 25 | L4: {=INDEX($A$1:$C$172,MATCH(1,($G4=$A$1:$A$172)*($H4=$B$1:$B$172),0),3)} -> HCM_NM_TTH_L
A5: Nhà Bè | B5: Triều Lên | C5: HCM_NM_NB_L | G5: Đồng Tranh 1 | H5: Triều Lên | I5: 1 | K5: 25 | L5: {=INDEX($A$1:$C$172,MATCH(1,($G5=$A$1:$A$172)*($H5=$B$1:$B$172),0),3)} -> HCM_NM_ĐT1_L
A6: Bình Lợi | B6: Triều Xuống | C6: HCM_NM_BL_X | G6: Lòng Tàu 1 | H6: Triều Xuống | I6: 1 | K6: 25 | L6: {=INDEX($A$1:$C$172,MATCH(1,($G6=$A$1:$A$172)*($H6=$B$1:$B$172),0),3)} -> HCM_NM_LT1_X
A7: Sài Gòn | B7: Triều Xuống | C7: HCM_NM_SG_X | G7: Lòng Tàu | H7: Triều Xuống | I7: 1 | K7: 25 | L7: {=INDEX($A$1:$C$172,MATCH(1,($G7=$A$1:$A$172)*($H7=$B$1:$B$172),0),3)} -> HCM_NM_LT_X
A8: Phú Mỹ | B8: Triều Xuống | C8: HCM_NM_PM_X | G8: Tam Thôn Hiệp | H8: Triều Xuống | I8: 1 | K8: 25 | L8: {=INDEX($A$1:$C$172,MATCH(1,($G8=$A$1:$A$172)*($H8=$B$1:$B$172),0),3)} -> HCM_NM_TTH_X
A9: Mũi Đèn Đỏ | B9: Triều Xuống | C9: HCM_NM_MĐĐ_X | G9: Đồng Tranh 1 | H9: Triều Xuống | I9: 1 | K9: 25 | L9: {=INDEX($A$1:$C$172,MATCH(1,($G9=$A$1:$A$172)*($H9=$B$1:$B$172),0),3)} -> HCM_NM_ĐT1_X
A10: Nhà Bè | B10: Triều Xuống | C10: HCM_NM_NB_X | G10: Bình Lợi | H10: Triều Lên | I10: 1 | K10: 25 | L10: {=INDEX($A$1:$C$172,MATCH(1,($G10=$A$1:$A$172)*($H10=$B$1:$B$172),0),3)} -> HCM_NM_BL_L
A11: Long Phước | B11: Triều Lên | C11: HCM_NM_LP_L | G11: Sài Gòn | H11: Triều Lên | I11: 1 | K11: 25 | L11: {=INDEX($A$1:$C$172,MATCH(1,($G11=$A$1:$A$172)*($H11=$B$1:$B$172),0),3)} -> HCM_NM_SG_L
A12: Cát Lái | B12: Triều Lên | C12: HCM_NM_CL_L | G12: Bình Lợi | H12: Triều Xuống | I12: 1 | K12: 25 | L12: {=INDEX($A$1:$C$172,MATCH(1,($G12=$A$1:$A$172)*($H12=$B$1:$B$172),0),3)} -> HCM_NM_BL_X
A13: Lòng Tàu | B13: Triều Lên | C13: HCM_NM_LT_L | G13: Sài Gòn | H13: Triều Xuống | I13: 1 | J13: 1 | K13: 25 | L13: {=INDEX($A$1:$C$172,MATCH(1,($G13=$A$1:$A$172)*($H13=$B$1:$B$172),0),3)} -> HCM_NM_SG_X
A14: Tam Thôn Hiệp | B14: Triều Lên | C14: HCM_NM_TTH_L | G14: Ngã Bảy | H14: Triều Lên | I14: 1 | K14: 26 | L14: {=INDEX($A$1:$C$172,MATCH(1,($G14=$A$1:$A$172)*($H14=$B$1:$B$172),0),3)} -> HCM_NM_N7_L
A15: Đồng Tranh 1 | B15: Triều Lên | C15: HCM_NM_ĐT1_L | G15: Vàm Sát | H15: Triều Lên | I15: 1 | K15: 26 | L15: {=INDEX($A$1:$C$172,MATCH(1,($G15=$A$1:$A$172)*($H15=$B$1:$B$172),0),3)} -> HCM_NM_VS_L
A16: Long Phước | B16: Triều Xuống | C16: HCM_NM_LP_X | G16: Đồng Tranh | H16: Triều Lên | I16: 1 | K16: 26 | L16: {=INDEX($A$1:$C$172,MATCH(1,($G16=$A$1:$A$172)*($H16=$B$1:$B$172),0),3)} -> HCM_NM_ĐT_L
A17: Cát Lái | B17: Triều Xuống | C17: HCM_NM_CL_X | G17: Ngã Bảy | H17: Triều Xuống | I17: 1 | K17: 26 | L17: {=INDEX($A$1:$C$172,MATCH(1,($G17=$A$1:$A$172)*($H17=$B$1:$B$172),0),3)} -> HCM_NM_N7_X
A18: Lòng Tàu | B18: Triều Xuống | C18: HCM_NM_LT_X | G18: Vàm Sát | H18: Triều Xuống | I18: 1 | K18: 26 | L18: {=INDEX($A$1:$C$172,MATCH(1,($G18=$A$1:$A$172)*($H18=$B$1:$B$172),0),3)} -> HCM_NM_VS_X
A19: Tam Thôn Hiệp | B19: Triều Xuống | C19: HCM_NM_TTH_X | G19: Đồng Tranh | H19: Triều Xuống | I19: 1 | K19: 26 | L19: {=INDEX($A$1:$C$172,MATCH(1,($G19=$A$1:$A$172)*($H19=$B$1:$B$172),0),3)} -> HCM_NM_ĐT_X
A20: Đồng Tranh 1 | B20: Triều Xuống | C20: HCM_NM_ĐT1_X | G20: Long Phước | H20: Triều Lên | I20: 1 | K20: 26 | L20: {=INDEX($A$1:$C$172,MATCH(1,($G20=$A$1:$A$172)*($H20=$B$1:$B$172),0),3)} -> HCM_NM_LP_L
A21: Lòng Tàu 1 | B21: Triều Lên | C21: HCM_NM_LT1_L | G21: Cát Lái | H21: Triều Lên | I21: 1 | K21: 26 | L21: {=INDEX($A$1:$C$172,MATCH(1,($G21=$A$1:$A$172)*($H21=$B$1:$B$172),0),3)} -> HCM_NM_CL_L
A22: Ngã Bảy | B22: Triều Lên | C22: HCM_NM_N7_L | G22: Long Phước | H22: Triều Xuống | I22: 1 | K22: 26 | L22: {=INDEX($A$1:$C$172,MATCH(1,($G22=$A$1:$A$172)*($H22=$B$1:$B$172),0),3)} -> HCM_NM_LP_X
A23: Vàm Sát | B23: Triều Lên | C23: HCM_NM_VS_L | G23: Cát Lái | H23: Triều Xuống | I23: 1 | K23: 26 | L23: {=INDEX($A$1:$C$172,MATCH(1,($G23=$A$1:$A$172)*($H23=$B$1:$B$172),0),3)} -> HCM_NM_CL_X
A24: Đồng Tranh | B24: Triều Lên | C24: HCM_NM_ĐT_L | G24: Mũi Đèn Đỏ | H24: Triều Lên | I24: 1 | K24: 27 | L24: {=INDEX($A$1:$C$172,MATCH(1,($G24=$A$1:$A$172)*($H24=$B$1:$B$172),0),3)} -> HCM_NM_MĐĐ_L
A25: Lòng Tàu 1 | B25: Triều Xuống | C25: HCM_NM_LT1_X | G25: Nhà Bè | H25: Triều Lên | I25: 1 | K25: 27 | L25: {=INDEX($A$1:$C$172,MATCH(1,($G25=$A$1:$A$172)*($H25=$B$1:$B$172),0),3)} -> HCM_NM_NB_L
... A28: Đồng Tranh | B28: Triều Xuống | C28: HCM_NM_ĐT_X | G28: Nhà Bè | H28: Triều Xuống | I28: 1 | K28: 27 | L28: {=INDEX($A$1:$C$172,MATCH(1,($G28=$A$1:$A$172)*($H28=$B$1:$B$172),0),3)} -> HCM_NM_NB_X
G29: Phú Mỹ | H29: Triều Xuống | I29: 1 | K29: 27 | L29: {=INDEX($A$1:$C$172,MATCH(1,($G29=$A$1:$A$172)*($H29=$B$1:$B$172),0),3)} -> HCM_NM_PM_X

Sheet CS2 NEW
A1: Cầu số 1 | B1: Triều Lên | C1: HCM_NM_CS1_L | E1: Năm | F1: Tháng | G1: Nơi thực hiện | H1: Vị trí quan trắc | I1: Số lượng mẫu | J1: Số lượng mẫu QC | K1: Ngày | L1: Ký hiệu | M1: Ký hiệu
A2: Lê Văn Sỹ | B2: Triều Lên | C2: HCM_NM_LVS_L | E2: 26 | F2: 05 | G2: ĐPNM1 - HCM_NM_ĐPNM1 - 01 | H2: ĐPNM1 - 01 | I2: 1 | K2: 11 | L2: =M2&"."&$E$2&"."&$F$2&"."&K2&INDEX('TONG HOP DIA DIEM'!$A$1:$L$181,MATCH('CS2 NEW'!$G2,'TONG HOP DIA DIEM'!$G$1:$G$181,0),3) -> HCM_NM_ĐPNM1.26.05.11.01 | M2: =INDEX('TONG HOP DIA DIEM'!$A$1:$L$181,MATCH('CS2 NEW'!$G2,'TONG HOP DIA DIEM'!$G$1:$G$181,0),4) -> HCM_NM_ĐPNM1
A3: Hải Đức | B3: Triều Lên | C3: HCM_NM_HĐ_L | G3: ĐPNM4 - HCM_NM_ĐPNM4 - 01 | H3: ĐPNM4 - 01 | I3: 1 | K3: 11 | L3: =M3&"."&$E$2&"."&$F$2&"."&K3&INDEX('TONG HOP DIA DIEM'!$A$1:$L$181,MATCH('CS2 NEW'!$G3,'TONG HOP DIA DIEM'!$G$1:$G$181,0),3) -> HCM_NM_ĐPNM4.26.05.11.01 | M3: =INDEX('TONG HOP DIA DIEM'!$A$1:$L$181,MATCH('CS2 NEW'!$G3,'TONG HOP DIA DIEM'!$G$1:$G$181,0),4) -> HCM_NM_ĐPNM4
A4: Điện Biên Phủ | B4: Triều Lên | C4: HCM_NM_ĐBP_L | G4: ĐPNM5 - HCM_NM_ĐPNM5 - 01 | H4: ĐPNM5 - 01 | I4: 1 | K4: 11 | L4: =M4&"."&$E$2&"."&$F$2&"."&K4&INDEX('TONG HOP DIA DIEM'!$A$1:$L$181,MATCH('CS2 NEW'!$G4,'TONG HOP DIA DIEM'!$G$1:$G$181,0),3) -> HCM_NM_ĐPNM5.26.05.11.01 | M4: =INDEX('TONG HOP DIA DIEM'!$A$1:$L$181,MATCH('CS2 NEW'!$G4,'TONG HOP DIA DIEM'!$G$1:$G$181,0),4) -> HCM_NM_ĐPNM5
A5: Bùi Đình Túy | B5: Triều Lên | C5: HCM_NM_BĐT_L | G5: ĐPNM8 - HCM_NM_ĐPNM8 - 01 | H5: ĐPNM8 - 01 | I5: 1 | K5: 11 | L5: =M5&"."&$E$2&"."&$F$2&"."&K5&INDEX('TONG HOP DIA DIEM'!$A$1:$L$181,MATCH('CS2 NEW'!$G5,'TONG HOP DIA DIEM'!$G$1:$G$181,0),3) -> HCM_NM_ĐPNM8.26.05.11.01 | M5: =INDEX('TONG HOP DIA DIEM'!$A$1:$L$181,MATCH('CS2 NEW'!$G5,'TONG HOP DIA DIEM'!$G$1:$G$181,0),4) -> HCM_NM_ĐPNM8
A6: Cầu Đỏ | B6: Triều Lên | C6: HCM_NM_CĐ_L | G6: ĐPNM1 - HCM_NM_ĐPNM1 - 02 | H6: ĐPNM1 - 02 | I6: 1 | K6: 11 | L6: =M6&"."&$E$2&"."&$F$2&"."&K6&INDEX('TONG HOP DIA DIEM'!$A$1:$L$181,MATCH('CS2 NEW'!$G6,'TONG HOP DIA DIEM'!$G$1:$G$181,0),3) -> HCM_NM_ĐPNM1.26.05.11.02 | M6: =INDEX('TONG HOP DIA DIEM'!$A$1:$L$181,MATCH('CS2 NEW'!$G6,'TONG HOP DIA DIEM'!$G$1:$G$181,0),4) -> HCM_NM_ĐPNM1
A7: Thị Nghè 2 | B7: Triều Lên | C7: HCM_NM_TN2_L | G7: ĐPNM4 - HCM_NM_ĐPNM4 - 02 | H7: ĐPNM4 - 02 | I7: 1 | K7: 11 | L7: =M7&"."&$E$2&"."&$F$2&"."&K7&INDEX('TONG HOP DIA DIEM'!$A$1:$L$181,MATCH('CS2 NEW'!$G7,'TONG HOP DIA DIEM'!$G$1:$G$181,0),3) -> HCM_NM_ĐPNM4.26.05.11.02 | M7: =INDEX('TONG HOP DIA DIEM'!$A$1:$L$181,MATCH('CS2 NEW'!$G7,'TONG HOP DIA DIEM'!$G$1:$G$181,0),4) -> HCM_NM_ĐPNM4
A8: Bùi Hữu Nghĩa | B8: Triều Lên | C8: HCM_NM_BHN_L | G8: ĐPNM5 - HCM_NM_ĐPNM5 - 02 | H8: ĐPNM5 - 02 | I8: 1 | K8: 11 | L8: =M8&"."&$E$2&"."&$F$2&"."&K8&INDEX('TONG HOP DIA DIEM'!$A$1:$L$181,MATCH('CS2 NEW'!$G8,'TONG HOP DIA DIEM'!$G$1:$G$181,0),3) -> HCM_NM_ĐPNM5.26.05.11.02 | M8: =INDEX('TONG HOP DIA DIEM'!$A$1:$L$181,MATCH('CS2 NEW'!$G8,'TONG HOP DIA DIEM'!$G$1:$G$181,0),4) -> HCM_NM_ĐPNM5
A9: Cầu Văn Thánh | B9: Triều Lên | C9: HCM_NM_RVT_L | G9: ĐPNM8 - HCM_NM_ĐPNM8 - 02 | H9: ĐPNM8 - 02 | I9: 1 | K9: 11 | L9: =M9&"."&$E$2&"."&$F$2&"."&K9&INDEX('TONG HOP DIA DIEM'!$A$1:$L$181,MATCH('CS2 NEW'!$G9,'TONG HOP DIA DIEM'!$G$1:$G$181,0),3) -> HCM_NM_ĐPNM8.26.05.11.02 | M9: =INDEX('TONG HOP DIA DIEM'!$A$1:$L$181,MATCH('CS2 NEW'!$G9,'TONG HOP DIA DIEM'!$G$1:$G$181,0),4) -> HCM_NM_ĐPNM8
A10: Cầu Văn Thánh 2 | B10: Triều Lên | C10: HCM_NM_RVT2_L | G10: Bà Lào - HCM_NM_BLa - Triều Lên | H10: Bà Lào - Triều Lên | I10: 1 | J10: 1 | K10: 11 | L10: =M10&"."&$E$2&"."&$F$2&"."&K10&INDEX('TONG HOP DIA DIEM'!$A$1:$L$181,MATCH('CS2 NEW'!$G10,'TONG HOP DIA DIEM'!$G$1:$G$181,0),3) -> HCM_NM_BLa.26.05.11.L | M10: =INDEX('TONG HOP DIA DIEM'!$A$1:$L$181,MATCH('CS2 NEW'!$G10,'TONG HOP DIA DIEM'!$G$1:$G$181,0),4) -> HCM_NM_BLa
A11: Cầu số 1 | B11: Triều Xuống | C11: HCM_NM_CS1_X | G11: Long Hậu Tân Kim - HCM_NM_LHTK - Triều Lên | H11: Long Hậu Tân Kim - Triều Lên | I11: 1 | K11: 11 | L11: =M11&"."&$E$2&"."&$F$2&"."&K11&INDEX('TONG HOP DIA DIEM'!$A$1:$L$181,MATCH('CS2 NEW'!$G11,'TONG HOP DIA DIEM'!$G$1:$G$181,0),3) -> HCM_NM_LHTK.26.05.11.L | M11: =INDEX('TONG HOP DIA DIEM'!$A$1:$L$181,MATCH('CS2 NEW'!$G11,'TONG HOP DIA DIEM'!$G$1:$G$181,0),4) -> HCM_NM_LHTK
A12: Lê Văn Sỹ | B12: Triều Xuống | C12: HCM_NM_LVS_X | G12: Phú Xuân - HCM_NM_PX - Triều Lên | H12: Phú Xuân - Triều Lên | I12: 1 | K12: 11 | L12: =M12&"."&$E$2&"."&$F$2&"."&K12&INDEX('TONG HOP DIA DIEM'!$A$1:$L$181,MATCH('CS2 NEW'!$G12,'TONG HOP DIA DIEM'!$G$1:$G$181,0),3) -> HCM_NM_PX.26.05.11.L | M12: =INDEX('TONG HOP DIA DIEM'!$A$1:$L$181,MATCH('CS2 NEW'!$G12,'TONG HOP DIA DIEM'!$G$1:$G$181,0),4) -> HCM_NM_PX
A13: Hải Đức | B13: Triều Xuống | C13: HCM_NM_HĐ_X | G13: Hiệp Phước - HCM_NM_HPh - Triều Lên | H13: Hiệp Phước - Triều Lên | I13: 1 | K13: 11 | L13: =M13&"."&$E$2&"."&$F$2&"."&K13&INDEX('TONG HOP DIA DIEM'!$A$1:$L$181,MATCH('CS2 NEW'!$G13,'TONG HOP DIA DIEM'!$G$1:$G$181,0),3) -> HCM_NM_HPh.26.05.11.L | M13: =INDEX('TONG HOP DIA DIEM'!$A$1:$L$181,MATCH('CS2 NEW'!$G13,'TONG HOP DIA DIEM'!$G$1:$G$181,0),4) -> HCM_NM_HPh
A14: Điện Biên Phủ | B14: Triều Xuống | C14: HCM_NM_ĐBP_X | G14: Bà Lào - HCM_NM_BLa - Triều Xuống | H14: Bà Lào - Triều Xuống | I14: 1 | K14: 11 | L14: =M14&"."&$E$2&"."&$F$2&"."&K14&INDEX('TONG HOP DIA DIEM'!$A$1:$L$181,MATCH('CS2 NEW'!$G14,'TONG HOP DIA DIEM'!$G$1:$G$181,0),3) -> HCM_NM_BLa.26.05.11.X | M14: =INDEX('TONG HOP DIA DIEM'!$A$1:$L$181,MATCH('CS2 NEW'!$G14,'TONG HOP DIA DIEM'!$G$1:$G$181,0),4) -> HCM_NM_BLa
A15: Bùi Đình Túy | B15: Triều Xuống | C15: HCM_NM_BĐT_X | G15: Long Hậu Tân Kim - HCM_NM_LHTK - Triều Xuống | H15: Long Hậu Tân Kim - Triều Xuống | I15: 1 | K15: 11 | L15: =M15&"."&$E$2&"."&$F$2&"."&K15&INDEX('TONG HOP DIA DIEM'!$A$1:$L$181,MATCH('CS2 NEW'!$G15,'TONG HOP DIA DIEM'!$G$1:$G$181,0),3) -> HCM_NM_LHTK.26.05.11.X | M15: =INDEX('TONG HOP DIA DIEM'!$A$1:$L$181,MATCH('CS2 NEW'!$G15,'TONG HOP DIA DIEM'!$G$1:$G$181,0),4) -> HCM_NM_LHTK
A16: Cầu Đỏ | B16: Triều Xuống | C16: HCM_NM_CĐ_X | G16: Phú Xuân - HCM_NM_PX - Triều Xuống | H16: Phú Xuân - Triều Xuống | I16: 1 | K16: 11 | L16: =M16&"."&$E$2&"."&$F$2&"."&K16&INDEX('TONG HOP DIA DIEM'!$A$1:$L$181,MATCH('CS2 NEW'!$G16,'TONG HOP DIA DIEM'!$G$1:$G$181,0),3) -> HCM_NM_PX.26.05.11.X | M16: =INDEX('TONG HOP DIA DIEM'!$A$1:$L$181,MATCH('CS2 NEW'!$G16,'TONG HOP DIA DIEM'!$G$1:$G$181,0),4) -> HCM_NM_PX
A17: Thị Nghè 2 | B17: Triều Xuống | C17: HCM_NM_TN2_X | G17: Hiệp Phước - HCM_NM_HPh - Triều Xuống | H17: Hiệp Phước - Triều Xuống | I17: 1 | K17: 11 | L17: =M17&"."&$E$2&"."&$F$2&"."&K17&INDEX('TONG HOP DIA DIEM'!$A$1:$L$181,MATCH('CS2 NEW'!$G17,'TONG HOP DIA DIEM'!$G$1:$G$181,0),3) -> HCM_NM_HPh.26.05.11.X | M17: =INDEX('TONG HOP DIA DIEM'!$A$1:$L$181,MATCH('CS2 NEW'!$G17,'TONG HOP DIA DIEM'!$G$1:$G$181,0),4) -> HCM_NM_HPh
A18: Bùi Hữu Nghĩa | B18: Triều Xuống | C18: HCM_NM_BHN_X | G18: Cầu số 1 - HCM_NM_CS1 - Triều Lên | H18: Cầu số 1 - Triều Lên | I18: 1 | K18: 12 | L18: =M18&"."&$E$2&"."&$F$2&"."&K18&INDEX('TONG HOP DIA DIEM'!$A$1:$L$181,MATCH('CS2 NEW'!$G18,'TONG HOP DIA DIEM'!$G$1:$G$181,0),3) -> HCM_NM_CS1.26.05.12.L | M18: =INDEX('TONG HOP DIA DIEM'!$A$1:$L$181,MATCH('CS2 NEW'!$G18,'TONG HOP DIA DIEM'!$G$1:$G$181,0),4) -> HCM_NM_CS1
A19: Cầu Văn Thánh | B19: Triều Xuống | C19: HCM_NM_RVT_X | G19: Lê Văn Sỹ - HCM_NM_LVS - Triều Lên | H19: Lê Văn Sỹ - Triều Lên | I19: 1 | K19: 12 | L19: =M19&"."&$E$2&"."&$F$2&"."&K19&INDEX('TONG HOP DIA DIEM'!$A$1:$L$181,MATCH('CS2 NEW'!$G19,'TONG HOP DIA DIEM'!$G$1:$G$181,0),3) -> HCM_NM_LVS.26.05.12.L | M19: =INDEX('TONG HOP DIA DIEM'!$A$1:$L$181,MATCH('CS2 NEW'!$G19,'TONG HOP DIA DIEM'!$G$1:$G$181,0),4) -> HCM_NM_LVS
A20: Cầu Văn Thánh 2 | B20: Triều Xuống | C20: HCM_NM_RVT2_X | G20: Hải Đức - HCM_NM_HĐ - Triều Lên | H20: Hải Đức - Triều Lên | I20: 1 | K20: 12 | L20: =M20&"."&$E$2&"."&$F$2&"."&K20&INDEX('TONG HOP DIA DIEM'!$A$1:$L$181,MATCH('CS2 NEW'!$G20,'TONG HOP DIA DIEM'!$G$1:$G$181,0),3) -> HCM_NM_HĐ.26.05.12.L | M20: =INDEX('TONG HOP DIA DIEM'!$A$1:$L$181,MATCH('CS2 NEW'!$G20,'TONG HOP DIA DIEM'!$G$1:$G$181,0),4) -> HCM_NM_HĐ
A21: TBNM15 | B21: Triều Lên | C21: HCM_NM_TBNM15_L | G21: Điện Biên Phủ - HCM_NM_ĐBP - Triều Lên | H21: Điện Biên Phủ - Triều Lên | I21: 1 | K21: 12 | L21: =M21&"."&$E$2&"."&$F$2&"."&K21&INDEX('TONG HOP DIA DIEM'!$A$1:$L$181,MATCH('CS2 NEW'!$G21,'TONG HOP DIA DIEM'!$G$1:$G$181,0),3) -> HCM_NM_ĐBP.26.05.12.L | M21: =INDEX('TONG HOP DIA DIEM'!$A$1:$L$181,MATCH('CS2 NEW'!$G21,'TONG HOP DIA DIEM'!$G$1:$G$181,0),4) -> HCM_NM_ĐBP
A22: TBNM5 | B22: Triều Lên | C22: HCM_NM_TBNM5_L | G22: Bùi Hữu Nghĩa - HCM_NM_BHN - Triều Lên | H22: Bùi Hữu Nghĩa - Triều Lên | I22: 1 | K22: 12 | L22: =M22&"."&$E$2&"."&$F$2&"."&K22&INDEX('TONG HOP DIA DIEM'!$A$1:$L$181,MATCH('CS2 NEW'!$G22,'TONG HOP DIA DIEM'!$G$1:$G$181,0),3) -> HCM_NM_BHN.26.05.12.L | M22: =INDEX('TONG HOP DIA DIEM'!$A$1:$L$181,MATCH('CS2 NEW'!$G22,'TONG HOP DIA DIEM'!$G$1:$G$181,0),4) -> HCM_NM_BHN
A23: Cầu Tân Thái | B23: Triều Lên | C23: HCM_NM_CTT_L | G23: Cầu số 1 - HCM_NM_CS1 - Triều Xuống | H23: Cầu số 1 - Triều Xuống | I23: 1 | J23: 3 | K23: 12 | L23: =M23&"."&$E$2&"."&$F$2&"."&K23&INDEX('TONG HOP DIA DIEM'!$A$1:$L$181,MATCH('CS2 NEW'!$G23,'TONG HOP DIA DIEM'!$G$1:$G$181,0),3) -> HCM_NM_CS1.26.05.12.X | M23: =INDEX('TONG HOP DIA DIEM'!$A$1:$L$181,MATCH('CS2 NEW'!$G23,'TONG HOP DIA DIEM'!$G$1:$G$181,0),4) -> HCM_NM_CS1
A24: TBNM14 | B24: Triều Lên | C24: HCM_NM_TBNM14_L | G24: Lê Văn Sỹ - HCM_NM_LVS - Triều Xuống | H24: Lê Văn Sỹ - Triều Xuống | I24: 1 | K24: 12 | L24: =M24&"."&$E$2&"."&$F$2&"."&K24&INDEX('TONG HOP DIA DIEM'!$A$1:$L$181,MATCH('CS2 NEW'!$G24,'TONG HOP DIA DIEM'!$G$1:$G$181,0),3) -> HCM_NM_LVS.26.05.12.X | M24: =INDEX('TONG HOP DIA DIEM'!$A$1:$L$181,MATCH('CS2 NEW'!$G24,'TONG HOP DIA DIEM'!$G$1:$G$181,0),4) -> HCM_NM_LVS
A25: TBNM9 | B25: Triều Lên | C25: HCM_NM_TBNM9_L | G25: Hải Đức - HCM_NM_HĐ - Triều Xuống | H25: Hải Đức - Triều Xuống | I25: 1 | K25: 12 | L25: =M25&"."&$E$2&"."&$F$2&"."&K25&INDEX('TONG HOP DIA DIEM'!$A$1:$L$181,MATCH('CS2 NEW'!$G25,'TONG HOP DIA DIEM'!$G$1:$G$181,0),3) -> HCM_NM_HĐ.26.05.12.X | M25: =INDEX('TONG HOP DIA DIEM'!$A$1:$L$181,MATCH('CS2 NEW'!$G25,'TONG HOP DIA DIEM'!$G$1:$G$181,0),4) -> HCM_NM_HĐ
A26: TBNM11 | B26: Triều Lên | C26: HCM_NM_TBNM11_L | G26: Điện Biên Phủ - HCM_NM_ĐBP - Triều Xuống | H26: Điện Biên Phủ - Triều Xuống | I26: 1 | K26: 12 | L26: =M26&"."&$E$2&"."&$F$2&"."&K26&INDEX('TONG HOP DIA DIEM'!$A$1:$L$181,MATCH('CS2 NEW'!$G26,'TONG HOP DIA DIEM'!$G$1:$G$181,0),3) -> HCM_NM_ĐBP.26.05.12.X | M26: =INDEX('TONG HOP DIA DIEM'!$A$1:$L$181,MATCH('CS2 NEW'!$G26,'TONG HOP DIA DIEM'!$G$1:$G$181,0),4) -> HCM_NM_ĐBP
A27: TBNM1 | B27: Triều Lên | C27: HCM_NM_TBNM1_L | G27: Bùi Hữu Nghĩa - HCM_NM_BHN - Triều Xuống | H27: Bùi Hữu Nghĩa - Triều Xuống | I27: 1 | K27: 12 | L27: =M27&"."&$E$2&"."&$F$2&"."&K27&INDEX('TONG HOP DIA DIEM'!$A$1:$L$181,MATCH('CS2 NEW'!$G27,'TONG HOP DIA DIEM'!$G$1:$G$181,0),3) -> HCM_NM_BHN.26.05.12.X | M27: =INDEX('TONG HOP DIA DIEM'!$A$1:$L$181,MATCH('CS2 NEW'!$G27,'TONG HOP DIA DIEM'!$G$1:$G$181,0),4) -> HCM_NM_BHN
A28: Thầy Cai | B28: Triều Lên | C28: HCM_NM_TCa_L | G28: Cầu Đỏ - HCM_NM_CĐ - Triều Lên | H28: Cầu Đỏ - Triều Lên | I28: 1 | K28: 12 | L28: =M28&"."&$E$2&"."&$F$2&"."&K28&INDEX('TONG HOP DIA DIEM'!$A$1:$L$181,MATCH('CS2 NEW'!$G28,'TONG HOP DIA DIEM'!$G$1:$G$181,0),3) -> HCM_NM_CĐ.26.05.12.L | M28: =INDEX('TONG HOP DIA DIEM'!$A$1:$L$181,MATCH('CS2 NEW'!$G28,'TONG HOP DIA DIEM'!$G$1:$G$181,0),4) -> HCM_NM_CĐ
A29: TBNM15 | B29: Triều Xuống | C29: HCM_NM_TBNM15_X | G29: Thị Nghè 2 - HCM_NM_TN2 - Triều Lên | H29: Thị Nghè 2 - Triều Lên | I29: 1 | K29: 12 | L29: =M29&"."&$E$2&"."&$F$2&"."&K29&INDEX('TONG HOP DIA DIEM'!$A$1:$L$181,MATCH('CS2 NEW'!$G29,'TONG HOP DIA DIEM'!$G$1:$G$181,0),3) -> HCM_NM_TN2.26.05.12.L | M29: =INDEX('TONG HOP DIA DIEM'!$A$1:$L$181,MATCH('CS2 NEW'!$G29,'TONG HOP DIA DIEM'!$G$1:$G$181,0),4) -> HCM_NM_TN2
A30: TBNM5 | B30: Triều Xuống | C30: HCM_NM_TBNM5_X | G30: Bùi Đình Túy - HCM_NM_BĐT - Triều Lên | H30: Bùi Đình Túy - Triều Lên | I30: 1 | K30: 12 | L30: =M30&"."&$E$2&"."&$F$2&"."&K30&INDEX('TONG HOP DIA DIEM'!$A$1:$L$181,MATCH('CS2 NEW'!$G30,'TONG HOP DIA DIEM'!$G$1:$G$181,0),3) -> HCM_NM_BĐT.26.05.12.L | M30: =INDEX('TONG HOP DIA DIEM'!$A$1:$L$181,MATCH('CS2 NEW'!$G30,'TONG HOP DIA DIEM'!$G$1:$G$181,0),4) -> HCM_NM_BĐT
A31: Cầu Tân Thái | B31: Triều Xuống | C31: HCM_NM_CTT_X | G31: Cầu Văn Thánh - HCM_NM_RVT - Triều Lên | H31: Cầu Văn Thánh - Triều Lên | I31: 1 | K31: 12 | L31: =M31&"."&$E$2&"."&$F$2&"."&K31&INDEX('TONG HOP DIA DIEM'!$A$1:$L$181,MATCH('CS2 NEW'!$G31,'TONG HOP DIA DIEM'!$G$1:$G$181,0),3) -> HCM_NM_RVT.26.05.12.L | M31: =INDEX('TONG HOP DIA DIEM'!$A$1:$L$181,MATCH('CS2 NEW'!$G31,'TONG HOP DIA DIEM'!$G$1:$G$181,0),4) -> HCM_NM_RVT
A32: TBNM14 | B32: Triều Xuống | C32: HCM_NM_TBNM14_X | G32: Cầu Văn Thánh 2 - HCM_NM_RVT2 - Triều Lên | H32: Cầu Văn Thánh 2 - Triều Lên | I32: 1 | K32: 12 | L32: =M32&"."&$E$2&"."&$F$2&"."&K32&INDEX('TONG HOP DIA DIEM'!$A$1:$L$181,MATCH('CS2 NEW'!$G32,'TONG HOP DIA DIEM'!$G$1:$G$181,0),3) -> HCM_NM_RVT2.26.05.12.L | M32: =INDEX('TONG HOP DIA DIEM'!$A$1:$L$181,MATCH('CS2 NEW'!$G32,'TONG HOP DIA DIEM'!$G$1:$G$181,0),4) -> HCM_NM_RVT2
A33: TBNM9 | B33: Triều Xuống | C33: HCM_NM_TBNM9_X | G33: Cầu Đỏ - HCM_NM_CĐ - Triều Xuống | H33: Cầu Đỏ - Triều Xuống | I33: 1 | J33: 1 | K33: 12 | L33: =M33&"."&$E$2&"."&$F$2&"."&K33&INDEX('TONG HOP DIA DIEM'!$A$1:$L$181,MATCH('CS2 NEW'!$G33,'TONG HOP DIA DIEM'!$G$1:$G$181,0),3) -> HCM_NM_CĐ.26.05.12.X | M33: =INDEX('TONG HOP DIA DIEM'!$A$1:$L$181,MATCH('CS2 NEW'!$G33,'TONG HOP DIA DIEM'!$G$1:$G$181,0),4) -> HCM_NM_CĐ
A34: TBNM11 | B34: Triều Xuống | C34: HCM_NM_TBNM11_X | G34: Thị Nghè 2 - HCM_NM_TN2 - Triều Xuống | H34: Thị Nghè 2 - Triều Xuống | I34: 1 | K34: 12 | L34: =M34&"."&$E$2&"."&$F$2&"."&K34&INDEX('TONG HOP DIA DIEM'!$A$1:$L$181,MATCH('CS2 NEW'!$G34,'TONG HOP DIA DIEM'!$G$1:$G$181,0),3) -> HCM_NM_TN2.26.05.12.X | M34: =INDEX('TONG HOP DIA DIEM'!$A$1:$L$181,MATCH('CS2 NEW'!$G34,'TONG HOP DIA DIEM'!$G$1:$G$181,0),4) -> HCM_NM_TN2
A35: TBNM1 | B35: Triều Xuống | C35: HCM_NM_TBNM1_X | G35: Bùi Đình Túy - HCM_NM_BĐT - Triều Xuống | H35: Bùi Đình Túy - Triều Xuống | I35: 1 | K35: 12 | L35: =M35&"."&$E$2&"."&$F$2&"."&K35&INDEX('TONG HOP DIA DIEM'!$A$1:$L$181,MATCH('CS2 NEW'!$G35,'TONG HOP DIA DIEM'!$G$1:$G$181,0),3) -> HCM_NM_BĐT.26.05.12.X | M35: =INDEX('TONG HOP DIA DIEM'!$A$1:$L$181,MATCH('CS2 NEW'!$G35,'TONG HOP DIA DIEM'!$G$1:$G$181,0),4) -> HCM_NM_BĐT
A36: Thầy Cai | B36: Triều Xuống | C36: HCM_NM_TCa_X | G36: Cầu Văn Thánh - HCM_NM_RVT - Triều Xuống | H36: Cầu Văn Thánh - Triều Xuống | I36: 1 | K36: 12 | L36: =M36&"."&$E$2&"."&$F$2&"."&K36&INDEX('TONG HOP DIA DIEM'!$A$1:$L$181,MATCH('CS2 NEW'!$G36,'TONG HOP DIA DIEM'!$G$1:$G$181,0),3) -> HCM_NM_RVT.26.05.12.X | M36: =INDEX('TONG HOP DIA DIEM'!$A$1:$L$181,MATCH('CS2 NEW'!$G36,'TONG HOP DIA DIEM'!$G$1:$G$181,0),4) -> HCM_NM_RVT
A37: Kênh N46 | B37: Triều Lên | C37: HCM_NM_N46_L | G37: Cầu Văn Thánh 2 - HCM_NM_RVT2 - Triều Xuống | H37: Cầu Văn Thánh 2 - Triều Xuống | I37: 1 | K37: 12 | L37: =M37&"."&$E$2&"."&$F$2&"."&K37&INDEX('TONG HOP DIA DIEM'!$A$1:$L$181,MATCH('CS2 NEW'!$G37,'TONG HOP DIA DIEM'!$G$1:$G$181,0),3) -> HCM_NM_RVT2.26.05.12.X | M37: =INDEX('TONG HOP DIA DIEM'!$A$1:$L$181,MATCH('CS2 NEW'!$G37,'TONG HOP DIA DIEM'!$G$1:$G$181,0),4) -> HCM_NM_RVT2
A38: Tân Phú Trung | B38: Triều Lên | C38: HCM_NM_TPT_L | G38: Cầu TL9 - HCM_NM_CTL9 - Triều Lên | H38: Cầu TL9 - Triều Lên | I38: 1 | K38: 13 | L38: =M38&"."&$E$2&"."&$F$2&"."&K38&INDEX('TONG HOP DIA DIEM'!$A$1:$L$181,MATCH('CS2 NEW'!$G38,'TONG HOP DIA DIEM'!$G$1:$G$181,0),3) -> HCM_NM_CTL9.26.05.13.L | M38: =INDEX('TONG HOP DIA DIEM'!$A$1:$L$181,MATCH('CS2 NEW'!$G38,'TONG HOP DIA DIEM'!$G$1:$G$181,0),4) -> HCM_NM_CTL9
A39: TC18A | B39: Triều Lên | C39: HCM_NM_TC18A_L | G39: Xuân Thới Sơn - HCM_NM_XTS - Triều Lên | H39: Xuân Thới Sơn - Triều Lên | I39: 1 | K39: 13 | L39: =M39&"."&$E$2&"."&$F$2&"."&K39&INDEX('TONG HOP DIA DIEM'!$A$1:$L$181,MATCH('CS2 NEW'!$G39,'TONG HOP DIA DIEM'!$G$1:$G$181,0),3) -> HCM_NM_XTS.26.05.13.L | M39: =INDEX('TONG HOP DIA DIEM'!$A$1:$L$181,MATCH('CS2 NEW'!$G39,'TONG HOP DIA DIEM'!$G$1:$G$181,0),4) -> HCM_NM_XTS
A40: An Hạ 1 | B40: Triều Lên | C40: HCM_NM_AH1_L | G40: Cầu Lớn - HCM_NM_CLo - Triều Lên | H40: Cầu Lớn - Triều Lên | I40: 1 | K40: 13 | L40: =M40&"."&$E$2&"."&$F$2&"."&K40&INDEX('TONG HOP DIA DIEM'!$A$1:$L$181,MATCH('CS2 NEW'!$G40,'TONG HOP DIA DIEM'!$G$1:$G$181,0),3) -> HCM_NM_CLo.26.05.13.L | M40: =INDEX('TONG HOP DIA DIEM'!$A$1:$L$181,MATCH('CS2 NEW'!$G40,'TONG HOP DIA DIEM'!$G$1:$G$181,0),4) -> HCM_NM_CLo
...

Sheet CS3 NEW
A1: Bình Lợi | B1: Triều Lên | C1: HCM_NM_BL_L | E1: Năm | F1: Tháng | G1: Nơi thực hiện | H1: Vị trí quan trắc | I1: Số lượng mẫu | J1: Số lượng mẫu QC | K1: Ngày | L1: Ký hiệu | M1: Ký hiệu
A2: Sài Gòn | B2: Triều Lên | C2: HCM_NM_SG_L | E2: 26 | F2: 05 | G2: Lòng Tàu 1 - HCM_NM_LT1 - Triều Lên | H2: Lòng Tàu 1 - Triều Lên | I2: 1 | K2: 25 | L2: =M2&"."&$E$2&"."&$F$2&"."&K2&INDEX('TONG HOP DIA DIEM'!$A$1:$L$181,MATCH('CS3 NEW'!$G2,'TONG HOP DIA DIEM'!$G$1:$G$181,0),3) -> HCM_NM_LT1.26.05.25.L | M2: =INDEX('TONG HOP DIA DIEM'!$A$1:$L$181,MATCH('CS3 NEW'!$G2,'TONG HOP DIA DIEM'!$G$1:$G$181,0),4) -> HCM_NM_LT1
A3: Phú Mỹ | B3: Triều Lên | C3: HCM_NM_PM_L | G3: Lòng Tàu - HCM_NM_LT - Triều Lên | H3: Lòng Tàu - Triều Lên | I3: 1 | K3: 25 | L3: =M3&"."&$E$2&"."&$F$2&"."&K3&INDEX('TONG HOP DIA DIEM'!$A$1:$L$181,MATCH('CS3 NEW'!$G3,'TONG HOP DIA DIEM'!$G$1:$G$181,0),3) -> HCM_NM_LT.26.05.25.L | M3: =INDEX('TONG HOP DIA DIEM'!$A$1:$L$181,MATCH('CS3 NEW'!$G3,'TONG HOP DIA DIEM'!$G$1:$G$181,0),4) -> HCM_NM_LT
A4: Mũi Đèn Đỏ | B4: Triều Lên | C4: HCM_NM_MĐĐ_L | G4: Tam Thôn Hiệp - HCM_NM_TTH - Triều Lên | H4: Tam Thôn Hiệp - Triều Lên | I4: 1 | K4: 25 | L4: =M4&"."&$E$2&"."&$F$2&"."&K4&INDEX('TONG HOP DIA DIEM'!$A$1:$L$181,MATCH('CS3 NEW'!$G4,'TONG HOP DIA DIEM'!$G$1:$G$181,0),3) -> HCM_NM_TTH.26.05.25.L | M4: =INDEX('TONG HOP DIA DIEM'!$A$1:$L$181,MATCH('CS3 NEW'!$G4,'TONG HOP DIA DIEM'!$G$1:$G$181,0),4) -> HCM_NM_TTH
A5: Nhà Bè | B5: Triều Lên | C5: HCM_NM_NB_L | G5: Đồng Tranh 1 - HCM_NM_ĐT1 - Triều Lên | H5: Đồng Tranh 1 - Triều Lên | I5: 1 | K5: 25 | L5: =M5&"."&$E$2&"."&$F$2&"."&K5&INDEX('TONG HOP DIA DIEM'!$A$1:$L$181,MATCH('CS3 NEW'!$G5,'TONG HOP DIA DIEM'!$G$1:$G$181,0),3) -> HCM_NM_ĐT1.26.05.25.L | M5: =INDEX('TONG HOP DIA DIEM'!$A$1:$L$181,MATCH('CS3 NEW'!$G5,'TONG HOP DIA DIEM'!$G$1:$G$181,0),4) -> HCM_NM_ĐT1
A6: Bình Lợi | B6: Triều Xuống | C6: HCM_NM_BL_X | G6: Lòng Tàu 1 - HCM_NM_LT1 - Triều Xuống | H6: Lòng Tàu 1 - Triều Xuống | I6: 1 | K6: 25 | L6: =M6&"."&$E$2&"."&$F$2&"."&K6&INDEX('TONG HOP DIA DIEM'!$A$1:$L$181,MATCH('CS3 NEW'!$G6,'TONG HOP DIA DIEM'!$G$1:$G$181,0),3) -> HCM_NM_LT1.26.05.25.X | M6: =INDEX('TONG HOP DIA DIEM'!$A$1:$L$181,MATCH('CS3 NEW'!$G6,'TONG HOP DIA DIEM'!$G$1:$G$181,0),4) -> HCM_NM_LT1
A7: Sài Gòn | B7: Triều Xuống | C7: HCM_NM_SG_X | G7: Lòng Tàu - HCM_NM_LT - Triều Xuống | H7: Lòng Tàu - Triều Xuống | I7: 1 | K7: 25 | L7: =M7&"."&$E$2&"."&$F$2&"."&K7&INDEX('TONG HOP DIA DIEM'!$A$1:$L$181,MATCH('CS3 NEW'!$G7,'TONG HOP DIA DIEM'!$G$1:$G$181,0),3) -> HCM_NM_LT.26.05.25.X | M7: =INDEX('TONG HOP DIA DIEM'!$A$1:$L$181,MATCH('CS3 NEW'!$G7,'TONG HOP DIA DIEM'!$G$1:$G$181,0),4) -> HCM_NM_LT
A8: Phú Mỹ | B8: Triều Xuống | C8: HCM_NM_PM_X | G8: Tam Thôn Hiệp - HCM_NM_TTH - Triều Xuống | H8: Tam Thôn Hiệp - Triều Xuống | I8: 1 | K8: 25 | L8: =M8&"."&$E$2&"."&$F$2&"."&K8&INDEX('TONG HOP DIA DIEM'!$A$1:$L$181,MATCH('CS3 NEW'!$G8,'TONG HOP DIA DIEM'!$G$1:$G$181,0),3) -> HCM_NM_TTH.26.05.25.X | M8: =INDEX('TONG HOP DIA DIEM'!$A$1:$L$181,MATCH('CS3 NEW'!$G8,'TONG HOP DIA DIEM'!$G$1:$G$181,0),4) -> HCM_NM_TTH
A9: Mũi Đèn Đỏ | B9: Triều Xuống | C9: HCM_NM_MĐĐ_X | G9: Đồng Tranh 1 - HCM_NM_ĐT1 - Triều Xuống | H9: Đồng Tranh 1 - Triều Xuống | I9: 1 | K9: 25 | L9: =M9&"."&$E$2&"."&$F$2&"."&K9&INDEX('TONG HOP DIA DIEM'!$A$1:$L$181,MATCH('CS3 NEW'!$G9,'TONG HOP DIA DIEM'!$G$1:$G$181,0),3) -> HCM_NM_ĐT1.26.05.25.X | M9: =INDEX('TONG HOP DIA DIEM'!$A$1:$L$181,MATCH('CS3 NEW'!$G9,'TONG HOP DIA DIEM'!$G$1:$G$181,0),4) -> HCM_NM_ĐT1
A10: Nhà Bè | B10: Triều Xuống | C10: HCM_NM_NB_X | G10: Bình Lợi - HCM_NM_BL - Triều Lên | H10: Bình Lợi - Triều Lên | I10: 1 | K10: 25 | L10: =M10&"."&$E$2&"."&$F$2&"."&K10&INDEX('TONG HOP DIA DIEM'!$A$1:$L$181,MATCH('CS3 NEW'!$G10,'TONG HOP DIA DIEM'!$G$1:$G$181,0),3) -> HCM_NM_BL.26.05.25.L | M10: =INDEX('TONG HOP DIA DIEM'!$A$1:$L$181,MATCH('CS3 NEW'!$G10,'TONG HOP DIA DIEM'!$G$1:$G$181,0),4) -> HCM_NM_BL
A11: Long Phước | B11: Triều Lên | C11: HCM_NM_LP_L | G11: Sài Gòn - HCM_NM_SG - Triều Lên | H11: Sài Gòn - Triều Lên | I11: 1 | K11: 25 | L11: =M11&"."&$E$2&"."&$F$2&"."&K11&INDEX('TONG HOP DIA DIEM'!$A$1:$L$181,MATCH('CS3 NEW'!$G11,'TONG HOP DIA DIEM'!$G$1:$G$181,0),3) -> HCM_NM_SG.26.05.25.L | M11: =INDEX('TONG HOP DIA DIEM'!$A$1:$L$181,MATCH('CS3 NEW'!$G11,'TONG HOP DIA DIEM'!$G$1:$G$181,0),4) -> HCM_NM_SG
A12: Cát Lái | B12: Triều Lên | C12: HCM_NM_CL_L | G12: Bình Lợi - HCM_NM_BL - Triều Xuống | H12: Bình Lợi - Triều Xuống | I12: 1 | K12: 25 | L12: =M12&"."&$E$2&"."&$F$2&"."&K12&INDEX('TONG HOP DIA DIEM'!$A$1:$L$181,MATCH('CS3 NEW'!$G12,'TONG HOP DIA DIEM'!$G$1:$G$181,0),3) -> HCM_NM_BL.26.05.25.X | M12: =INDEX('TONG HOP DIA DIEM'!$A$1:$L$181,MATCH('CS3 NEW'!$G12,'TONG HOP DIA DIEM'!$G$1:$G$181,0),4) -> HCM_NM_BL
A13: Lòng Tàu | B13: Triều Lên | C13: HCM_NM_LT_L | G13: Sài Gòn - HCM_NM_SG - Triều Xuống | H13: Sài Gòn - Triều Xuống | I13: 1 | J13: 2 | K13: 25 | L13: =M13&"."&$E$2&"."&$F$2&"."&K13&INDEX('TONG HOP DIA DIEM'!$A$1:$L$181,MATCH('CS3 NEW'!$G13,'TONG HOP DIA DIEM'!$G$1:$G$181,0),3) -> HCM_NM_SG.26.05.25.X | M13: =INDEX('TONG HOP DIA DIEM'!$A$1:$L$181,MATCH('CS3 NEW'!$G13,'TONG HOP DIA DIEM'!$G$1:$G$181,0),4) -> HCM_NM_SG
A14: Tam Thôn Hiệp | B14: Triều Lên | C14: HCM_NM_TTH_L | G14: Ngã Bảy - HCM_NM_N7 - Triều Lên | H14: Ngã Bảy - Triều Lên | I14: 1 | K14: 26 | L14: =M14&"."&$E$2&"."&$F$2&"."&K14&INDEX('TONG HOP DIA DIEM'!$A$1:$L$181,MATCH('CS3 NEW'!$G14,'TONG HOP DIA DIEM'!$G$1:$G$181,0),3) -> HCM_NM_N7.26.05.26.L | M14: =INDEX('TONG HOP DIA DIEM'!$A$1:$L$181,MATCH('CS3 NEW'!$G14,'TONG HOP DIA DIEM'!$G$1:$G$181,0),4) -> HCM_NM_N7
A15: Đồng Tranh 1 | B15: Triều Lên | C15: HCM_NM_ĐT1_L | G15: Vàm Sát - HCM_NM_VS - Triều Lên | H15: Vàm Sát - Triều Lên | I15: 1 | K15: 26 | L15: =M15&"."&$E$2&"."&$F$2&"."&K15&INDEX('TONG HOP DIA DIEM'!$A$1:$L$181,MATCH('CS3 NEW'!$G15,'TONG HOP DIA DIEM'!$G$1:$G$181,0),3) -> HCM_NM_VS.26.05.26.L | M15: =INDEX('TONG HOP DIA DIEM'!$A$1:$L$181,MATCH('CS3 NEW'!$G15,'TONG HOP DIA DIEM'!$G$1:$G$181,0),4) -> HCM_NM_VS
A16: Long Phước | B16: Triều Xuống | C16: HCM_NM_LP_X | G16: Đồng Tranh - HCM_NM_ĐT - Triều Lên | H16: Đồng Tranh - Triều Lên | I16: 1 | K16: 26 | L16: =M16&"."&$E$2&"."&$F$2&"."&K16&INDEX('TONG HOP DIA DIEM'!$A$1:$L$181,MATCH('CS3 NEW'!$G16,'TONG HOP DIA DIEM'!$G$1:$G$181,0),3) -> HCM_NM_ĐT.26.05.26.L | M16: =INDEX('TONG HOP DIA DIEM'!$A$1:$L$181,MATCH('CS3 NEW'!$G16,'TONG HOP DIA DIEM'!$G$1:$G$181,0),4) -> HCM_NM_ĐT
A17: Cát Lái | B17: Triều Xuống | C17: HCM_NM_CL_X | G17: Ngã Bảy - HCM_NM_N7 - Triều Xuống | H17: Ngã Bảy - Triều Xuống | I17: 1 | K17: 26 | L17: =M17&"."&$E$2&"."&$F$2&"."&K17&INDEX('TONG HOP DIA DIEM'!$A$1:$L$181,MATCH('CS3 NEW'!$G17,'TONG HOP DIA DIEM'!$G$1:$G$181,0),3) -> HCM_NM_N7.26.05.26.X | M17: =INDEX('TONG HOP DIA DIEM'!$A$1:$L$181,MATCH('CS3 NEW'!$G17,'TONG HOP DIA DIEM'!$G$1:$G$181,0),4) -> HCM_NM_N7
A18: Lòng Tàu | B18: Triều Xuống | C18: HCM_NM_LT_X | G18: Vàm Sát - HCM_NM_VS - Triều Xuống | H18: Vàm Sát - Triều Xuống | I18: 1 | K18: 26 | L18: =M18&"."&$E$2&"."&$F$2&"."&K18&INDEX('TONG HOP DIA DIEM'!$A$1:$L$181,MATCH('CS3 NEW'!$G18,'TONG HOP DIA DIEM'!$G$1:$G$181,0),3) -> HCM_NM_VS.26.05.26.X | M18: =INDEX('TONG HOP DIA DIEM'!$A$1:$L$181,MATCH('CS3 NEW'!$G18,'TONG HOP DIA DIEM'!$G$1:$G$181,0),4) -> HCM_NM_VS
A19: Tam Thôn Hiệp | B19: Triều Xuống | C19: HCM_NM_TTH_X | G19: Đồng Tranh - HCM_NM_ĐT - Triều Xuống | H19: Đồng Tranh - Triều Xuống | I19: 1 | K19: 26 | L19: =M19&"."&$E$2&"."&$F$2&"."&K19&INDEX('TONG HOP DIA DIEM'!$A$1:$L$181,MATCH('CS3 NEW'!$G19,'TONG HOP DIA DIEM'!$G$1:$G$181,0),3) -> HCM_NM_ĐT.26.05.26.X | M19: =INDEX('TONG HOP DIA DIEM'!$A$1:$L$181,MATCH('CS3 NEW'!$G19,'TONG HOP DIA DIEM'!$G$1:$G$181,0),4) -> HCM_NM_ĐT
A20: Đồng Tranh 1 | B20: Triều Xuống | C20: HCM_NM_ĐT1_X | G20: Long Phước - HCM_NM_LP - Triều Lên | H20: Long Phước - Triều Lên | I20: 1 | K20: 26 | L20: =M20&"."&$E$2&"."&$F$2&"."&K20&INDEX('TONG HOP DIA DIEM'!$A$1:$L$181,MATCH('CS3 NEW'!$G20,'TONG HOP DIA DIEM'!$G$1:$G$181,0),3) -> HCM_NM_LP.26.05.26.L | M20: =INDEX('TONG HOP DIA DIEM'!$A$1:$L$181,MATCH('CS3 NEW'!$G20,'TONG HOP DIA DIEM'!$G$1:$G$181,0),4) -> HCM_NM_LP
A21: Lòng Tàu 1 | B21: Triều Lên | C21: HCM_NM_LT1_L | G21: Cát Lái - HCM_NM_CL - Triều Lên | H21: Cát Lái - Triều Lên | I21: 1 | K21: 26 | L21: =M21&"."&$E$2&"."&$F$2&"."&K21&INDEX('TONG HOP DIA DIEM'!$A$1:$L$181,MATCH('CS3 NEW'!$G21,'TONG HOP DIA DIEM'!$G$1:$G$181,0),3) -> HCM_NM_CL.26.05.26.L | M21: =INDEX('TONG HOP DIA DIEM'!$A$1:$L$181,MATCH('CS3 NEW'!$G21,'TONG HOP DIA DIEM'!$G$1:$G$181,0),4) -> HCM_NM_CL
A22: Ngã Bảy | B22: Triều Lên | C22: HCM_NM_N7_L | G22: Long Phước - HCM_NM_LP - Triều Xuống | H22: Long Phước - Triều Xuống | I22: 1 | K22: 26 | L22: =M22&"."&$E$2&"."&$F$2&"."&K22&INDEX('TONG HOP DIA DIEM'!$A$1:$L$181,MATCH('CS3 NEW'!$G22,'TONG HOP DIA DIEM'!$G$1:$G$181,0),3) -> HCM_NM_LP.26.05.26.X | M22: =INDEX('TONG HOP DIA DIEM'!$A$1:$L$181,MATCH('CS3 NEW'!$G22,'TONG HOP DIA DIEM'!$G$1:$G$181,0),4) -> HCM_NM_LP
A23: Vàm Sát | B23: Triều Lên | C23: HCM_NM_VS_L | G23: Cát Lái - HCM_NM_CL - Triều Xuống | H23: Cát Lái - Triều Xuống | I23: 1 | K23: 26 | L23: =M23&"."&$E$2&"."&$F$2&"."&K23&INDEX('TONG HOP DIA DIEM'!$A$1:$L$181,MATCH('CS3 NEW'!$G23,'TONG HOP DIA DIEM'!$G$1:$G$181,0),3) -> HCM_NM_CL.26.05.26.X | M23: =INDEX('TONG HOP DIA DIEM'!$A$1:$L$181,MATCH('CS3 NEW'!$G23,'TONG HOP DIA DIEM'!$G$1:$G$181,0),4) -> HCM_NM_CL
A24: Đồng Tranh | B24: Triều Lên | C24: HCM_NM_ĐT_L | G24: Mũi Đèn Đỏ - HCM_NM_MĐĐ - Triều Lên | H24: Mũi Đèn Đỏ - Triều Lên | I24: 1 | K24: 27 | L24: =M24&"."&$E$2&"."&$F$2&"."&K24&INDEX('TONG HOP DIA DIEM'!$A$1:$L$181,MATCH('CS3 NEW'!$G24,'TONG HOP DIA DIEM'!$G$1:$G$181,0),3) -> HCM_NM_MĐĐ.26.05.27.L | M24: =INDEX('TONG HOP DIA DIEM'!$A$1:$L$181,MATCH('CS3 NEW'!$G24,'TONG HOP DIA DIEM'!$G$1:$G$181,0),4) -> HCM_NM_MĐĐ
A25: Lòng Tàu 1 | B25: Triều Xuống | C25: HCM_NM_LT1_X | G25: Nhà Bè - HCM_NM_NB - Triều Lên | H25: Nhà Bè - Triều Lên | I25: 1 | K25: 27 | L25: =M25&"."&$E$2&"."&$F$2&"."&K25&INDEX('TONG HOP DIA DIEM'!$A$1:$L$181,MATCH('CS3 NEW'!$G25,'TONG HOP DIA DIEM'!$G$1:$G$181,0),3) -> HCM_NM_NB.26.05.27.L | M25: =INDEX('TONG HOP DIA DIEM'!$A$1:$L$181,MATCH('CS3 NEW'!$G25,'TONG HOP DIA DIEM'!$G$1:$G$181,0),4) -> HCM_NM_NB
... A28: Đồng Tranh | B28: Triều Xuống | C28: HCM_NM_ĐT_X | G28: Nhà Bè - HCM_NM_NB - Triều Xuống | H28: Nhà Bè - Triều Xuống | I28: 1 | K28: 27 | L28: =M28&"."&$E$2&"."&$F$2&"."&K28&INDEX('TONG HOP DIA DIEM'!$A$1:$L$181,MATCH('CS3 NEW'!$G28,'TONG HOP DIA DIEM'!$G$1:$G$181,0),3) -> HCM_NM_NB.26.05.27.X | M28: =INDEX('TONG HOP DIA DIEM'!$A$1:$L$181,MATCH('CS3 NEW'!$G28,'TONG HOP DIA DIEM'!$G$1:$G$181,0),4) -> HCM_NM_NB
F29: Code QC | G29: Phú Mỹ - HCM_NM_PM - Triều Xuống | H29: Phú Mỹ - Triều Xuống | I29: 1 | K29: 27 | L29: =M29&"."&$E$2&"."&$F$2&"."&K29&INDEX('TONG HOP DIA DIEM'!$A$1:$L$181,MATCH('CS3 NEW'!$G29,'TONG HOP DIA DIEM'!$G$1:$G$181,0),3) -> HCM_NM_PM.26.05.27.X | M29: =INDEX('TONG HOP DIA DIEM'!$A$1:$L$181,MATCH('CS3 NEW'!$G29,'TONG HOP DIA DIEM'!$G$1:$G$181,0),4) -> HCM_NM_PM
F30: =IF(RIGHT(H30,8)="Mẫu lặp)","05","0"&RANDBETWEEN(6,8)) -> 05 | G30: =_xlfn.IFNA(INDEX('TONG HOP DIA DIEM'!$A$1:$L$181,MATCH($H30,'TONG HOP DIA DIEM'!$I$1:$I$181,0),7),INDEX('TONG HOP DIA DIEM'!$A$1:$L$181,MATCH($H30,'TONG HOP DIA DIEM'!$J$1:$J$181,0),7)) -> Sài Gòn - HCM_NM_SG - Triều Xuống | H30: Sài Gòn - Triều Xuống (QC - Mẫu lặp) | I30: 1 | K30: =VLOOKUP(G30,$G$1:$M$119,5,0) -> 25 | L30: =VLOOKUP(G30,$G$1:$M$119,6,0)&"."&F30 -> HCM_NM_SG.26.05.25.X.05
F31: =IF(RIGHT(H31,8)="Mẫu lặp)","05","0"&RANDBETWEEN(6,8)) -> 07 | G31: =_xlfn.IFNA(INDEX('TONG HOP DIA DIEM'!$A$1:$L$181,MATCH($H31,'TONG HOP DIA DIEM'!$I$1:$I$181,0),7),INDEX('TONG HOP DIA DIEM'!$A$1:$L$181,MATCH($H31,'TONG HOP DIA DIEM'!$J$1:$J$181,0),7)) -> Sài Gòn - HCM_NM_SG - Triều Xuống | H31: Sài Gòn - Triều Xuống (QC - Mẫu trắng) | I31: 1 | K31: =VLOOKUP(G31,$G$1:$M$119,5,0) -> 25 | L31: =VLOOKUP(G31,$G$1:$M$119,6,0)&"."&F31 -> HCM_NM_SG.26.05.25.X.07

Sheet TONG HOP DIA DIEM
A1: Địa điểm quan trắc | B1: Triều | C1: Ký hiệu Triều | D1: Ký hiệu | E1: Tên viết tắt | F1: Địa chỉ | G1: Tên nơi lấy mẫu | H1: Tên vị trí | I1: Tên vị trí mẫu lặp | J1: Tên vị trí Mẫu trắng | K1: Tên vị trí mẫu trắng vận chuyển | L1: Tên vị trí mẫu trắng thiết bị
A2: Cầu số 1 | B2: Triều Lên | C2: =IF(B2="Triều Lên",".L",IF(B2="Triều Xuống",".X","."&B2)) -> .L | D2: HCM_NM_CS1 | E2: HCM_NM_CS1_L | F2: Khu vực Cầu số 1, đầu tuyến kênh Nhiêu Lộc – Thị Nghè | G2: Cầu số 1 - HCM_NM_CS1 - Triều Lên | H2: Cầu số 1 - Triều Lên | I2: Cầu số 1 - Triều Lên (QC - Mẫu lặp) | J2: Cầu số 1 - Triều Lên (QC - Mẫu trắng) | K2: Cầu số 1 - Triều Lên (QC - Mẫu trắng vận chuyển) | L2: Cầu số 1 - Triều Lên (QC - Mẫu trắng thiết bị)
A3: Lê Văn Sỹ | B3: Triều Lên | C3: =IF(B3="Triều Lên",".L",IF(B3="Triều Xuống",".X","."&B3)) -> .L | D3: HCM_NM_LVS | E3: HCM_NM_LVS_L | F3: Khu vực cầu Lê Văn Sỹ, nối đường Lê Văn Sỹ và đường Trần Quốc Thảo | G3: Lê Văn Sỹ - HCM_NM_LVS - Triều Lên | H3: Lê Văn Sỹ - Triều Lên | I3: Lê Văn Sỹ - Triều Lên (QC - Mẫu lặp) | J3: Lê Văn Sỹ - Triều Lên (QC - Mẫu trắng) | K3: Lê Văn Sỹ - Triều Lên (QC - Mẫu trắng vận chuyển) | L3: Lê Văn Sỹ - Triều Lên (QC - Mẫu trắng thiết bị)
A4: Hải Đức | B4: Triều Lên | C4: =IF(B4="Triều Lên",".L",IF(B4="Triều Xuống",".X","."&B4)) -> .L | D4: HCM_NM_HĐ | E4: HCM_NM_HĐ_L | F4: Đoạn kênh khu vực gần Chùa Hải Đức, phường Cầu Kiệu | G4: Hải Đức - HCM_NM_HĐ - Triều Lên | H4: Hải Đức - Triều Lên | I4: Hải Đức - Triều Lên (QC - Mẫu lặp) | J4: Hải Đức - Triều Lên (QC - Mẫu trắng) | K4: Hải Đức - Triều Lên (QC - Mẫu trắng vận chuyển) | L4: Hải Đức - Triều Lên (QC - Mẫu trắng thiết bị)
A5: Điện Biên Phủ | B5: Triều Lên | C5: =IF(B5="Triều Lên",".L",IF(B5="Triều Xuống",".X","."&B5)) -> .L | D5: HCM_NM_ĐBP | E5: HCM_NM_ĐBP_L | F5: Khu vực cầu Điện Biên Phủ, gần Vòng xoay Điện Biên Phủ | G5: Điện Biên Phủ - HCM_NM_ĐBP - Triều Lên | H5: Điện Biên Phủ - Triều Lên | I5: Điện Biên Phủ - Triều Lên (QC - Mẫu lặp) | J5: Điện Biên Phủ - Triều Lên (QC - Mẫu trắng) | K5: Điện Biên Phủ - Triều Lên (QC - Mẫu trắng vận chuyển) | L5: Điện Biên Phủ - Triều Lên (QC - Mẫu trắng thiết bị)
A6: Bùi Đình Túy | B6: Triều Lên | C6: =IF(B6="Triều Lên",".L",IF(B6="Triều Xuống",".X","."&B6)) -> .L | D6: HCM_NM_BĐT | E6: HCM_NM_BĐT_L | F6: Khu vực gần công viên đường số 4, giáp bờ sông, gần đường Chu Văn An, phường Bình Thạnh | G6: Bùi Đình Túy - HCM_NM_BĐT - Triều Lên | H6: Bùi Đình Túy - Triều Lên | I6: Bùi Đình Túy - Triều Lên (QC - Mẫu lặp) | J6: Bùi Đình Túy - Triều Lên (QC - Mẫu trắng) | K6: Bùi Đình Túy - Triều Lên (QC - Mẫu trắng vận chuyển) | L6: Bùi Đình Túy - Triều Lên (QC - Mẫu trắng thiết bị)
A7: Cầu Đỏ | B7: Triều Lên | C7: =IF(B7="Triều Lên",".L",IF(B7="Triều Xuống",".X","."&B7)) -> .L | D7: HCM_NM_CĐ | E7: HCM_NM_CĐ_L | F7: Khu vực Cầu Đỏ trên đường Nguyễn Xí, đoạn qua rạch Cầu Sơn | G7: Cầu Đỏ - HCM_NM_CĐ - Triều Lên | H7: Cầu Đỏ - Triều Lên | I7: Cầu Đỏ - Triều Lên (QC - Mẫu lặp) | J7: Cầu Đỏ - Triều Lên (QC - Mẫu trắng) | K7: Cầu Đỏ - Triều Lên (QC - Mẫu trắng vận chuyển) | L7: Cầu Đỏ - Triều Lên (QC - Mẫu trắng thiết bị)
A8: Thị Nghè 2 | B8: Triều Lên | C8: =IF(B8="Triều Lên",".L",IF(B8="Triều Xuống",".X","."&B8)) -> .L | D8: HCM_NM_TN2 | E8: HCM_NM_TN2_L | F8: Khu vực cầu Thị Nghè 2 trên đường Nguyễn Hữu Cảnh, gần Thảo Cầm Viên | G8: Thị Nghè 2 - HCM_NM_TN2 - Triều Lên | H8: Thị Nghè 2 - Triều Lên | I8: Thị Nghè 2 - Triều Lên (QC - Mẫu lặp) | J8: Thị Nghè 2 - Triều Lên (QC - Mẫu trắng) | K8: Thị Nghè 2 - Triều Lên (QC - Mẫu trắng vận chuyển) | L8: Thị Nghè 2 - Triều Lên (QC - Mẫu trắng thiết bị)
A9: Bùi Hữu Nghĩa | B9: Triều Lên | C9: =IF(B9="Triều Lên",".L",IF(B9="Triều Xuống",".X","."&B9)) -> .L | D9: HCM_NM_BHN | E9: HCM_NM_BHN_L | F9: Khu vực cầu Bùi Hữu Nghĩa, đoạn rạch Cầu Bông đổ ra kênh Nhiêu Lộc – Thị Nghè | G9: Bùi Hữu Nghĩa - HCM_NM_BHN - Triều Lên | H9: Bùi Hữu Nghĩa - Triều Lên | I9: Bùi Hữu Nghĩa - Triều Lên (QC - Mẫu lặp) | J9: Bùi Hữu Nghĩa - Triều Lên (QC - Mẫu trắng) | K9: Bùi Hữu Nghĩa - Triều Lên (QC - Mẫu trắng vận chuyển) | L9: Bùi Hữu Nghĩa - Triều Lên (QC - Mẫu trắng thiết bị)
A10: Cầu Văn Thánh | B10: Triều Lên | C10: =IF(B10="Triều Lên",".L",IF(B10="Triều Xuống",".X","."&B10)) -> .L | D10: HCM_NM_RVT | E10: HCM_NM_RVT_L | F10: Khu vực cầu Văn Thánh trên đường Điện Biên Phủ | G10: Cầu Văn Thánh - HCM_NM_RVT - Triều Lên | H10: Cầu Văn Thánh - Triều Lên | I10: Cầu Văn Thánh - Triều Lên (QC - Mẫu lặp) | J10: Cầu Văn Thánh - Triều Lên (QC - Mẫu trắng) | K10: Cầu Văn Thánh - Triều Lên (QC - Mẫu trắng vận chuyển) | L10: Cầu Văn Thánh - Triều Lên (QC - Mẫu trắng thiết bị)
A11: Cầu Văn Thánh 2 | B11: Triều Lên | C11: =IF(B11="Triều Lên",".L",IF(B11="Triều Xuống",".X","."&B11)) -> .L | D11: HCM_NM_RVT2 | E11: HCM_NM_RVT2_L | F11: Khu vực cầu Văn Thánh 2 trên đường Nguyễn Hữu Cảnh, đoạn qua rạch Văn Thánh | G11: Cầu Văn Thánh 2 - HCM_NM_RVT2 - Triều Lên | H11: Cầu Văn Thánh 2 - Triều Lên | I11: Cầu Văn Thánh 2 - Triều Lên (QC - Mẫu lặp) | J11: Cầu Văn Thánh 2 - Triều Lên (QC - Mẫu trắng) | K11: Cầu Văn Thánh 2 - Triều Lên (QC - Mẫu trắng vận chuyển) | L11: Cầu Văn Thánh 2 - Triều Lên (QC - Mẫu trắng thiết bị)
A12: Cầu số 1 | B12: Triều Xuống | C12: =IF(B12="Triều Lên",".L",IF(B12="Triều Xuống",".X","."&B12)) -> .X | D12: HCM_NM_CS1 | E12: HCM_NM_CS1_X | F12: Khu vực Cầu số 1, đầu tuyến kênh Nhiêu Lộc – Thị Nghè | G12: Cầu số 1 - HCM_NM_CS1 - Triều Xuống | H12: Cầu số 1 - Triều Xuống | I12: Cầu số 1 - Triều Xuống (QC - Mẫu lặp) | J12: Cầu số 1 - Triều Xuống (QC - Mẫu trắng) | K12: Cầu số 1 - Triều Xuống (QC - Mẫu trắng vận chuyển) | L12: Cầu số 1 - Triều Xuống (QC - Mẫu trắng thiết bị)
A13: Lê Văn Sỹ | B13: Triều Xuống | C13: =IF(B13="Triều Lên",".L",IF(B13="Triều Xuống",".X","."&B13)) -> .X | D13: HCM_NM_LVS | E13: HCM_NM_LVS_X | F13: Khu vực cầu Lê Văn Sỹ, nối đường Lê Văn Sỹ và đường Trần Quốc Thảo | G13: Lê Văn Sỹ - HCM_NM_LVS - Triều Xuống | H13: Lê Văn Sỹ - Triều Xuống | I13: Lê Văn Sỹ - Triều Xuống (QC - Mẫu lặp) | J13: Lê Văn Sỹ - Triều Xuống (QC - Mẫu trắng) | K13: Lê Văn Sỹ - Triều Xuống (QC - Mẫu trắng vận chuyển) | L13: Lê Văn Sỹ - Triều Xuống (QC - Mẫu trắng thiết bị)
... A181: Đồng Tranh | B181: Triều Xuống | C181: =IF(B181="Triều Lên",".L",IF(B181="Triều Xuống",".X","."&B181)) -> .X | D181: HCM_NM_ĐT | E181: HCM_NM_ĐT_X | F181: Xã Cần Giờ - Gần cửa sông Đồng Tranh 2 km. | G181: Đồng Tranh - HCM_NM_ĐT - Triều Xuống | H181: Đồng Tranh - Triều Xuống | I181: Đồng Tranh - Triều Xuống (QC - Mẫu lặp) | J181: Đồng Tranh - Triều Xuống (QC - Mẫu trắng) | K181: Đồng Tranh - Triều Xuống (QC - Mẫu trắng vận chuyển) | L181: Đồng Tranh - Triều Xuống (QC - Mẫu trắng thiết bị)

Sheet TONG HOP DIA DIEM (3 MAU TRANG)
A1: Địa điểm quan trắc | B1: Triều | C1: Ký hiệu Triều | D1: Ký hiệu | E1: Tên viết tắt | F1: Địa chỉ | G1: Tên nơi lấy mẫu | H1: Tên vị trí | I1: Tên vị trí mẫu lặp | J1: Tên vị trí mẫu trắng hiện trường | K1: Tên vị trí mẫu trắng vận chuyển | L1: Tên vị trí mẫu trắng thiết bị
A2: Cầu số 1 | B2: Triều Lên | C2: =IF(B2="Triều Lên",".L",IF(B2="Triều Xuống",".X","."&B2)) -> .L | D2: HCM_NM_CS1 | E2: HCM_NM_CS1_L | F2: Khu vực Cầu số 1, đầu tuyến kênh Nhiêu Lộc – Thị Nghè | G2: Cầu số 1 - HCM_NM_CS1 - Triều Lên | H2: Cầu số 1 - Triều Lên | I2: Cầu số 1 - Triều Lên (QC - Mẫu lặp hiện trường) | J2: Cầu số 1 - Triều Lên (QC - Mẫu trắng hiện trường) | K2: Cầu số 1 - Triều Lên (QC - Mẫu trắng vận chuyển) | L2: Cầu số 1 - Triều Lên (QC - Mẫu trắng thiết bị)
A3: Lê Văn Sỹ | B3: Triều Lên | C3: =IF(B3="Triều Lên",".L",IF(B3="Triều Xuống",".X","."&B3)) -> .L | D3: HCM_NM_LVS | E3: HCM_NM_LVS_L | F3: Khu vực cầu Lê Văn Sỹ, nối đường Lê Văn Sỹ và đường Trần Quốc Thảo | G3: Lê Văn Sỹ - HCM_NM_LVS - Triều Lên | H3: Lê Văn Sỹ - Triều Lên | I3: Lê Văn Sỹ - Triều Lên (QC - Mẫu lặp hiện trường) | J3: Lê Văn Sỹ - Triều Lên (QC - Mẫu trắng hiện trường) | K3: Lê Văn Sỹ - Triều Lên (QC - Mẫu trắng vận chuyển) | L3: Lê Văn Sỹ - Triều Lên (QC - Mẫu trắng thiết bị)
A4: Hải Đức | B4: Triều Lên | C4: =IF(B4="Triều Lên",".L",IF(B4="Triều Xuống",".X","."&B4)) -> .L | D4: HCM_NM_HĐ | E4: HCM_NM_HĐ_L | F4: Đoạn kênh khu vực gần Chùa Hải Đức, phường Cầu Kiệu | G4: Hải Đức - HCM_NM_HĐ - Triều Lên | H4: Hải Đức - Triều Lên | I4: Hải Đức - Triều Lên (QC - Mẫu lặp hiện trường) | J4: Hải Đức - Triều Lên (QC - Mẫu trắng hiện trường) | K4: Hải Đức - Triều Lên (QC - Mẫu trắng vận chuyển) | L4: Hải Đức - Triều Lên (QC - Mẫu trắng thiết bị)
A5: Điện Biên Phủ | B5: Triều Lên | C5: =IF(B5="Triều Lên",".L",IF(B5="Triều Xuống",".X","."&B5)) -> .L | D5: HCM_NM_ĐBP | E5: HCM_NM_ĐBP_L | F5: Khu vực cầu Điện Biên Phủ, gần Vòng xoay Điện Biên Phủ | G5: Điện Biên Phủ - HCM_NM_ĐBP - Triều Lên | H5: Điện Biên Phủ - Triều Lên | I5: Điện Biên Phủ - Triều Lên (QC - Mẫu lặp hiện trường) | J5: Điện Biên Phủ - Triều Lên (QC - Mẫu trắng hiện trường) | K5: Điện Biên Phủ - Triều Lên (QC - Mẫu trắng vận chuyển) | L5: Điện Biên Phủ - Triều Lên (QC - Mẫu trắng thiết bị)
A6: Bùi Đình Túy | B6: Triều Lên | C6: =IF(B6="Triều Lên",".L",IF(B6="Triều Xuống",".X","."&B6)) -> .L | D6: HCM_NM_BĐT | E6: HCM_NM_BĐT_L | F6: Khu vực gần công viên đường số 4, giáp bờ sông, gần đường Chu Văn An, phường Bình Thạnh | G6: Bùi Đình Túy - HCM_NM_BĐT - Triều Lên | H6: Bùi Đình Túy - Triều Lên | I6: Bùi Đình Túy - Triều Lên (QC - Mẫu lặp hiện trường) | J6: Bùi Đình Túy - Triều Lên (QC - Mẫu trắng hiện trường) | K6: Bùi Đình Túy - Triều Lên (QC - Mẫu trắng vận chuyển) | L6: Bùi Đình Túy - Triều Lên (QC - Mẫu trắng thiết bị)
A7: Cầu Đỏ | B7: Triều Lên | C7: =IF(B7="Triều Lên",".L",IF(B7="Triều Xuống",".X","."&B7)) -> .L | D7: HCM_NM_CĐ | E7: HCM_NM_CĐ_L | F7: Khu vực Cầu Đỏ trên đường Nguyễn Xí, đoạn qua rạch Cầu Sơn | G7: Cầu Đỏ - HCM_NM_CĐ - Triều Lên | H7: Cầu Đỏ - Triều Lên | I7: Cầu Đỏ - Triều Lên (QC - Mẫu lặp hiện trường) | J7: Cầu Đỏ - Triều Lên (QC - Mẫu trắng hiện trường) | K7: Cầu Đỏ - Triều Lên (QC - Mẫu trắng vận chuyển) | L7: Cầu Đỏ - Triều Lên (QC - Mẫu trắng thiết bị)
A8: Thị Nghè 2 | B8: Triều Lên | C8: =IF(B8="Triều Lên",".L",IF(B8="Triều Xuống",".X","."&B8)) -> .L | D8: HCM_NM_TN2 | E8: HCM_NM_TN2_L | F8: Khu vực cầu Thị Nghè 2 trên đường Nguyễn Hữu Cảnh, gần Thảo Cầm Viên | G8: Thị Nghè 2 - HCM_NM_TN2 - Triều Lên | H8: Thị Nghè 2 - Triều Lên | I8: Thị Nghè 2 - Triều Lên (QC - Mẫu lặp hiện trường) | J8: Thị Nghè 2 - Triều Lên (QC - Mẫu trắng hiện trường) | K8: Thị Nghè 2 - Triều Lên (QC - Mẫu trắng vận chuyển) | L8: Thị Nghè 2 - Triều Lên (QC - Mẫu trắng thiết bị)
A9: Bùi Hữu Nghĩa | B9: Triều Lên | C9: =IF(B9="Triều Lên",".L",IF(B9="Triều Xuống",".X","."&B9)) -> .L | D9: HCM_NM_BHN | E9: HCM_NM_BHN_L | F9: Khu vực cầu Bùi Hữu Nghĩa, đoạn rạch Cầu Bông đổ ra kênh Nhiêu Lộc – Thị Nghè | G9: Bùi Hữu Nghĩa - HCM_NM_BHN - Triều Lên | H9: Bùi Hữu Nghĩa - Triều Lên | I9: Bùi Hữu Nghĩa - Triều Lên (QC - Mẫu lặp hiện trường) | J9: Bùi Hữu Nghĩa - Triều Lên (QC - Mẫu trắng hiện trường) | K9: Bùi Hữu Nghĩa - Triều Lên (QC - Mẫu trắng vận chuyển) | L9: Bùi Hữu Nghĩa - Triều Lên (QC - Mẫu trắng thiết bị)
A10: Cầu Văn Thánh | B10: Triều Lên | C10: =IF(B10="Triều Lên",".L",IF(B10="Triều Xuống",".X","."&B10)) -> .L | D10: HCM_NM_RVT | E10: HCM_NM_RVT_L | F10: Khu vực cầu Văn Thánh trên đường Điện Biên Phủ | G10: Cầu Văn Thánh - HCM_NM_RVT - Triều Lên | H10: Cầu Văn Thánh - Triều Lên | I10: Cầu Văn Thánh - Triều Lên (QC - Mẫu lặp hiện trường) | J10: Cầu Văn Thánh - Triều Lên (QC - Mẫu trắng hiện trường) | K10: Cầu Văn Thánh - Triều Lên (QC - Mẫu trắng vận chuyển) | L10: Cầu Văn Thánh - Triều Lên (QC - Mẫu trắng thiết bị)
A11: Cầu Văn Thánh 2 | B11: Triều Lên | C11: =IF(B11="Triều Lên",".L",IF(B11="Triều Xuống",".X","."&B11)) -> .L | D11: HCM_NM_RVT2 | E11: HCM_NM_RVT2_L | F11: Khu vực cầu Văn Thánh 2 trên đường Nguyễn Hữu Cảnh, đoạn qua rạch Văn Thánh | G11: Cầu Văn Thánh 2 - HCM_NM_RVT2 - Triều Lên | H11: Cầu Văn Thánh 2 - Triều Lên | I11: Cầu Văn Thánh 2 - Triều Lên (QC - Mẫu lặp hiện trường) | J11: Cầu Văn Thánh 2 - Triều Lên (QC - Mẫu trắng hiện trường) | K11: Cầu Văn Thánh 2 - Triều Lên (QC - Mẫu trắng vận chuyển) | L11: Cầu Văn Thánh 2 - Triều Lên (QC - Mẫu trắng thiết bị)
A12: Cầu số 1 | B12: Triều Xuống | C12: =IF(B12="Triều Lên",".L",IF(B12="Triều Xuống",".X","."&B12)) -> .X | D12: HCM_NM_CS1 | E12: HCM_NM_CS1_X | F12: Khu vực Cầu số 1, đầu tuyến kênh Nhiêu Lộc – Thị Nghè | G12: Cầu số 1 - HCM_NM_CS1 - Triều Xuống | H12: Cầu số 1 - Triều Xuống | I12: Cầu số 1 - Triều Xuống (QC - Mẫu lặp hiện trường) | J12: Cầu số 1 - Triều Xuống (QC - Mẫu trắng hiện trường) | K12: Cầu số 1 - Triều Xuống (QC - Mẫu trắng vận chuyển) | L12: Cầu số 1 - Triều Xuống (QC - Mẫu trắng thiết bị)
A13: Lê Văn Sỹ | B13: Triều Xuống | C13: =IF(B13="Triều Lên",".L",IF(B13="Triều Xuống",".X","."&B13)) -> .X | D13: HCM_NM_LVS | E13: HCM_NM_LVS_X | F13: Khu vực cầu Lê Văn Sỹ, nối đường Lê Văn Sỹ và đường Trần Quốc Thảo | G13: Lê Văn Sỹ - HCM_NM_LVS - Triều Xuống | H13: Lê Văn Sỹ - Triều Xuống | I13: Lê Văn Sỹ - Triều Xuống (QC - Mẫu lặp hiện trường) | J13: Lê Văn Sỹ - Triều Xuống (QC - Mẫu trắng hiện trường) | K13: Lê Văn Sỹ - Triều Xuống (QC - Mẫu trắng vận chuyển) | L13: Lê Văn Sỹ - Triều Xuống (QC - Mẫu trắng thiết bị)
... A181: Đồng Tranh | B181: Triều Xuống | C181: =IF(B181="Triều Lên",".L",IF(B181="Triều Xuống",".X","."&B181)) -> .X | D181: HCM_NM_ĐT | E181: HCM_NM_ĐT_X | F181: Xã Cần Giờ - Gần cửa sông Đồng Tranh 2 km. | G181: Đồng Tranh - HCM_NM_ĐT - Triều Xuống | H181: Đồng Tranh - Triều Xuống | I181: Đồng Tranh - Triều Xuống (QC - Mẫu lặp hiện trường) | J181: Đồng Tranh - Triều Xuống (QC - Mẫu trắng hiện trường) | K181: Đồng Tranh - Triều Xuống (QC - Mẫu trắng vận chuyển) | L181: Đồng Tranh - Triều Xuống (QC - Mẫu trắng thiết bị)
