Workbook

Sheet KYHIEUCS2
A1: Nơi thực hiện | B1: Vị trí quan trắc | C1: Số lượng mẫu | D1: Số lượng mẫu QC | E1: Ngày | F1: Ký hiệu
A2: Cầu số 1 | B2: Triều Lên | C2: 1 | D2: 1 | E2: 1 | F2: HCM_NM_CS1_L
A3: Lê Văn Sỹ | B3: Triều Lên | C3: 1 | E3: 1 | F3: HCM_NM_LVS_L
A4: Hải Đức | B4: Triều Lên | C4: 1 | E4: 1 | F4: HCM_NM_HĐ_L
A5: Điện Biên Phủ | B5: Triều Lên | C5: 1 | E5: 1 | F5: HCM_NM_ĐBP_L
A6: Bùi Đình Túy | B6: Triều Lên | C6: 1 | E6: 1 | F6: HCM_NM_BĐT_L
A7: Cầu Đỏ | B7: Triều Lên | C7: 1 | D7: 1 | E7: 1 | F7: HCM_NM_CĐ_L
A8: Thị Nghè 2 | B8: Triều Lên | C8: 1 | E8: 1 | F8: HCM_NM_TN2_L
A9: Bùi Hữu Nghĩa | B9: Triều Lên | C9: 1 | E9: 1 | F9: HCM_NM_BHN_L
A10: Cầu Văn Thánh | B10: Triều Lên | C10: 1 | E10: 1 | F10: HCM_NM_RVT_L
A11: Cầu Văn Thánh 2 | B11: Triều Lên | C11: 1 | E11: 1 | F11: HCM_NM_RVT2_L
A12: Cầu số 1 | B12: Triều Xuống | C12: 1 | E12: 1 | F12: HCM_NM_CS1_X
A13: Lê Văn Sỹ | B13: Triều Xuống | C13: 1 | E13: 1 | F13: HCM_NM_LVS_X
A14: Hải Đức | B14: Triều Xuống | C14: 1 | E14: 1 | F14: HCM_NM_HĐ_X
A15: Điện Biên Phủ | B15: Triều Xuống | C15: 1 | E15: 1 | F15: HCM_NM_ĐBP_X
A16: Bùi Đình Túy | B16: Triều Xuống | C16: 1 | E16: 1 | F16: HCM_NM_BĐT_X
A17: Cầu Đỏ | B17: Triều Xuống | C17: 1 | E17: 1 | F17: HCM_NM_CĐ_X
A18: Thị Nghè 2 | B18: Triều Xuống | C18: 1 | D18: 1 | E18: 1 | F18: HCM_NM_TN2_X
A19: Bùi Hữu Nghĩa | B19: Triều Xuống | C19: 1 | E19: 1 | F19: HCM_NM_BHN_X
A20: Cầu Văn Thánh | B20: Triều Xuống | C20: 1 | E20: 1 | F20: HCM_NM_RVT_X
A21: Cầu Văn Thánh 2 | B21: Triều Xuống | C21: 1 | E21: 1 | F21: HCM_NM_RVT2_X
A22: TBNM15 | B22: Triều Lên | C22: 1 | E22: 2 | F22: HCM_NM_TBNM15_L
A23: TBNM5 | B23: Triều Lên | C23: 1 | E23: 2 | F23: HCM_NM_TBNM5_L
A24: Cầu Tân Thái | B24: Triều Lên | C24: 1 | E24: 2 | F24: HCM_NM_CTT_L
A25: TBNM14 | B25: Triều Lên | C25: 1 | E25: 2 | F25: HCM_NM_TBNM14_L
A26: TBNM9 | B26: Triều Lên | C26: 1 | E26: 2 | F26: HCM_NM_TBNM9_L
A27: TBNM11 | B27: Triều Lên | C27: 1 | E27: 2 | F27: HCM_NM_TBNM11_L
A28: TBNM1 | B28: Triều Lên | C28: 1 | E28: 2 | F28: HCM_NM_TBNM1_L
A29: Thầy Cai | B29: Triều Lên | C29: 1 | E29: 2 | F29: HCM_NM_TCa_L
A30: TBNM15 | B30: Triều Xuống | C30: 1 | E30: 2 | F30: HCM_NM_TBNM15_X
... A36: TBNM1 | B36: Triều Xuống | C36: 1 | E36: 2 | F36: HCM_NM_TBNM1_X
A37: Thầy Cai | B37: Triều Xuống | C37: 1 | D37: 1 | E37: 2 | F37: HCM_NM_TCa_X
A38: Kênh N46 | B38: Triều Lên | C38: 1 | E38: 3 | F38: HCM_NM_N46_L
A39: Tân Phú Trung | B39: Triều Lên | C39: 1 | E39: 3 | F39: HCM_NM_TPT_L
A40: TC18A | B40: Triều Lên | C40: 1 | E40: 3 | F40: HCM_NM_TC18A_L
A41: An Hạ 1 | B41: Triều Lên | C41: 1 | E41: 3 | F41: HCM_NM_AH1_L
A42: Cầu TL9 | B42: Triều Lên | C42: 1 | E42: 3 | F42: HCM_NM_CTL9_L
A43: Xuân Thới Sơn | B43: Triều Lên | C43: 1 | E43: 3 | F43: HCM_NM_XTS_L
A44: Cầu Lớn | B44: Triều Lên | C44: 1 | E44: 3 | F44: HCM_NM_CLo_L
A45: An Hạ | B45: Triều Lên | C45: 1 | E45: 3 | F45: HCM_NM_AH_L
...

Sheet CS2-THONG KE (2)
A1: key | B1: Ngày | C1: idx | D1: Nơi thực hiện | E1: Vị trí quan trắc | F1: Ký hiệu | G1: ts | H1: Column1
A2: kehoach|0 | B2: 1 | C2: 0 | D2: Cầu số 1 | E2: Triều Lên | F2: HCM_NM_CS1_L | G2: 46052.945 | H2: =CS2_THONG_KE[[#This Row],[Ký hiệu]]=KYHIEUCS2!F2 -> TRUE
A3: kehoach|1 | B3: 1 | C3: 1 | D3: Lê Văn Sỹ | E3: Triều Lên | F3: HCM_NM_LVS_L | G3: 46052.945 | H3: =CS2_THONG_KE[[#This Row],[Ký hiệu]]=KYHIEUCS2!F3 -> TRUE
A4: kehoach|2 | B4: 1 | C4: 2 | D4: Hải Đức | E4: Triều Lên | F4: HCM_NM_HĐ_L | G4: 46052.945 | H4: =CS2_THONG_KE[[#This Row],[Ký hiệu]]=KYHIEUCS2!F4 -> TRUE
A5: kehoach|3 | B5: 1 | C5: 3 | D5: Điện Biên Phủ | E5: Triều Lên | F5: HCM_NM_ĐBP_L | G5: 46052.946 | H5: =CS2_THONG_KE[[#This Row],[Ký hiệu]]=KYHIEUCS2!F5 -> TRUE
A6: kehoach|4 | B6: 1 | C6: 4 | D6: Bùi Đình Túy | E6: Triều Lên | F6: HCM_NM_BĐT_L | G6: 46052.946 | H6: =CS2_THONG_KE[[#This Row],[Ký hiệu]]=KYHIEUCS2!F6 -> TRUE
A7: kehoach|5 | B7: 1 | C7: 5 | D7: Cầu Đỏ | E7: Triều Lên | F7: HCM_NM_CĐ_L | G7: 46052.946 | H7: =CS2_THONG_KE[[#This Row],[Ký hiệu]]=KYHIEUCS2!F7 -> TRUE
A8: kehoach|6 | B8: 1 | C8: 6 | D8: Thị Nghè 2 | E8: Triều Lên | F8: HCM_NM_TN2_L | G8: 46052.947 | H8: =CS2_THONG_KE[[#This Row],[Ký hiệu]]=KYHIEUCS2!F8 -> TRUE
A9: kehoach|7 | B9: 1 | C9: 7 | D9: Bùi Hữu Nghĩa | E9: Triều Lên | F9: HCM_NM_BHN_L | G9: 46052.947 | H9: =CS2_THONG_KE[[#This Row],[Ký hiệu]]=KYHIEUCS2!F9 -> TRUE
A10: kehoach|8 | B10: 1 | C10: 8 | D10: Cầu Văn Thánh | E10: Triều Lên | F10: HCM_NM_RVT_L | G10: 46052.947 | H10: =CS2_THONG_KE[[#This Row],[Ký hiệu]]=KYHIEUCS2!F10 -> TRUE
A11: kehoach|9 | B11: 1 | C11: 9 | D11: Cầu Văn Thánh 2 | E11: Triều Lên | F11: HCM_NM_RVT2_L | G11: 46052.948 | H11: =CS2_THONG_KE[[#This Row],[Ký hiệu]]=KYHIEUCS2!F11 -> TRUE
A12: kehoach|10 | B12: 1 | C12: 10 | D12: Cầu số 1 | E12: Triều Xuống | F12: HCM_NM_CS1_X | G12: 46052.948 | H12: =CS2_THONG_KE[[#This Row],[Ký hiệu]]=KYHIEUCS2!F12 -> TRUE
A13: kehoach|11 | B13: 1 | C13: 11 | D13: Lê Văn Sỹ | E13: Triều Xuống | F13: HCM_NM_LVS_X | G13: 46052.948 | H13: =CS2_THONG_KE[[#This Row],[Ký hiệu]]=KYHIEUCS2!F13 -> TRUE
... A81: kehoach|79 | B81: 5 | C81: 79 | D81: Hồ Ngọc Lãm | E81: Triều Xuống | F81: HCM_NM_HNL_X | G81: 46052.971 | H81: =CS2_THONG_KE[[#This Row],[Ký hiệu]]=KYHIEUCS2!F81 -> TRUE
A82: kehoach|82 | B82: 6 | C82: 82 | D82: Cầu Rạch Ngang | E82: Triều Lên | F82: HCM_NM_CRN_L | G82: 46052.971 | H82: =CS2_THONG_KE[[#This Row],[Ký hiệu]]=KYHIEUCS2!F82 -> FALSE | J82: Thiếu Bình Điền Chợ Đệm
A83: kehoach|83 | B83: 6 | C83: 83 | D83: Xóm Củi | E83: Triều Lên | F83: HCM_NM_XC_L | G83: 46052.971 | H83: =CS2_THONG_KE[[#This Row],[Ký hiệu]]=KYHIEUCS2!F83 -> FALSE
A84: kehoach|84 | B84: 6 | C84: 84 | D84: Ông Lớn | E84: Triều Lên | F84: HCM_NM_OL_L | G84: 46052.972 | H84: =CS2_THONG_KE[[#This Row],[Ký hiệu]]=KYHIEUCS2!F84 -> FALSE
A85: kehoach|85 | B85: 6 | C85: 85 | D85: Cần Giuộc | E85: Triều Lên | F85: HCM_NM_CG_L | G85: 46052.972 | H85: =CS2_THONG_KE[[#This Row],[Ký hiệu]]=KYHIEUCS2!F85 -> FALSE
A86: kehoach|86 | B86: 6 | C86: 86 | D86: Bà Lào | E86: Triều Lên | F86: HCM_NM_BLa_L | G86: 46052.972 | H86: =CS2_THONG_KE[[#This Row],[Ký hiệu]]=KYHIEUCS2!F86 -> FALSE
A87: kehoach|87 | B87: 6 | C87: 87 | D87: Long Hậu Tân Kim | E87: Triều Lên | F87: HCM_NM_LHTK_L | G87: 46052.973 | H87: =CS2_THONG_KE[[#This Row],[Ký hiệu]]=KYHIEUCS2!F87 -> FALSE
A88: kehoach|88 | B88: 6 | C88: 88 | D88: Hiệp Phước | E88: Triều Lên | F88: HCM_NM_HPh_L | G88: 46052.973 | H88: =CS2_THONG_KE[[#This Row],[Ký hiệu]]=KYHIEUCS2!F88 -> FALSE
A89: kehoach|89 | B89: 6 | C89: 89 | D89: Cầu Rạch Ngang | E89: Triều Xuống | F89: HCM_NM_CRN_X | G89: 46052.973 | H89: =CS2_THONG_KE[[#This Row],[Ký hiệu]]=KYHIEUCS2!F89 -> FALSE
A90: kehoach|90 | B90: 6 | C90: 90 | D90: Xóm Củi | E90: Triều Xuống | F90: HCM_NM_XC_X | G90: 46052.974 | H90: =CS2_THONG_KE[[#This Row],[Ký hiệu]]=KYHIEUCS2!F90 -> FALSE
A91: kehoach|91 | B91: 6 | C91: 91 | D91: Ông Lớn | E91: Triều Xuống | F91: HCM_NM_OL_X | G91: 46052.974 | H91: =CS2_THONG_KE[[#This Row],[Ký hiệu]]=KYHIEUCS2!F91 -> FALSE
A92: kehoach|92 | B92: 6 | C92: 92 | D92: Cần Giuộc | E92: Triều Xuống | F92: HCM_NM_CG_X | G92: 46052.974 | H92: =CS2_THONG_KE[[#This Row],[Ký hiệu]]=KYHIEUCS2!F92 -> FALSE
A93: kehoach|93 | B93: 6 | C93: 93 | D93: Bà Lào | E93: Triều Xuống | F93: HCM_NM_BLa_X | G93: 46052.974 | H93: =CS2_THONG_KE[[#This Row],[Ký hiệu]]=KYHIEUCS2!F93 -> FALSE
A94: kehoach|94 | B94: 6 | C94: 94 | D94: Long Hậu Tân Kim | E94: Triều Xuống | F94: HCM_NM_LHTK_X | G94: 46052.975 | H94: =CS2_THONG_KE[[#This Row],[Ký hiệu]]=KYHIEUCS2!F94 -> FALSE
... A153: kehoach|153 | B153: 25 | C153: 153 | D153: TBNM5 | E153: Triều Lên | F153: HCM_NM_TBNM5_L | G153: 46052.994 | H153: =CS2_THONG_KE[[#This Row],[Ký hiệu]]=KYHIEUCS2!F153 -> FALSE

Sheet CS2-THONG KE
A1: key,Ngày,idx,Nơi thực hiện,Vị trí quan trắc,Ký hiệu,ts
A2: kehoach|0,1,0,Cầu số 1,Triều Lên,HCM_NM_CS1_L,2026-01-30T22:40:25
A3: kehoach|0,1,0,Cầu số 1,Triều Lên,HCM_NM_CS1_L,2026-01-30T22:40:34
A4: kehoach|0,1,0,Cầu số 1,Triều Lên,HCM_NM_CS1_L,2026-01-30T22:40:42
A5: kehoach|1,1,1,Lê Văn Sỹ,Triều Lên,HCM_NM_LVS_L,2026-01-30T22:40:51
A6: kehoach|1,1,1,Lê Văn Sỹ,Triều Lên,HCM_NM_LVS_L,2026-01-30T22:41:00
A7: kehoach|1,1,1,Lê Văn Sỹ,Triều Lên,HCM_NM_LVS_L,2026-01-30T22:41:09
A8: kehoach|2,1,2,Hải Đức,Triều Lên,HCM_NM_HĐ_L,2026-01-30T22:41:18
A9: kehoach|2,1,2,Hải Đức,Triều Lên,HCM_NM_HĐ_L,2026-01-30T22:41:26
A10: kehoach|2,1,2,Hải Đức,Triều Lên,HCM_NM_HĐ_L,2026-01-30T22:41:35
A11: kehoach|3,1,3,Điện Biên Phủ,Triều Lên,HCM_NM_ĐBP_L,2026-01-30T22:41:44
A12: kehoach|3,1,3,Điện Biên Phủ,Triều Lên,HCM_NM_ĐBP_L,2026-01-30T22:41:53
... A450: kehoach|153,25,153,TBNM5,Triều Lên,HCM_NM_TBNM5_L,2026-01-30T23:50:53
