Workbook

Sheet FINAL
A1: Địa điểm quan trắc | B1: Triều | C1: Ký hiệu | D1: Tên viết tắt | E1: Địa chỉ | F1: Tên nơi lấy mẫu | G1: Tên vị trí | H1: Tên vị trí mẫu lặp | I1: Tên vị trí mẫu trắng hiện trường | J1: Tên vị trí mẫu trắng vận chuyển | K1: Tên vị trí mẫu trắng thiết bị
A2: Cầu số 1 | B2: Triều Lên | C2: HCM_NM_CS1 | D2: HCM_NM_CS1_L | E2: Khu vực Cầu số 1, đầu tuyến kênh Nhiêu Lộc – Thị Nghè | F2: =A2&" - "&C2&" - "&B2 -> Cầu số 1 - HCM_NM_CS1 - Triều Lên | G2: =A2&" - "&B2 -> Cầu số 1 - Triều Lên | H2: =A2&" - "&B2&" (QC - "&Sheet2!$A$2&")" -> Cầu số 1 - Triều Lên (QC - Mẫu lặp hiện trường) | I2: =A2&" - "&B2&" (QC - "&Sheet2!$A$1&")" -> Cầu số 1 - Triều Lên (QC - Mẫu trắng hiện trường) | J2: =A2&" - "&B2&" (QC - "&Sheet2!$A$3&")" -> Cầu số 1 - Triều Lên (QC - Mẫu trắng vận chuyển) | K2: =A2&" - "&B2&" (QC - "&Sheet2!$A$4&")" -> Cầu số 1 - Triều Lên (QC - Mẫu trắng thiết bị)
A3: Lê Văn Sỹ | B3: Triều Lên | C3: HCM_NM_LVS | D3: HCM_NM_LVS_L | E3: Khu vực cầu Lê Văn Sỹ, nối đường Lê Văn Sỹ và đường Trần Quốc Thảo | F3: =A3&" - "&C3&" - "&B3 -> Lê Văn Sỹ - HCM_NM_LVS - Triều Lên | G3: =A3&" - "&B3 -> Lê Văn Sỹ - Triều Lên | H3: =A3&" - "&B3&" (QC - "&Sheet2!$A$2&")" -> Lê Văn Sỹ - Triều Lên (QC - Mẫu lặp hiện trường) | I3: =A3&" - "&B3&" (QC - "&Sheet2!$A$1&")" -> Lê Văn Sỹ - Triều Lên (QC - Mẫu trắng hiện trường) | J3: =A3&" - "&B3&" (QC - "&Sheet2!$A$3&")" -> Lê Văn Sỹ - Triều Lên (QC - Mẫu trắng vận chuyển) | K3: =A3&" - "&B3&" (QC - "&Sheet2!$A$4&")" -> Lê Văn Sỹ - Triều Lên (QC - Mẫu trắng thiết bị)
A4: Hải Đức | B4: Triều Lên | C4: HCM_NM_HĐ | D4: HCM_NM_HĐ_L | E4: Đoạn kênh khu vực gần Chùa Hải Đức, phường Cầu Kiệu | F4: =A4&" - "&C4&" - "&B4 -> Hải Đức - HCM_NM_HĐ - Triều Lên | G4: =A4&" - "&B4 -> Hải Đức - Triều Lên | H4: =A4&" - "&B4&" (QC - "&Sheet2!$A$2&")" -> Hải Đức - Triều Lên (QC - Mẫu lặp hiện trường) | I4: =A4&" - "&B4&" (QC - "&Sheet2!$A$1&")" -> Hải Đức - Triều Lên (QC - Mẫu trắng hiện trường) | J4: =A4&" - "&B4&" (QC - "&Sheet2!$A$3&")" -> Hải Đức - Triều Lên (QC - Mẫu trắng vận chuyển) | K4: =A4&" - "&B4&" (QC - "&Sheet2!$A$4&")" -> Hải Đức - Triều Lên (QC - Mẫu trắng thiết bị)
A5: Điện Biên Phủ | B5: Triều Lên | C5: HCM_NM_ĐBP | D5: HCM_NM_ĐBP_L | E5: Khu vực cầu Điện Biên Phủ, gần Vòng xoay Điện Biên Phủ | F5: =A5&" - "&C5&" - "&B5 -> Điện Biên Phủ - HCM_NM_ĐBP - Triều Lên | G5: =A5&" - "&B5 -> Điện Biên Phủ - Triều Lên | H5: =A5&" - "&B5&" (QC - "&Sheet2!$A$2&")" -> Điện Biên Phủ - Triều Lên (QC - Mẫu lặp hiện trường) | I5: =A5&" - "&B5&" (QC - "&Sheet2!$A$1&")" -> Điện Biên Phủ - Triều Lên (QC - Mẫu trắng hiện trường) | J5: =A5&" - "&B5&" (QC - "&Sheet2!$A$3&")" -> Điện Biên Phủ - Triều Lên (QC - Mẫu trắng vận chuyển) | K5: =A5&" - "&B5&" (QC - "&Sheet2!$A$4&")" -> Điện Biên Phủ - Triều Lên (QC - Mẫu trắng thiết bị)
A6: Bùi Đình Túy | B6: Triều Lên | C6: HCM_NM_BĐT | D6: HCM_NM_BĐT_L | E6: Khu vực gần công viên đường số 4, giáp bờ sông, gần đường Chu Văn An, phường Bình Thạnh | F6: =A6&" - "&C6&" - "&B6 -> Bùi Đình Túy - HCM_NM_BĐT - Triều Lên | G6: =A6&" - "&B6 -> Bùi Đình Túy - Triều Lên | H6: =A6&" - "&B6&" (QC - "&Sheet2!$A$2&")" -> Bùi Đình Túy - Triều Lên (QC - Mẫu lặp hiện trường) | I6: =A6&" - "&B6&" (QC - "&Sheet2!$A$1&")" -> Bùi Đình Túy - Triều Lên (QC - Mẫu trắng hiện trường) | J6: =A6&" - "&B6&" (QC - "&Sheet2!$A$3&")" -> Bùi Đình Túy - Triều Lên (QC - Mẫu trắng vận chuyển) | K6: =A6&" - "&B6&" (QC - "&Sheet2!$A$4&")" -> Bùi Đình Túy - Triều Lên (QC - Mẫu trắng thiết bị)
A7: Cầu Đỏ | B7: Triều Lên | C7: HCM_NM_CĐ | D7: HCM_NM_CĐ_L | E7: Khu vực Cầu Đỏ trên đường Nguyễn Xí, đoạn qua rạch Cầu Sơn | F7: =A7&" - "&C7&" - "&B7 -> Cầu Đỏ - HCM_NM_CĐ - Triều Lên | G7: =A7&" - "&B7 -> Cầu Đỏ - Triều Lên | H7: =A7&" - "&B7&" (QC - "&Sheet2!$A$2&")" -> Cầu Đỏ - Triều Lên (QC - Mẫu lặp hiện trường) | I7: =A7&" - "&B7&" (QC - "&Sheet2!$A$1&")" -> Cầu Đỏ - Triều Lên (QC - Mẫu trắng hiện trường) | J7: =A7&" - "&B7&" (QC - "&Sheet2!$A$3&")" -> Cầu Đỏ - Triều Lên (QC - Mẫu trắng vận chuyển) | K7: =A7&" - "&B7&" (QC - "&Sheet2!$A$4&")" -> Cầu Đỏ - Triều Lên (QC - Mẫu trắng thiết bị)
A8: Thị Nghè 2 | B8: Triều Lên | C8: HCM_NM_TN2 | D8: HCM_NM_TN2_L | E8: Khu vực cầu Thị Nghè 2 trên đường Nguyễn Hữu Cảnh, gần Thảo Cầm Viên | F8: =A8&" - "&C8&" - "&B8 -> Thị Nghè 2 - HCM_NM_TN2 - Triều Lên | G8: =A8&" - "&B8 -> Thị Nghè 2 - Triều Lên | H8: =A8&" - "&B8&" (QC - "&Sheet2!$A$2&")" -> Thị Nghè 2 - Triều Lên (QC - Mẫu lặp hiện trường) | I8: =A8&" - "&B8&" (QC - "&Sheet2!$A$1&")" -> Thị Nghè 2 - Triều Lên (QC - Mẫu trắng hiện trường) | J8: =A8&" - "&B8&" (QC - "&Sheet2!$A$3&")" -> Thị Nghè 2 - Triều Lên (QC - Mẫu trắng vận chuyển) | K8: =A8&" - "&B8&" (QC - "&Sheet2!$A$4&")" -> Thị Nghè 2 - Triều Lên (QC - Mẫu trắng thiết bị)
A9: Bùi Hữu Nghĩa | B9: Triều Lên | C9: HCM_NM_BHN | D9: HCM_NM_BHN_L | E9: Khu vực cầu Bùi Hữu Nghĩa, đoạn rạch Cầu Bông đổ ra kênh Nhiêu Lộc – Thị Nghè | F9: =A9&" - "&C9&" - "&B9 -> Bùi Hữu Nghĩa - HCM_NM_BHN - Triều Lên | G9: =A9&" - "&B9 -> Bùi Hữu Nghĩa - Triều Lên | H9: =A9&" - "&B9&" (QC - "&Sheet2!$A$2&")" -> Bùi Hữu Nghĩa - Triều Lên (QC - Mẫu lặp hiện trường) | I9: =A9&" - "&B9&" (QC - "&Sheet2!$A$1&")" -> Bùi Hữu Nghĩa - Triều Lên (QC - Mẫu trắng hiện trường) | J9: =A9&" - "&B9&" (QC - "&Sheet2!$A$3&")" -> Bùi Hữu Nghĩa - Triều Lên (QC - Mẫu trắng vận chuyển) | K9: =A9&" - "&B9&" (QC - "&Sheet2!$A$4&")" -> Bùi Hữu Nghĩa - Triều Lên (QC - Mẫu trắng thiết bị)
A10: Cầu Văn Thánh | B10: Triều Lên | C10: HCM_NM_RVT | D10: HCM_NM_RVT_L | E10: Khu vực cầu Văn Thánh trên đường Điện Biên Phủ | F10: =A10&" - "&C10&" - "&B10 -> Cầu Văn Thánh - HCM_NM_RVT - Triều Lên | G10: =A10&" - "&B10 -> Cầu Văn Thánh - Triều Lên | H10: =A10&" - "&B10&" (QC - "&Sheet2!$A$2&")" -> Cầu Văn Thánh - Triều Lên (QC - Mẫu lặp hiện trường) | I10: =A10&" - "&B10&" (QC - "&Sheet2!$A$1&")" -> Cầu Văn Thánh - Triều Lên (QC - Mẫu trắng hiện trường) | J10: =A10&" - "&B10&" (QC - "&Sheet2!$A$3&")" -> Cầu Văn Thánh - Triều Lên (QC - Mẫu trắng vận chuyển) | K10: =A10&" - "&B10&" (QC - "&Sheet2!$A$4&")" -> Cầu Văn Thánh - Triều Lên (QC - Mẫu trắng thiết bị)
A11: Cầu Văn Thánh 2 | B11: Triều Lên | C11: HCM_NM_RVT2 | D11: HCM_NM_RVT2_L | E11: Khu vực cầu Văn Thánh 2 trên đường Nguyễn Hữu Cảnh, đoạn qua rạch Văn Thánh | F11: =A11&" - "&C11&" - "&B11 -> Cầu Văn Thánh 2 - HCM_NM_RVT2 - Triều Lên | G11: =A11&" - "&B11 -> Cầu Văn Thánh 2 - Triều Lên | H11: =A11&" - "&B11&" (QC - "&Sheet2!$A$2&")" -> Cầu Văn Thánh 2 - Triều Lên (QC - Mẫu lặp hiện trường) | I11: =A11&" - "&B11&" (QC - "&Sheet2!$A$1&")" -> Cầu Văn Thánh 2 - Triều Lên (QC - Mẫu trắng hiện trường) | J11: =A11&" - "&B11&" (QC - "&Sheet2!$A$3&")" -> Cầu Văn Thánh 2 - Triều Lên (QC - Mẫu trắng vận chuyển) | K11: =A11&" - "&B11&" (QC - "&Sheet2!$A$4&")" -> Cầu Văn Thánh 2 - Triều Lên (QC - Mẫu trắng thiết bị)
A12: Cầu số 1 | B12: Triều Xuống | C12: HCM_NM_CS1 | D12: HCM_NM_CS1_X | E12: Khu vực Cầu số 1, đầu tuyến kênh Nhiêu Lộc – Thị Nghè | F12: =A12&" - "&C12&" - "&B12 -> Cầu số 1 - HCM_NM_CS1 - Triều Xuống | G12: =A12&" - "&B12 -> Cầu số 1 - Triều Xuống | H12: =A12&" - "&B12&" (QC - "&Sheet2!$A$2&")" -> Cầu số 1 - Triều Xuống (QC - Mẫu lặp hiện trường) | I12: =A12&" - "&B12&" (QC - "&Sheet2!$A$1&")" -> Cầu số 1 - Triều Xuống (QC - Mẫu trắng hiện trường) | J12: =A12&" - "&B12&" (QC - "&Sheet2!$A$3&")" -> Cầu số 1 - Triều Xuống (QC - Mẫu trắng vận chuyển) | K12: =A12&" - "&B12&" (QC - "&Sheet2!$A$4&")" -> Cầu số 1 - Triều Xuống (QC - Mẫu trắng thiết bị)
A13: Lê Văn Sỹ | B13: Triều Xuống | C13: HCM_NM_LVS | D13: HCM_NM_LVS_X | E13: Khu vực cầu Lê Văn Sỹ, nối đường Lê Văn Sỹ và đường Trần Quốc Thảo | F13: =A13&" - "&C13&" - "&B13 -> Lê Văn Sỹ - HCM_NM_LVS - Triều Xuống | G13: =A13&" - "&B13 -> Lê Văn Sỹ - Triều Xuống | H13: =A13&" - "&B13&" (QC - "&Sheet2!$A$2&")" -> Lê Văn Sỹ - Triều Xuống (QC - Mẫu lặp hiện trường) | I13: =A13&" - "&B13&" (QC - "&Sheet2!$A$1&")" -> Lê Văn Sỹ - Triều Xuống (QC - Mẫu trắng hiện trường) | J13: =A13&" - "&B13&" (QC - "&Sheet2!$A$3&")" -> Lê Văn Sỹ - Triều Xuống (QC - Mẫu trắng vận chuyển) | K13: =A13&" - "&B13&" (QC - "&Sheet2!$A$4&")" -> Lê Văn Sỹ - Triều Xuống (QC - Mẫu trắng thiết bị)
... A21: Cầu Văn Thánh 2 | B21: Triều Xuống | C21: HCM_NM_RVT2 | D21: HCM_NM_RVT2_X | E21: Khu vực cầu Văn Thánh 2 trên đường Nguyễn Hữu Cảnh, đoạn qua rạch Văn Thánh | F21: =A21&" - "&C21&" - "&B21 -> Cầu Văn Thánh 2 - HCM_NM_RVT2 - Triều Xuống | G21: =A21&" - "&B21 -> Cầu Văn Thánh 2 - Triều Xuống | H21: =A21&" - "&B21&" (QC - "&Sheet2!$A$2&")" -> Cầu Văn Thánh 2 - Triều Xuống (QC - Mẫu lặp hiện trường) | I21: =A21&" - "&B21&" (QC - "&Sheet2!$A$1&")" -> Cầu Văn Thánh 2 - Triều Xuống (QC - Mẫu trắng hiện trường) | J21: =A21&" - "&B21&" (QC - "&Sheet2!$A$3&")" -> Cầu Văn Thánh 2 - Triều Xuống (QC - Mẫu trắng vận chuyển) | K21: =A21&" - "&B21&" (QC - "&Sheet2!$A$4&")" -> Cầu Văn Thánh 2 - Triều Xuống (QC - Mẫu trắng thiết bị)
A22: TBNM15 | B22: 01 | C22: HCM_NM_TBNM15 | D22: =C22&"_"&B22 -> HCM_NM_TBNM15_01 | E22: Kênh 18 – Cách nhà máy Vietstar 300m về hướng ngược dòng chảy. | F22: =A22&" - "&C22&" - "&B22 -> TBNM15 - HCM_NM_TBNM15 - 01 | G22: =A22&" - "&B22 -> TBNM15 - 01 | H22: =A22&" - "&B22&" (QC - "&Sheet2!$A$2&")" -> TBNM15 - 01 (QC - Mẫu lặp hiện trường) | I22: =A22&" - "&B22&" (QC - "&Sheet2!$A$1&")" -> TBNM15 - 01 (QC - Mẫu trắng hiện trường) | J22: =A22&" - "&B22&" (QC - "&Sheet2!$A$3&")" -> TBNM15 - 01 (QC - Mẫu trắng vận chuyển) | K22: =A22&" - "&B22&" (QC - "&Sheet2!$A$4&")" -> TBNM15 - 01 (QC - Mẫu trắng thiết bị)
A23: TBNM5 | B23: 01 | C23: HCM_NM_TBNM5 | D23: =C23&"_"&B23 -> HCM_NM_TBNM5_01 | E23: Kênh Thầy Cai – cách kênh 18 khoảng 500 m, hướng về phía thượng nguồn. | F23: =A23&" - "&C23&" - "&B23 -> TBNM5 - HCM_NM_TBNM5 - 01 | G23: =A23&" - "&B23 -> TBNM5 - 01 | H23: =A23&" - "&B23&" (QC - "&Sheet2!$A$2&")" -> TBNM5 - 01 (QC - Mẫu lặp hiện trường) | I23: =A23&" - "&B23&" (QC - "&Sheet2!$A$1&")" -> TBNM5 - 01 (QC - Mẫu trắng hiện trường) | J23: =A23&" - "&B23&" (QC - "&Sheet2!$A$3&")" -> TBNM5 - 01 (QC - Mẫu trắng vận chuyển) | K23: =A23&" - "&B23&" (QC - "&Sheet2!$A$4&")" -> TBNM5 - 01 (QC - Mẫu trắng thiết bị)
A24: Cầu Tân Thái | B24: Triều Lên | C24: HCM_NM_CTT | D24: HCM_NM_CTT_L | E24: Cầu Tân Thái, TL 822, ranh giới giữa Phường Thái Mỹ và tỉnh Tây Ninh | F24: =A24&" - "&C24&" - "&B24 -> Cầu Tân Thái - HCM_NM_CTT - Triều Lên | G24: =A24&" - "&B24 -> Cầu Tân Thái - Triều Lên | H24: =A24&" - "&B24&" (QC - "&Sheet2!$A$2&")" -> Cầu Tân Thái - Triều Lên (QC - Mẫu lặp hiện trường) | I24: =A24&" - "&B24&" (QC - "&Sheet2!$A$1&")" -> Cầu Tân Thái - Triều Lên (QC - Mẫu trắng hiện trường) | J24: =A24&" - "&B24&" (QC - "&Sheet2!$A$3&")" -> Cầu Tân Thái - Triều Lên (QC - Mẫu trắng vận chuyển) | K24: =A24&" - "&B24&" (QC - "&Sheet2!$A$4&")" -> Cầu Tân Thái - Triều Lên (QC - Mẫu trắng thiết bị)
A25: TBNM14 | B25: 01 | C25: HCM_NM_TBNM14 | D25: =C25&"_"&B25 -> HCM_NM_TBNM14_01 | E25: Kênh 17 – Đầu kênh | F25: =A25&" - "&C25&" - "&B25 -> TBNM14 - HCM_NM_TBNM14 - 01 | G25: =A25&" - "&B25 -> TBNM14 - 01 | H25: =A25&" - "&B25&" (QC - "&Sheet2!$A$2&")" -> TBNM14 - 01 (QC - Mẫu lặp hiện trường) | I25: =A25&" - "&B25&" (QC - "&Sheet2!$A$1&")" -> TBNM14 - 01 (QC - Mẫu trắng hiện trường) | J25: =A25&" - "&B25&" (QC - "&Sheet2!$A$3&")" -> TBNM14 - 01 (QC - Mẫu trắng vận chuyển) | K25: =A25&" - "&B25&" (QC - "&Sheet2!$A$4&")" -> TBNM14 - 01 (QC - Mẫu trắng thiết bị)
A26: TBNM9 | B26: 01 | C26: HCM_NM_TBNM9 | D26: =C26&"_"&B26 -> HCM_NM_TBNM9_01 | E26: Kênh 15 – Thượng nguồn - Cách bãi số 3 khoảng 500 m ngược hướng dòng chảy | F26: =A26&" - "&C26&" - "&B26 -> TBNM9 - HCM_NM_TBNM9 - 01 | G26: =A26&" - "&B26 -> TBNM9 - 01 | H26: =A26&" - "&B26&" (QC - "&Sheet2!$A$2&")" -> TBNM9 - 01 (QC - Mẫu lặp hiện trường) | I26: =A26&" - "&B26&" (QC - "&Sheet2!$A$1&")" -> TBNM9 - 01 (QC - Mẫu trắng hiện trường) | J26: =A26&" - "&B26&" (QC - "&Sheet2!$A$3&")" -> TBNM9 - 01 (QC - Mẫu trắng vận chuyển) | K26: =A26&" - "&B26&" (QC - "&Sheet2!$A$4&")" -> TBNM9 - 01 (QC - Mẫu trắng thiết bị)
A27: TBNM11 | B27: 01 | C27: HCM_NM_TBNM11 | D27: =C27&"_"&B27 -> HCM_NM_TBNM11_01 | E27: Kênh 16 – giáp bãi chôn lấp số 3 (đầu kênh) | F27: =A27&" - "&C27&" - "&B27 -> TBNM11 - HCM_NM_TBNM11 - 01 | G27: =A27&" - "&B27 -> TBNM11 - 01 | H27: =A27&" - "&B27&" (QC - "&Sheet2!$A$2&")" -> TBNM11 - 01 (QC - Mẫu lặp hiện trường) | I27: =A27&" - "&B27&" (QC - "&Sheet2!$A$1&")" -> TBNM11 - 01 (QC - Mẫu trắng hiện trường) | J27: =A27&" - "&B27&" (QC - "&Sheet2!$A$3&")" -> TBNM11 - 01 (QC - Mẫu trắng vận chuyển) | K27: =A27&" - "&B27&" (QC - "&Sheet2!$A$4&")" -> TBNM11 - 01 (QC - Mẫu trắng thiết bị)
A28: TBNM1 | B28: 01 | C28: HCM_NM_TBNM1 | D28: =C28&"_"&B28 -> HCM_NM_TBNM1_01 | E28: Kênh Thầy Cai – cách ngã 3 kênh 15 và kênh Thầy Cai khoảng 500 m về hướng dân cư. | F28: =A28&" - "&C28&" - "&B28 -> TBNM1 - HCM_NM_TBNM1 - 01 | G28: =A28&" - "&B28 -> TBNM1 - 01 | H28: =A28&" - "&B28&" (QC - "&Sheet2!$A$2&")" -> TBNM1 - 01 (QC - Mẫu lặp hiện trường) | I28: =A28&" - "&B28&" (QC - "&Sheet2!$A$1&")" -> TBNM1 - 01 (QC - Mẫu trắng hiện trường) | J28: =A28&" - "&B28&" (QC - "&Sheet2!$A$3&")" -> TBNM1 - 01 (QC - Mẫu trắng vận chuyển) | K28: =A28&" - "&B28&" (QC - "&Sheet2!$A$4&")" -> TBNM1 - 01 (QC - Mẫu trắng thiết bị)
A29: Thầy Cai | B29: Triều Lên | C29: HCM_NM_TCa | D29: HCM_NM_TCa_L | E29: Tại khu vực cầu Thầy Cai. | F29: =A29&" - "&C29&" - "&B29 -> Thầy Cai - HCM_NM_TCa - Triều Lên | G29: =A29&" - "&B29 -> Thầy Cai - Triều Lên | H29: =A29&" - "&B29&" (QC - "&Sheet2!$A$2&")" -> Thầy Cai - Triều Lên (QC - Mẫu lặp hiện trường) | I29: =A29&" - "&B29&" (QC - "&Sheet2!$A$1&")" -> Thầy Cai - Triều Lên (QC - Mẫu trắng hiện trường) | J29: =A29&" - "&B29&" (QC - "&Sheet2!$A$3&")" -> Thầy Cai - Triều Lên (QC - Mẫu trắng vận chuyển) | K29: =A29&" - "&B29&" (QC - "&Sheet2!$A$4&")" -> Thầy Cai - Triều Lên (QC - Mẫu trắng thiết bị)
A30: TBNM15 | B30: 02 | C30: HCM_NM_TBNM15 | D30: =C30&"_"&B30 -> HCM_NM_TBNM15_02 | E30: Kênh 18 – Cách nhà máy Vietstar 300m về hướng ngược dòng chảy. | F30: =A30&" - "&C30&" - "&B30 -> TBNM15 - HCM_NM_TBNM15 - 02 | G30: =A30&" - "&B30 -> TBNM15 - 02 | H30: =A30&" - "&B30&" (QC - "&Sheet2!$A$2&")" -> TBNM15 - 02 (QC - Mẫu lặp hiện trường) | I30: =A30&" - "&B30&" (QC - "&Sheet2!$A$1&")" -> TBNM15 - 02 (QC - Mẫu trắng hiện trường) | J30: =A30&" - "&B30&" (QC - "&Sheet2!$A$3&")" -> TBNM15 - 02 (QC - Mẫu trắng vận chuyển) | K30: =A30&" - "&B30&" (QC - "&Sheet2!$A$4&")" -> TBNM15 - 02 (QC - Mẫu trắng thiết bị)
A31: TBNM5 | B31: 02 | C31: HCM_NM_TBNM5 | D31: =C31&"_"&B31 -> HCM_NM_TBNM5_02 | E31: Kênh Thầy Cai – cách kênh 18 khoảng 500 m, hướng về phía thượng nguồn. | F31: =A31&" - "&C31&" - "&B31 -> TBNM5 - HCM_NM_TBNM5 - 02 | G31: =A31&" - "&B31 -> TBNM5 - 02 | H31: =A31&" - "&B31&" (QC - "&Sheet2!$A$2&")" -> TBNM5 - 02 (QC - Mẫu lặp hiện trường) | I31: =A31&" - "&B31&" (QC - "&Sheet2!$A$1&")" -> TBNM5 - 02 (QC - Mẫu trắng hiện trường) | J31: =A31&" - "&B31&" (QC - "&Sheet2!$A$3&")" -> TBNM5 - 02 (QC - Mẫu trắng vận chuyển) | K31: =A31&" - "&B31&" (QC - "&Sheet2!$A$4&")" -> TBNM5 - 02 (QC - Mẫu trắng thiết bị)
A32: Cầu Tân Thái | B32: Triều Xuống | C32: HCM_NM_CTT | D32: HCM_NM_CTT_X | E32: Cầu Tân Thái, TL 822, ranh giới giữa Phường Thái Mỹ và tỉnh Tây Ninh | F32: =A32&" - "&C32&" - "&B32 -> Cầu Tân Thái - HCM_NM_CTT - Triều Xuống | G32: =A32&" - "&B32 -> Cầu Tân Thái - Triều Xuống | H32: =A32&" - "&B32&" (QC - "&Sheet2!$A$2&")" -> Cầu Tân Thái - Triều Xuống (QC - Mẫu lặp hiện trường) | I32: =A32&" - "&B32&" (QC - "&Sheet2!$A$1&")" -> Cầu Tân Thái - Triều Xuống (QC - Mẫu trắng hiện trường) | J32: =A32&" - "&B32&" (QC - "&Sheet2!$A$3&")" -> Cầu Tân Thái - Triều Xuống (QC - Mẫu trắng vận chuyển) | K32: =A32&" - "&B32&" (QC - "&Sheet2!$A$4&")" -> Cầu Tân Thái - Triều Xuống (QC - Mẫu trắng thiết bị)
A33: TBNM14 | B33: 02 | C33: HCM_NM_TBNM14 | D33: =C33&"_"&B33 -> HCM_NM_TBNM14_02 | E33: Kênh 17 – Đầu kênh | F33: =A33&" - "&C33&" - "&B33 -> TBNM14 - HCM_NM_TBNM14 - 02 | G33: =A33&" - "&B33 -> TBNM14 - 02 | H33: =A33&" - "&B33&" (QC - "&Sheet2!$A$2&")" -> TBNM14 - 02 (QC - Mẫu lặp hiện trường) | I33: =A33&" - "&B33&" (QC - "&Sheet2!$A$1&")" -> TBNM14 - 02 (QC - Mẫu trắng hiện trường) | J33: =A33&" - "&B33&" (QC - "&Sheet2!$A$3&")" -> TBNM14 - 02 (QC - Mẫu trắng vận chuyển) | K33: =A33&" - "&B33&" (QC - "&Sheet2!$A$4&")" -> TBNM14 - 02 (QC - Mẫu trắng thiết bị)
A34: TBNM9 | B34: 02 | C34: HCM_NM_TBNM9 | D34: =C34&"_"&B34 -> HCM_NM_TBNM9_02 | E34: Kênh 15 – Thượng nguồn - Cách bãi số 3 khoảng 500 m ngược hướng dòng chảy | F34: =A34&" - "&C34&" - "&B34 -> TBNM9 - HCM_NM_TBNM9 - 02 | G34: =A34&" - "&B34 -> TBNM9 - 02 | H34: =A34&" - "&B34&" (QC - "&Sheet2!$A$2&")" -> TBNM9 - 02 (QC - Mẫu lặp hiện trường) | I34: =A34&" - "&B34&" (QC - "&Sheet2!$A$1&")" -> TBNM9 - 02 (QC - Mẫu trắng hiện trường) | J34: =A34&" - "&B34&" (QC - "&Sheet2!$A$3&")" -> TBNM9 - 02 (QC - Mẫu trắng vận chuyển) | K34: =A34&" - "&B34&" (QC - "&Sheet2!$A$4&")" -> TBNM9 - 02 (QC - Mẫu trắng thiết bị)
A35: TBNM11 | B35: 02 | C35: HCM_NM_TBNM11 | D35: =C35&"_"&B35 -> HCM_NM_TBNM11_02 | E35: Kênh 16 – giáp bãi chôn lấp số 3 (đầu kênh) | F35: =A35&" - "&C35&" - "&B35 -> TBNM11 - HCM_NM_TBNM11 - 02 | G35: =A35&" - "&B35 -> TBNM11 - 02 | H35: =A35&" - "&B35&" (QC - "&Sheet2!$A$2&")" -> TBNM11 - 02 (QC - Mẫu lặp hiện trường) | I35: =A35&" - "&B35&" (QC - "&Sheet2!$A$1&")" -> TBNM11 - 02 (QC - Mẫu trắng hiện trường) | J35: =A35&" - "&B35&" (QC - "&Sheet2!$A$3&")" -> TBNM11 - 02 (QC - Mẫu trắng vận chuyển) | K35: =A35&" - "&B35&" (QC - "&Sheet2!$A$4&")" -> TBNM11 - 02 (QC - Mẫu trắng thiết bị)
A36: TBNM1 | B36: 02 | C36: HCM_NM_TBNM1 | D36: =C36&"_"&B36 -> HCM_NM_TBNM1_02 | E36: Kênh Thầy Cai – cách ngã 3 kênh 15 và kênh Thầy Cai khoảng 500 m về hướng dân cư. | F36: =A36&" - "&C36&" - "&B36 -> TBNM1 - HCM_NM_TBNM1 - 02 | G36: =A36&" - "&B36 -> TBNM1 - 02 | H36: =A36&" - "&B36&" (QC - "&Sheet2!$A$2&")" -> TBNM1 - 02 (QC - Mẫu lặp hiện trường) | I36: =A36&" - "&B36&" (QC - "&Sheet2!$A$1&")" -> TBNM1 - 02 (QC - Mẫu trắng hiện trường) | J36: =A36&" - "&B36&" (QC - "&Sheet2!$A$3&")" -> TBNM1 - 02 (QC - Mẫu trắng vận chuyển) | K36: =A36&" - "&B36&" (QC - "&Sheet2!$A$4&")" -> TBNM1 - 02 (QC - Mẫu trắng thiết bị)
A37: Thầy Cai | B37: Triều Xuống | C37: HCM_NM_TCa | D37: HCM_NM_TCa_X | E37: Tại khu vực cầu Thầy Cai. | F37: =A37&" - "&C37&" - "&B37 -> Thầy Cai - HCM_NM_TCa - Triều Xuống | G37: =A37&" - "&B37 -> Thầy Cai - Triều Xuống | H37: =A37&" - "&B37&" (QC - "&Sheet2!$A$2&")" -> Thầy Cai - Triều Xuống (QC - Mẫu lặp hiện trường) | I37: =A37&" - "&B37&" (QC - "&Sheet2!$A$1&")" -> Thầy Cai - Triều Xuống (QC - Mẫu trắng hiện trường) | J37: =A37&" - "&B37&" (QC - "&Sheet2!$A$3&")" -> Thầy Cai - Triều Xuống (QC - Mẫu trắng vận chuyển) | K37: =A37&" - "&B37&" (QC - "&Sheet2!$A$4&")" -> Thầy Cai - Triều Xuống (QC - Mẫu trắng thiết bị)
A38: Kênh N46 | B38: Triều Lên | C38: HCM_NM_N46 | D38: HCM_NM_N46_L | E38: Hồ chứa nước kênh Đông, xã Củ Chi | F38: =A38&" - "&C38&" - "&B38 -> Kênh N46 - HCM_NM_N46 - Triều Lên | G38: =A38&" - "&B38 -> Kênh N46 - Triều Lên | H38: =A38&" - "&B38&" (QC - "&Sheet2!$A$2&")" -> Kênh N46 - Triều Lên (QC - Mẫu lặp hiện trường) | I38: =A38&" - "&B38&" (QC - "&Sheet2!$A$1&")" -> Kênh N46 - Triều Lên (QC - Mẫu trắng hiện trường) | J38: =A38&" - "&B38&" (QC - "&Sheet2!$A$3&")" -> Kênh N46 - Triều Lên (QC - Mẫu trắng vận chuyển) | K38: =A38&" - "&B38&" (QC - "&Sheet2!$A$4&")" -> Kênh N46 - Triều Lên (QC - Mẫu trắng thiết bị)
A39: Tân Phú Trung | B39: Triều Lên | C39: HCM_NM_TPT | D39: HCM_NM_TPT_L | E39: Dọc đường Tam Tân cách ngã giao kênh Thầy Cai và kênh An Hạ 1km về phía Tây | F39: =A39&" - "&C39&" - "&B39 -> Tân Phú Trung - HCM_NM_TPT - Triều Lên | G39: =A39&" - "&B39 -> Tân Phú Trung - Triều Lên | H39: =A39&" - "&B39&" (QC - "&Sheet2!$A$2&")" -> Tân Phú Trung - Triều Lên (QC - Mẫu lặp hiện trường) | I39: =A39&" - "&B39&" (QC - "&Sheet2!$A$1&")" -> Tân Phú Trung - Triều Lên (QC - Mẫu trắng hiện trường) | J39: =A39&" - "&B39&" (QC - "&Sheet2!$A$3&")" -> Tân Phú Trung - Triều Lên (QC - Mẫu trắng vận chuyển) | K39: =A39&" - "&B39&" (QC - "&Sheet2!$A$4&")" -> Tân Phú Trung - Triều Lên (QC - Mẫu trắng thiết bị)
A40: TC18A | B40: Triều Lên | C40: HCM_NM_TC18A | D40: HCM_NM_TC18A_L | E40: Trước cổng công ty Fujifilm | F40: =A40&" - "&C40&" - "&B40 -> TC18A - HCM_NM_TC18A - Triều Lên | G40: =A40&" - "&B40 -> TC18A - Triều Lên | H40: =A40&" - "&B40&" (QC - "&Sheet2!$A$2&")" -> TC18A - Triều Lên (QC - Mẫu lặp hiện trường) | I40: =A40&" - "&B40&" (QC - "&Sheet2!$A$1&")" -> TC18A - Triều Lên (QC - Mẫu trắng hiện trường) | J40: =A40&" - "&B40&" (QC - "&Sheet2!$A$3&")" -> TC18A - Triều Lên (QC - Mẫu trắng vận chuyển) | K40: =A40&" - "&B40&" (QC - "&Sheet2!$A$4&")" -> TC18A - Triều Lên (QC - Mẫu trắng thiết bị)
A41: An Hạ 1 | B41: Triều Lên | C41: HCM_NM_AH1 | D41: HCM_NM_AH1_L | E41: Cầu An Hạ, QL 22 | F41: =A41&" - "&C41&" - "&B41 -> An Hạ 1 - HCM_NM_AH1 - Triều Lên | G41: =A41&" - "&B41 -> An Hạ 1 - Triều Lên | H41: =A41&" - "&B41&" (QC - "&Sheet2!$A$2&")" -> An Hạ 1 - Triều Lên (QC - Mẫu lặp hiện trường) | I41: =A41&" - "&B41&" (QC - "&Sheet2!$A$1&")" -> An Hạ 1 - Triều Lên (QC - Mẫu trắng hiện trường) | J41: =A41&" - "&B41&" (QC - "&Sheet2!$A$3&")" -> An Hạ 1 - Triều Lên (QC - Mẫu trắng vận chuyển) | K41: =A41&" - "&B41&" (QC - "&Sheet2!$A$4&")" -> An Hạ 1 - Triều Lên (QC - Mẫu trắng thiết bị)
A42: Cầu TL9 | B42: Triều Lên | C42: HCM_NM_CTL9 | D42: HCM_NM_CTL9_L | E42: Tại khu vực cầu TL9 | F42: =A42&" - "&C42&" - "&B42 -> Cầu TL9 - HCM_NM_CTL9 - Triều Lên | G42: =A42&" - "&B42 -> Cầu TL9 - Triều Lên | H42: =A42&" - "&B42&" (QC - "&Sheet2!$A$2&")" -> Cầu TL9 - Triều Lên (QC - Mẫu lặp hiện trường) | I42: =A42&" - "&B42&" (QC - "&Sheet2!$A$1&")" -> Cầu TL9 - Triều Lên (QC - Mẫu trắng hiện trường) | J42: =A42&" - "&B42&" (QC - "&Sheet2!$A$3&")" -> Cầu TL9 - Triều Lên (QC - Mẫu trắng vận chuyển) | K42: =A42&" - "&B42&" (QC - "&Sheet2!$A$4&")" -> Cầu TL9 - Triều Lên (QC - Mẫu trắng thiết bị)
A43: Xuân Thới Sơn | B43: Triều Lên | C43: HCM_NM_XTS | D43: HCM_NM_XTS_L | E43: Dọc đường Thanh Niên đối diện với cơ sở xã hội Nhị Xuân | F43: =A43&" - "&C43&" - "&B43 -> Xuân Thới Sơn - HCM_NM_XTS - Triều Lên | G43: =A43&" - "&B43 -> Xuân Thới Sơn - Triều Lên | H43: =A43&" - "&B43&" (QC - "&Sheet2!$A$2&")" -> Xuân Thới Sơn - Triều Lên (QC - Mẫu lặp hiện trường) | I43: =A43&" - "&B43&" (QC - "&Sheet2!$A$1&")" -> Xuân Thới Sơn - Triều Lên (QC - Mẫu trắng hiện trường) | J43: =A43&" - "&B43&" (QC - "&Sheet2!$A$3&")" -> Xuân Thới Sơn - Triều Lên (QC - Mẫu trắng vận chuyển) | K43: =A43&" - "&B43&" (QC - "&Sheet2!$A$4&")" -> Xuân Thới Sơn - Triều Lên (QC - Mẫu trắng thiết bị)
A44: Cầu Lớn | B44: Triều Lên | C44: HCM_NM_CLo | D44: HCM_NM_CLo_L | E44: Tại khu vực cầu Lớn | F44: =A44&" - "&C44&" - "&B44 -> Cầu Lớn - HCM_NM_CLo - Triều Lên | G44: =A44&" - "&B44 -> Cầu Lớn - Triều Lên | H44: =A44&" - "&B44&" (QC - "&Sheet2!$A$2&")" -> Cầu Lớn - Triều Lên (QC - Mẫu lặp hiện trường) | I44: =A44&" - "&B44&" (QC - "&Sheet2!$A$1&")" -> Cầu Lớn - Triều Lên (QC - Mẫu trắng hiện trường) | J44: =A44&" - "&B44&" (QC - "&Sheet2!$A$3&")" -> Cầu Lớn - Triều Lên (QC - Mẫu trắng vận chuyển) | K44: =A44&" - "&B44&" (QC - "&Sheet2!$A$4&")" -> Cầu Lớn - Triều Lên (QC - Mẫu trắng thiết bị)
A45: An Hạ | B45: Triều Lên | C45: HCM_NM_AH | D45: HCM_NM_AH_L | E45: Cầu Xáng, đường Trần Văn Giàu, Xã Tân Vĩnh Lộc | F45: =A45&" - "&C45&" - "&B45 -> An Hạ - HCM_NM_AH - Triều Lên | G45: =A45&" - "&B45 -> An Hạ - Triều Lên | H45: =A45&" - "&B45&" (QC - "&Sheet2!$A$2&")" -> An Hạ - Triều Lên (QC - Mẫu lặp hiện trường) | I45: =A45&" - "&B45&" (QC - "&Sheet2!$A$1&")" -> An Hạ - Triều Lên (QC - Mẫu trắng hiện trường) | J45: =A45&" - "&B45&" (QC - "&Sheet2!$A$3&")" -> An Hạ - Triều Lên (QC - Mẫu trắng vận chuyển) | K45: =A45&" - "&B45&" (QC - "&Sheet2!$A$4&")" -> An Hạ - Triều Lên (QC - Mẫu trắng thiết bị)
A46: Rau Răm | B46: Triều Lên | C46: HCM_NM_RR | D46: HCM_NM_RR_L | E46: Tại khu vực cầu Rau Răm | F46: =A46&" - "&C46&" - "&B46 -> Rau Răm - HCM_NM_RR - Triều Lên | G46: =A46&" - "&B46 -> Rau Răm - Triều Lên | H46: =A46&" - "&B46&" (QC - "&Sheet2!$A$2&")" -> Rau Răm - Triều Lên (QC - Mẫu lặp hiện trường) | I46: =A46&" - "&B46&" (QC - "&Sheet2!$A$1&")" -> Rau Răm - Triều Lên (QC - Mẫu trắng hiện trường) | J46: =A46&" - "&B46&" (QC - "&Sheet2!$A$3&")" -> Rau Răm - Triều Lên (QC - Mẫu trắng vận chuyển) | K46: =A46&" - "&B46&" (QC - "&Sheet2!$A$4&")" -> Rau Răm - Triều Lên (QC - Mẫu trắng thiết bị)
A47: Kênh N46 | B47: Triều Xuống | C47: HCM_NM_N46 | D47: HCM_NM_N46_X | E47: Hồ chứa nước kênh Đông, xã Củ Chi | F47: =A47&" - "&C47&" - "&B47 -> Kênh N46 - HCM_NM_N46 - Triều Xuống | G47: =A47&" - "&B47 -> Kênh N46 - Triều Xuống | H47: =A47&" - "&B47&" (QC - "&Sheet2!$A$2&")" -> Kênh N46 - Triều Xuống (QC - Mẫu lặp hiện trường) | I47: =A47&" - "&B47&" (QC - "&Sheet2!$A$1&")" -> Kênh N46 - Triều Xuống (QC - Mẫu trắng hiện trường) | J47: =A47&" - "&B47&" (QC - "&Sheet2!$A$3&")" -> Kênh N46 - Triều Xuống (QC - Mẫu trắng vận chuyển) | K47: =A47&" - "&B47&" (QC - "&Sheet2!$A$4&")" -> Kênh N46 - Triều Xuống (QC - Mẫu trắng thiết bị)
...

Sheet Sheet1
A1: Địa điểm quan trắc | B1: Triều | C1: Ký hiệu | D1: Tên viết tắt | E1: Địa chỉ | F1: Tên nơi lấy mẫu | G1: Tên vị trí | H1: Tên vị trí mẫu lặp | I1: Tên vị trí mẫu trắng hiện trường | J1: Tên vị trí mẫu trắng vận chuyển | K1: Tên vị trí mẫu trắng thiết bị
A2: Cầu số 1 | B2: Triều Lên | C2: HCM_NM_CS1 | D2: HCM_NM_CS1_L | E2: Khu vực Cầu số 1, đầu tuyến kênh Nhiêu Lộc – Thị Nghè | F2: Cầu số 1 - HCM_NM_CS1 - Triều Lên | G2: Cầu số 1 - Triều Lên | H2: Cầu số 1 - Triều Lên (QC - Mẫu lặp hiện trường) | I2: Cầu số 1 - Triều Lên (QC - Mẫu trắng hiện trường) | J2: Cầu số 1 - Triều Lên (QC - Mẫu trắng vận chuyển) | K2: Cầu số 1 - Triều Lên (QC - Mẫu trắng thiết bị)
A3: Lê Văn Sỹ | B3: Triều Lên | C3: HCM_NM_LVS | D3: HCM_NM_LVS_L | E3: Khu vực cầu Lê Văn Sỹ, nối đường Lê Văn Sỹ và đường Trần Quốc Thảo | F3: Lê Văn Sỹ - HCM_NM_LVS - Triều Lên | G3: Lê Văn Sỹ - Triều Lên | H3: Lê Văn Sỹ - Triều Lên (QC - Mẫu lặp hiện trường) | I3: Lê Văn Sỹ - Triều Lên (QC - Mẫu trắng hiện trường) | J3: Lê Văn Sỹ - Triều Lên (QC - Mẫu trắng vận chuyển) | K3: Lê Văn Sỹ - Triều Lên (QC - Mẫu trắng thiết bị)
A4: Hải Đức | B4: Triều Lên | C4: HCM_NM_HĐ | D4: HCM_NM_HĐ_L | E4: Đoạn kênh khu vực gần Chùa Hải Đức, phường Cầu Kiệu | F4: Hải Đức - HCM_NM_HĐ - Triều Lên | G4: Hải Đức - Triều Lên | H4: Hải Đức - Triều Lên (QC - Mẫu lặp hiện trường) | I4: Hải Đức - Triều Lên (QC - Mẫu trắng hiện trường) | J4: Hải Đức - Triều Lên (QC - Mẫu trắng vận chuyển) | K4: Hải Đức - Triều Lên (QC - Mẫu trắng thiết bị)
A5: Điện Biên Phủ | B5: Triều Lên | C5: HCM_NM_ĐBP | D5: HCM_NM_ĐBP_L | E5: Khu vực cầu Điện Biên Phủ, gần Vòng xoay Điện Biên Phủ | F5: Điện Biên Phủ - HCM_NM_ĐBP - Triều Lên | G5: Điện Biên Phủ - Triều Lên | H5: Điện Biên Phủ - Triều Lên (QC - Mẫu lặp hiện trường) | I5: Điện Biên Phủ - Triều Lên (QC - Mẫu trắng hiện trường) | J5: Điện Biên Phủ - Triều Lên (QC - Mẫu trắng vận chuyển) | K5: Điện Biên Phủ - Triều Lên (QC - Mẫu trắng thiết bị)
A6: Bùi Đình Túy | B6: Triều Lên | C6: HCM_NM_BĐT | D6: HCM_NM_BĐT_L | E6: Khu vực gần công viên đường số 4, giáp bờ sông, gần đường Chu Văn An, phường Bình Thạnh | F6: Bùi Đình Túy - HCM_NM_BĐT - Triều Lên | G6: Bùi Đình Túy - Triều Lên | H6: Bùi Đình Túy - Triều Lên (QC - Mẫu lặp hiện trường) | I6: Bùi Đình Túy - Triều Lên (QC - Mẫu trắng hiện trường) | J6: Bùi Đình Túy - Triều Lên (QC - Mẫu trắng vận chuyển) | K6: Bùi Đình Túy - Triều Lên (QC - Mẫu trắng thiết bị)
A7: Cầu Đỏ | B7: Triều Lên | C7: HCM_NM_CĐ | D7: HCM_NM_CĐ_L | E7: Khu vực Cầu Đỏ trên đường Nguyễn Xí, đoạn qua rạch Cầu Sơn | F7: Cầu Đỏ - HCM_NM_CĐ - Triều Lên | G7: Cầu Đỏ - Triều Lên | H7: Cầu Đỏ - Triều Lên (QC - Mẫu lặp hiện trường) | I7: Cầu Đỏ - Triều Lên (QC - Mẫu trắng hiện trường) | J7: Cầu Đỏ - Triều Lên (QC - Mẫu trắng vận chuyển) | K7: Cầu Đỏ - Triều Lên (QC - Mẫu trắng thiết bị)
A8: Thị Nghè 2 | B8: Triều Lên | C8: HCM_NM_TN2 | D8: HCM_NM_TN2_L | E8: Khu vực cầu Thị Nghè 2 trên đường Nguyễn Hữu Cảnh, gần Thảo Cầm Viên | F8: Thị Nghè 2 - HCM_NM_TN2 - Triều Lên | G8: Thị Nghè 2 - Triều Lên | H8: Thị Nghè 2 - Triều Lên (QC - Mẫu lặp hiện trường) | I8: Thị Nghè 2 - Triều Lên (QC - Mẫu trắng hiện trường) | J8: Thị Nghè 2 - Triều Lên (QC - Mẫu trắng vận chuyển) | K8: Thị Nghè 2 - Triều Lên (QC - Mẫu trắng thiết bị)
A9: Bùi Hữu Nghĩa | B9: Triều Lên | C9: HCM_NM_BHN | D9: HCM_NM_BHN_L | E9: Khu vực cầu Bùi Hữu Nghĩa, đoạn rạch Cầu Bông đổ ra kênh Nhiêu Lộc – Thị Nghè | F9: Bùi Hữu Nghĩa - HCM_NM_BHN - Triều Lên | G9: Bùi Hữu Nghĩa - Triều Lên | H9: Bùi Hữu Nghĩa - Triều Lên (QC - Mẫu lặp hiện trường) | I9: Bùi Hữu Nghĩa - Triều Lên (QC - Mẫu trắng hiện trường) | J9: Bùi Hữu Nghĩa - Triều Lên (QC - Mẫu trắng vận chuyển) | K9: Bùi Hữu Nghĩa - Triều Lên (QC - Mẫu trắng thiết bị)
A10: Cầu Văn Thánh | B10: Triều Lên | C10: HCM_NM_RVT | D10: HCM_NM_RVT_L | E10: Khu vực cầu Văn Thánh trên đường Điện Biên Phủ | F10: Cầu Văn Thánh - HCM_NM_RVT - Triều Lên | G10: Cầu Văn Thánh - Triều Lên | H10: Cầu Văn Thánh - Triều Lên (QC - Mẫu lặp hiện trường) | I10: Cầu Văn Thánh - Triều Lên (QC - Mẫu trắng hiện trường) | J10: Cầu Văn Thánh - Triều Lên (QC - Mẫu trắng vận chuyển) | K10: Cầu Văn Thánh - Triều Lên (QC - Mẫu trắng thiết bị)
A11: Cầu Văn Thánh 2 | B11: Triều Lên | C11: HCM_NM_RVT2 | D11: HCM_NM_RVT2_L | E11: Khu vực cầu Văn Thánh 2 trên đường Nguyễn Hữu Cảnh, đoạn qua rạch Văn Thánh | F11: Cầu Văn Thánh 2 - HCM_NM_RVT2 - Triều Lên | G11: Cầu Văn Thánh 2 - Triều Lên | H11: Cầu Văn Thánh 2 - Triều Lên (QC - Mẫu lặp hiện trường) | I11: Cầu Văn Thánh 2 - Triều Lên (QC - Mẫu trắng hiện trường) | J11: Cầu Văn Thánh 2 - Triều Lên (QC - Mẫu trắng vận chuyển) | K11: Cầu Văn Thánh 2 - Triều Lên (QC - Mẫu trắng thiết bị)
A12: Cầu số 1 | B12: Triều Xuống | C12: HCM_NM_CS1 | D12: HCM_NM_CS1_X | E12: Khu vực Cầu số 1, đầu tuyến kênh Nhiêu Lộc – Thị Nghè | F12: Cầu số 1 - HCM_NM_CS1 - Triều Xuống | G12: Cầu số 1 - Triều Xuống | H12: Cầu số 1 - Triều Xuống (QC - Mẫu lặp hiện trường) | I12: Cầu số 1 - Triều Xuống (QC - Mẫu trắng hiện trường) | J12: Cầu số 1 - Triều Xuống (QC - Mẫu trắng vận chuyển) | K12: Cầu số 1 - Triều Xuống (QC - Mẫu trắng thiết bị)
... A181: Đồng Tranh | B181: Triều Xuống | C181: HCM_NM_ĐT | D181: HCM_NM_ĐT_X | E181: Xã Cần Giờ - Gần cửa sông Đồng Tranh 2 km. | F181: Đồng Tranh - HCM_NM_ĐT - Triều Xuống | G181: Đồng Tranh - Triều Xuống | H181: Đồng Tranh - Triều Xuống (QC - Mẫu lặp hiện trường) | I181: Đồng Tranh - Triều Xuống (QC - Mẫu trắng hiện trường) | J181: Đồng Tranh - Triều Xuống (QC - Mẫu trắng vận chuyển) | K181: Đồng Tranh - Triều Xuống (QC - Mẫu trắng thiết bị)

Sheet Sheet2
A1: Mẫu trắng hiện trường
A2: Mẫu lặp hiện trường
A3: Mẫu trắng vận chuyển
A4: Mẫu trắng thiết bị

Sheet QUYET DINH
A2: Phú Bình | B2: HCM_NM_STT1 | C2: Định kỳ | D2: Tác động | E2: - Cầu Phú Bình.
E3: - Đánh giá chất lượng nước mặt bị tác động bởi nước thải các nhà máy sản xuất mủ cao su Phú Bình, Long Hòa và một số cơ sở chăn nuôi heo và nước thải khu dân cư.
A4: Cầu trên đường vành đai 4 | B4: HCM_NM_STT2 | C4: Tự động liên tục | D4: Tác động | E4: - Cầu trên đường vành đai 4
E5: - Đánh giá chất lượng nước mặt bị tác động bởi nước thải KCN, đô thị Bàu Bàng, các KCN và đô thị Mỹ Phước, hoạt động chăn nuôi quy mô lớn.
A6: Trạm quan trắc nước mặt tự động trên sông Thị Tính | B6: HCM_NM_STT4 | C6: Tự động liên tục | D6: Tác động | E6: - Trạm quan trắc nước mặt tự động trên sông Thị Tính.
E7: - Đánh giá chất lượng nước bị tác động bởi nước thải sau xử lý các KCN Mỹ Phước 2, Mỹ Phước 3.
A8: Ông Cộ | B8: HCM_NM_STT3 | C8: Định kỳ | D8: Tác động | E8: - Cầu Ông Cộ (Hợp lưu sông thị Tính và sông Sài Gòn) phường Phú An.
E9: - Đánh giá chất lượng nước mặt bị tác động bởi nước thải của KCN Mỹ Phước I, II, III và Cụm Công nghiệp Tân Định, nhà máy giấy Vạn Phát, Tân Thuận An, các khu dân cư thuộc phường Mỹ Phước.
A10: Bến Củi | B10: HCM_NM_SG1 | C10: Định kỳ | D10: Nền | E10: - Hạ lưu cửa xả hồ Dầu Tiếng, cách đập Dầu Tiếng 2 km.
E11: - Nhằm đánh giá chất lượng nước thượng nguồn sông Sài Gòn khu vực bắt đầu chảy qua địa phận Thành phố Hồ Chí Minh.
A12: Bến Súc | B12: HCM_NM_BS | C12: Tự động liên tục | D12: Nền | E12: - Cầu Bến Súc, TL15 xã An Nhơn Tây.
E13: - Đánh giá chất lượng nước mặt sông Sài Gòn.
A14: An Phú | B14: HCM_NM_SG5 | C14: Định kỳ | D14: Tác động | E14: - Lưu vực An Tây-Bến Cát xã An Nhơn Tây (gần Bến đò An Phú).
E15: - Đánh giá chất lượng nước sông Sài Gòn chịu ảnh hưởng bởi các KCN Việt Hương 2, Rạch Bắp, An Tây và dân cư xung quanh.
A16: Hòa Phú | B16: HCM_NM_HP | C16: Định kỳ | D16: Cấp nước | E16: - Khu vực gần trạm bơm Hòa Phú xã Bình Mỹ.
E17: - Đánh giá chất lượng nước phục vụ cho trạm cấp nước Hòa Phú.
A18: Phú Cường | B18: HCM_NM_SG2 | C18: Tự động liên tục | D18: Cấp nước | E18: - Khu vực gần họng thu nước nhà máy nước Thủ Dầu Một phường Thủ Dầu Một.
E19: - Nhằm đánh giá chất lượng nguồn nước mặt cung cấp cho mục đích sinh hoạt trên địa bàn phường Thủ Dầu Một.
A20: Phú Long | B20: HCM_NM_SG4 | C20: Tự động liên tục | D20: Tác động | E20: - Trạm thủy văn trên sông Sài Gòn.
E21: - Đánh giá chất lượng nước sông Sài Gòn chịu ảnh hưởng quá trình đô thị hóa và sản xuất công nghiệp trên địa bàn của phường Lái Thiêu.
A22: Bình Phước | B22: HCM_NM_BP | C22: Tự động liên tục | D22: Tác động | E22: - Cách ngã 3 rạch Vĩnh Bình Sông Sài Gòn 500m về phía hạ lưu.
E23: - Nhằm đánh giá chất lượng nước sông Sài Gòn bị tác động bởi nước thải từ các khu công nghiệp trên địa bàn thành phố Dĩ An, Thuận An, KCN Linh Trung 2 và các cơ sở sản xuất trên địa bàn thành phố HCM.
A24: Bình Lợi | B24: HCM_NM_BL | C24: Định kỳ | D24: Tác động | E24: - Khu vực Thanh Đa, Phường Bình Quới.
E25: - Đánh giá chất lượng nước sông Sài Gòn sau tác động của KCN Bình Chiểu.
A26: Sài Gòn | B26: HCM_NM_SG | C26: Tự động liên tục | D26: Tác động | E26: - Cầu Sài Gòn KTĐ mới Thủ Thiêm Sông Sài Gòn.
E27: - Đánh giá chất lượng nước mặt sông Sài Gòn sau khu qua khu vực dân cư phường Bình Thạnh, Phường Thạnh Mỹ Tây, Phường Bình Quới và phường An Khánh.
A28: Phú Mỹ | B28: HCM_NM_PM | C28: Tự động liên tục | D28: Tác động | E28: - Gần cầu Thời Đại, Phường Bình Trưng.
E29: - Đánh giá chất lượng nước sông Sài Gòn trước khi hợp lưu với sông Đồng Nai.
A30: Phước Hòa | B30: HCM_NM_SB1 | C30: Định kỳ | D30: Tác động | E30: - Vị trí quan trắc trên Sông Bé tại cửa xả của Hồ.
E31: - Nhằm đánh giá chất lượng nước sau đập Phước Hòa.
A32: Sông Bé 2 | B32: HCM_NM_SB2 | C32: Định kỳ | D32: Tác động | E32: - Vị trí quan trắc tại khu vực Cầu Sông Bé.
E33: - Nhằm đánh giá chất lượng nước bị tác động bởi nước thải từ các nhà máy cao su thải ra suối Lùng và đổ vào sông Bé.
A34: Sông Bé 1 | B34: HCM_NM_ĐN1 | C34: Định kỳ | D34: Nền | E34: - Tại Bến đò Lạc An (cách ngã ba sông ĐN – SB 1 km).
E35: - Đánh giá chất lượng nước mặt tại hợp lưu của sông Đồng Nai và sông Bé.
A36: Tại giao lộ với QL13 | B36: HCM_NM_SB3 | C36: Tự động liên tục | D36: Tác động | E36: - Tại giao lộ với QL13.
E37: - Nhằm đánh giá chất lượng nước cho Hồ thủy lợi Dầu Tiếng và Thành phố mới Bình Dương.
A38: Suối Giai | B38: HCM_NM_SB5 | C38: Định kỳ | D38: Nền | E38: - Suối Giai.
E39: - Nhằm đánh giá chất lượng nước suối Giai từ Bình Phước chảy vào Sông Bé, địa phận Bình Dương.
A40: Suối Rạc | B40: HCM_NM_SB4 | C40: Định kỳ | D40: Nền | E40: - Suối Rạc.
E41: - Nhằm đánh giá chất lượng nước suối Rạc từ Bình Phước chảy vào Sông Bé, Bình Dương.
...
