Workbook

Sheet Thang 05-2026
A1: Vị trí | B1: Thời gian | C1: Ngày | D1: Triều Lớn | E1: Triều Ròng | F1: Nhóm thông số mẫu thực | J1: Nhóm thông số mẫu lặp | N1: Nhóm thông số mẫu trắng | R1: Gửi mẫu | S1: Nhóm
F2: Hóa lý, vi sinh | G2: Kim loại | H2: Hóa chất bảo vệ thực vật, Cl- | I2: Trầm tích | J2: Hóa lý, vi sinh | K2: Kim loại | L2: Hóa chất bảo vệ thực vật, Cl- | M2: Trầm tích | N2: Hóa lý, vi sinh | O2: Kim loại | P2: Hóa chất bảo vệ thực vật, Cl- | Q2: Trầm tích
A3: TBNM15 | B3: 04/05/2026 | C3: 4 | F3: 2 | G3: 2 | R3: CS2
A4: TBNM5 | C4: 4 | F4: 2 | G4: 2 | R4: CS2
A5: Cầu Tân Thái | C5: 4 | F5: 2 | G5: 1 | N5: 1 | O5: 1 | R5: CS2
A6: TBNM14 | C6: 4 | F6: 2 | G6: 2 | R6: CS2
A7: TBNM9 | C7: 4 | F7: 2 | G7: 2 | J7: 1 | R7: CS2
A8: TBNM11 | C8: 4 | F8: 2 | G8: 2 | R8: CS2
A9: TBNM1 | C9: 4 | F9: 2 | G9: 2 | R9: CS2
A10: Thầy Cai | C10: 4 | F10: 2 | G10: 1 | R10: CS2
A11: Cầu Chữ Y | B11: 05/05/2026 | C11: 5 | F11: 2 | G11: 1 | R11: CS2
A12: Chà Và | C12: 5 | F12: 2 | G12: 1 | R12: CS2
A13: Chánh Hưng | C13: 5 | F13: 2 | G13: 1 | R13: CS2
A14: Nhị Thiên Đường | C14: 5 | F14: 2 | G14: 1 | R14: CS2
A15: Cầu Mống | C15: 5 | F15: 2 | G15: 1 | R15: CS2
A16: Tân Thuận | C16: 5 | F16: 2 | G16: 1 | R16: CS2
A17: Kênh Tẻ | C17: 5 | F17: 2 | G17: 1 | J17: 1 | K17: 1 | N17: 1 | O17: 1 | R17: CS2
A18: Kênh N46 | B18: 06/05/2026 | C18: 6 | F18: 2 | G18: 1 | R18: CS2
A19: Tân Phú Trung | C19: 6 | F19: 2 | G19: 1 | I19: 1 | J19: 1 | K19: 1 | R19: CS2
A20: TC18A | C20: 6 | F20: 2 | G20: 1 | R20: CS2
A21: An Hạ 1 | C21: 6 | F21: 2 | G21: 1 | N21: 1 | R21: CS2
A22: Cầu Đường A | B22: 07/05/2026 | C22: 7 | F22: 2 | G22: 1 | R22: CS2
A23: Trung Tâm | C23: 7 | F23: 2 | G23: 1 | R23: CS2
A24: Nước Lên | C24: 7 | F24: 2 | G24: 1 | R24: CS2
A25: Lương Bèo | C25: 7 | F25: 2 | G25: 1 | R25: CS2
A26: Hòa Bình | B26: 08/05/2026 | C26: 8 | F26: 2 | G26: 1 | J26: 1 | R26: CS2
A27: Ông Buông | C27: 8 | F27: 2 | G27: 1 | R27: CS2
A28: Rạch Ngựa | C28: 8 | F28: 2 | G28: 1 | R28: CS2
A29: Phú Định | C29: 8 | F29: 2 | G29: 1 | R29: CS2
A30: ĐPNM1 | B30: 11/05/2026 | C30: 11 | F30: 2 | G30: 2 | N30: 1 | R30: CS2
A31: ĐPNM4 | C31: 11 | F31: 2 | G31: 2 | R31: CS2
A32: ĐPNM5 | C32: 11 | F32: 2 | G32: 2 | R32: CS2
A33: ĐPNM8 | C33: 11 | F33: 2 | G33: 2 | R33: CS2
A34: Bà Lào | C34: 11 | F34: 2 | G34: 1 | I34: 1 | J34: 1 | R34: CS2
A35: Long Hậu Tân Kim | C35: 11 | F35: 2 | G35: 1 | R35: CS2
A36: Phú Xuân | C36: 11 | F36: 2 | G36: 1 | R36: CS2
A37: Hiệp Phước | C37: 11 | F37: 2 | G37: 1 | R37: CS2
A38: Cầu số 1 | B38: 12/05/2026 | C38: 12 | F38: 2 | G38: 1 | N38: 1 | O38: 1 | R38: CS2
A39: Lê Văn Sỹ | C39: 12 | F39: 2 | G39: 1 | R39: CS2
A40: Hải Đức | C40: 12 | F40: 2 | G40: 1 | J40: 1 | K40: 1 | R40: CS2
...

Sheet CS2_OLD
A1: Nơi thực hiện | B1: Vị trí quan trắc | C1: Số lượng mẫu | D1: Số lượng mẫu QC lặp | E1: Số lượng mẫu QC trắng | F1: Số lượng mẫu QC | G1: Ngày
A2: TBNM15 | B2: Triều Lên | C2: 1 | D2: {=IF(AND(INDEX('Thang 05-2026'!$A$3:$Q$102,MATCH(1,($A2='Thang 05-2026'!$A$3:$A$102)*($G2='Thang 05-2026'!$C$3:$C$102),0),11)=1,$B2="Triều Xuống"),1,IF(AND(INDEX('Thang 05-2026'!$A$3:$Q$102,MATCH(1,($A2='Thang 05-2026'!$A$3:$A$102)*($G2='Thang 05-2026'!$C$3:$C$102),0),10)=1,$B2="Triều Lên",INDEX('Thang 05-2026'!$A$3:$Q$102,MATCH(1,($A2='Thang 05-2026'!$A$3:$A$102)*($G2='Thang 05-2026'!$C$3:$C$102),0),11)=0),1,0))} -> 0 | E2: {=IF(AND(INDEX('Thang 05-2026'!$A$3:$Q$102,MATCH(1,($A2='Thang 05-2026'!$A$3:$A$102)*($G2='Thang 05-2026'!$C$3:$C$102),0),15)=1,$B2="Triều Xuống"),1,IF(AND(INDEX('Thang 05-2026'!$A$3:$Q$102,MATCH(1,($A2='Thang 05-2026'!$A$3:$A$102)*($G2='Thang 05-2026'!$C$3:$C$102),0),14)=1,$B2="Triều Lên",INDEX('Thang 05-2026'!$A$3:$Q$102,MATCH(1,($A2='Thang 05-2026'!$A$3:$A$102)*($G2='Thang 05-2026'!$C$3:$C$102),0),15)=0),1,0))} -> 0 | F2: =D2+E2 -> 0 | G2: =INDEX('Thang 05-2026'!$A$3:$C$102,MATCH(A2,'Thang 05-2026'!$A$3:$A$102,0),3) -> 4
A3: TBNM5 | B3: Triều Lên | C3: 1 | D3: {=IF(AND(INDEX('Thang 05-2026'!$A$3:$Q$102,MATCH(1,($A3='Thang 05-2026'!$A$3:$A$102)*($G3='Thang 05-2026'!$C$3:$C$102),0),11)=1,$B3="Triều Xuống"),1,IF(AND(INDEX('Thang 05-2026'!$A$3:$Q$102,MATCH(1,($A3='Thang 05-2026'!$A$3:$A$102)*($G3='Thang 05-2026'!$C$3:$C$102),0),10)=1,$B3="Triều Lên",INDEX('Thang 05-2026'!$A$3:$Q$102,MATCH(1,($A3='Thang 05-2026'!$A$3:$A$102)*($G3='Thang 05-2026'!$C$3:$C$102),0),11)=0),1,0))} -> 0 | E3: {=IF(AND(INDEX('Thang 05-2026'!$A$3:$Q$102,MATCH(1,($A3='Thang 05-2026'!$A$3:$A$102)*($G3='Thang 05-2026'!$C$3:$C$102),0),15)=1,$B3="Triều Xuống"),1,IF(AND(INDEX('Thang 05-2026'!$A$3:$Q$102,MATCH(1,($A3='Thang 05-2026'!$A$3:$A$102)*($G3='Thang 05-2026'!$C$3:$C$102),0),14)=1,$B3="Triều Lên",INDEX('Thang 05-2026'!$A$3:$Q$102,MATCH(1,($A3='Thang 05-2026'!$A$3:$A$102)*($G3='Thang 05-2026'!$C$3:$C$102),0),15)=0),1,0))} -> 0 | F3: =D3+E3 -> 0 | G3: =INDEX('Thang 05-2026'!$A$3:$C$102,MATCH(A3,'Thang 05-2026'!$A$3:$A$102,0),3) -> 4
A4: Cầu Tân Thái | B4: Triều Lên | C4: 1 | D4: {=IF(AND(INDEX('Thang 05-2026'!$A$3:$Q$102,MATCH(1,($A4='Thang 05-2026'!$A$3:$A$102)*($G4='Thang 05-2026'!$C$3:$C$102),0),11)=1,$B4="Triều Xuống"),1,IF(AND(INDEX('Thang 05-2026'!$A$3:$Q$102,MATCH(1,($A4='Thang 05-2026'!$A$3:$A$102)*($G4='Thang 05-2026'!$C$3:$C$102),0),10)=1,$B4="Triều Lên",INDEX('Thang 05-2026'!$A$3:$Q$102,MATCH(1,($A4='Thang 05-2026'!$A$3:$A$102)*($G4='Thang 05-2026'!$C$3:$C$102),0),11)=0),1,0))} -> 0 | E4: {=IF(AND(INDEX('Thang 05-2026'!$A$3:$Q$102,MATCH(1,($A4='Thang 05-2026'!$A$3:$A$102)*($G4='Thang 05-2026'!$C$3:$C$102),0),15)=1,$B4="Triều Xuống"),1,IF(AND(INDEX('Thang 05-2026'!$A$3:$Q$102,MATCH(1,($A4='Thang 05-2026'!$A$3:$A$102)*($G4='Thang 05-2026'!$C$3:$C$102),0),14)=1,$B4="Triều Lên",INDEX('Thang 05-2026'!$A$3:$Q$102,MATCH(1,($A4='Thang 05-2026'!$A$3:$A$102)*($G4='Thang 05-2026'!$C$3:$C$102),0),15)=0),1,0))} -> 0 | F4: =D4+E4 -> 0 | G4: =INDEX('Thang 05-2026'!$A$3:$C$102,MATCH(A4,'Thang 05-2026'!$A$3:$A$102,0),3) -> 4
A5: TBNM14 | B5: Triều Lên | C5: 1 | D5: {=IF(AND(INDEX('Thang 05-2026'!$A$3:$Q$102,MATCH(1,($A5='Thang 05-2026'!$A$3:$A$102)*($G5='Thang 05-2026'!$C$3:$C$102),0),11)=1,$B5="Triều Xuống"),1,IF(AND(INDEX('Thang 05-2026'!$A$3:$Q$102,MATCH(1,($A5='Thang 05-2026'!$A$3:$A$102)*($G5='Thang 05-2026'!$C$3:$C$102),0),10)=1,$B5="Triều Lên",INDEX('Thang 05-2026'!$A$3:$Q$102,MATCH(1,($A5='Thang 05-2026'!$A$3:$A$102)*($G5='Thang 05-2026'!$C$3:$C$102),0),11)=0),1,0))} -> 0 | E5: {=IF(AND(INDEX('Thang 05-2026'!$A$3:$Q$102,MATCH(1,($A5='Thang 05-2026'!$A$3:$A$102)*($G5='Thang 05-2026'!$C$3:$C$102),0),15)=1,$B5="Triều Xuống"),1,IF(AND(INDEX('Thang 05-2026'!$A$3:$Q$102,MATCH(1,($A5='Thang 05-2026'!$A$3:$A$102)*($G5='Thang 05-2026'!$C$3:$C$102),0),14)=1,$B5="Triều Lên",INDEX('Thang 05-2026'!$A$3:$Q$102,MATCH(1,($A5='Thang 05-2026'!$A$3:$A$102)*($G5='Thang 05-2026'!$C$3:$C$102),0),15)=0),1,0))} -> 0 | F5: =D5+E5 -> 0 | G5: =INDEX('Thang 05-2026'!$A$3:$C$102,MATCH(A5,'Thang 05-2026'!$A$3:$A$102,0),3) -> 4
A6: TBNM15 | B6: Triều Xuống | C6: 1 | D6: {=IF(AND(INDEX('Thang 05-2026'!$A$3:$Q$102,MATCH(1,($A6='Thang 05-2026'!$A$3:$A$102)*($G6='Thang 05-2026'!$C$3:$C$102),0),11)=1,$B6="Triều Xuống"),1,IF(AND(INDEX('Thang 05-2026'!$A$3:$Q$102,MATCH(1,($A6='Thang 05-2026'!$A$3:$A$102)*($G6='Thang 05-2026'!$C$3:$C$102),0),10)=1,$B6="Triều Lên",INDEX('Thang 05-2026'!$A$3:$Q$102,MATCH(1,($A6='Thang 05-2026'!$A$3:$A$102)*($G6='Thang 05-2026'!$C$3:$C$102),0),11)=0),1,0))} -> 0 | E6: {=IF(AND(INDEX('Thang 05-2026'!$A$3:$Q$102,MATCH(1,($A6='Thang 05-2026'!$A$3:$A$102)*($G6='Thang 05-2026'!$C$3:$C$102),0),15)=1,$B6="Triều Xuống"),1,IF(AND(INDEX('Thang 05-2026'!$A$3:$Q$102,MATCH(1,($A6='Thang 05-2026'!$A$3:$A$102)*($G6='Thang 05-2026'!$C$3:$C$102),0),14)=1,$B6="Triều Lên",INDEX('Thang 05-2026'!$A$3:$Q$102,MATCH(1,($A6='Thang 05-2026'!$A$3:$A$102)*($G6='Thang 05-2026'!$C$3:$C$102),0),15)=0),1,0))} -> 0 | F6: =D6+E6 -> 0 | G6: =INDEX('Thang 05-2026'!$A$3:$C$102,MATCH(A6,'Thang 05-2026'!$A$3:$A$102,0),3) -> 4
A7: TBNM5 | B7: Triều Xuống | C7: 1 | D7: {=IF(AND(INDEX('Thang 05-2026'!$A$3:$Q$102,MATCH(1,($A7='Thang 05-2026'!$A$3:$A$102)*($G7='Thang 05-2026'!$C$3:$C$102),0),11)=1,$B7="Triều Xuống"),1,IF(AND(INDEX('Thang 05-2026'!$A$3:$Q$102,MATCH(1,($A7='Thang 05-2026'!$A$3:$A$102)*($G7='Thang 05-2026'!$C$3:$C$102),0),10)=1,$B7="Triều Lên",INDEX('Thang 05-2026'!$A$3:$Q$102,MATCH(1,($A7='Thang 05-2026'!$A$3:$A$102)*($G7='Thang 05-2026'!$C$3:$C$102),0),11)=0),1,0))} -> 0 | E7: {=IF(AND(INDEX('Thang 05-2026'!$A$3:$Q$102,MATCH(1,($A7='Thang 05-2026'!$A$3:$A$102)*($G7='Thang 05-2026'!$C$3:$C$102),0),15)=1,$B7="Triều Xuống"),1,IF(AND(INDEX('Thang 05-2026'!$A$3:$Q$102,MATCH(1,($A7='Thang 05-2026'!$A$3:$A$102)*($G7='Thang 05-2026'!$C$3:$C$102),0),14)=1,$B7="Triều Lên",INDEX('Thang 05-2026'!$A$3:$Q$102,MATCH(1,($A7='Thang 05-2026'!$A$3:$A$102)*($G7='Thang 05-2026'!$C$3:$C$102),0),15)=0),1,0))} -> 0 | F7: =D7+E7 -> 0 | G7: =INDEX('Thang 05-2026'!$A$3:$C$102,MATCH(A7,'Thang 05-2026'!$A$3:$A$102,0),3) -> 4
A8: Cầu Tân Thái | B8: Triều Xuống | C8: 1 | D8: {=IF(AND(INDEX('Thang 05-2026'!$A$3:$Q$102,MATCH(1,($A8='Thang 05-2026'!$A$3:$A$102)*($G8='Thang 05-2026'!$C$3:$C$102),0),11)=1,$B8="Triều Xuống"),1,IF(AND(INDEX('Thang 05-2026'!$A$3:$Q$102,MATCH(1,($A8='Thang 05-2026'!$A$3:$A$102)*($G8='Thang 05-2026'!$C$3:$C$102),0),10)=1,$B8="Triều Lên",INDEX('Thang 05-2026'!$A$3:$Q$102,MATCH(1,($A8='Thang 05-2026'!$A$3:$A$102)*($G8='Thang 05-2026'!$C$3:$C$102),0),11)=0),1,0))} -> 0 | E8: {=IF(AND(INDEX('Thang 05-2026'!$A$3:$Q$102,MATCH(1,($A8='Thang 05-2026'!$A$3:$A$102)*($G8='Thang 05-2026'!$C$3:$C$102),0),15)=1,$B8="Triều Xuống"),1,IF(AND(INDEX('Thang 05-2026'!$A$3:$Q$102,MATCH(1,($A8='Thang 05-2026'!$A$3:$A$102)*($G8='Thang 05-2026'!$C$3:$C$102),0),14)=1,$B8="Triều Lên",INDEX('Thang 05-2026'!$A$3:$Q$102,MATCH(1,($A8='Thang 05-2026'!$A$3:$A$102)*($G8='Thang 05-2026'!$C$3:$C$102),0),15)=0),1,0))} -> 1 | F8: =D8+E8 -> 1 | G8: =INDEX('Thang 05-2026'!$A$3:$C$102,MATCH(A8,'Thang 05-2026'!$A$3:$A$102,0),3) -> 4
A9: TBNM14 | B9: Triều Xuống | C9: 1 | D9: {=IF(AND(INDEX('Thang 05-2026'!$A$3:$Q$102,MATCH(1,($A9='Thang 05-2026'!$A$3:$A$102)*($G9='Thang 05-2026'!$C$3:$C$102),0),11)=1,$B9="Triều Xuống"),1,IF(AND(INDEX('Thang 05-2026'!$A$3:$Q$102,MATCH(1,($A9='Thang 05-2026'!$A$3:$A$102)*($G9='Thang 05-2026'!$C$3:$C$102),0),10)=1,$B9="Triều Lên",INDEX('Thang 05-2026'!$A$3:$Q$102,MATCH(1,($A9='Thang 05-2026'!$A$3:$A$102)*($G9='Thang 05-2026'!$C$3:$C$102),0),11)=0),1,0))} -> 0 | E9: {=IF(AND(INDEX('Thang 05-2026'!$A$3:$Q$102,MATCH(1,($A9='Thang 05-2026'!$A$3:$A$102)*($G9='Thang 05-2026'!$C$3:$C$102),0),15)=1,$B9="Triều Xuống"),1,IF(AND(INDEX('Thang 05-2026'!$A$3:$Q$102,MATCH(1,($A9='Thang 05-2026'!$A$3:$A$102)*($G9='Thang 05-2026'!$C$3:$C$102),0),14)=1,$B9="Triều Lên",INDEX('Thang 05-2026'!$A$3:$Q$102,MATCH(1,($A9='Thang 05-2026'!$A$3:$A$102)*($G9='Thang 05-2026'!$C$3:$C$102),0),15)=0),1,0))} -> 0 | F9: =D9+E9 -> 0 | G9: =INDEX('Thang 05-2026'!$A$3:$C$102,MATCH(A9,'Thang 05-2026'!$A$3:$A$102,0),3) -> 4
A10: TBNM9 | B10: Triều Lên | C10: 1 | D10: {=IF(AND(INDEX('Thang 05-2026'!$A$3:$Q$102,MATCH(1,($A10='Thang 05-2026'!$A$3:$A$102)*($G10='Thang 05-2026'!$C$3:$C$102),0),11)=1,$B10="Triều Xuống"),1,IF(AND(INDEX('Thang 05-2026'!$A$3:$Q$102,MATCH(1,($A10='Thang 05-2026'!$A$3:$A$102)*($G10='Thang 05-2026'!$C$3:$C$102),0),10)=1,$B10="Triều Lên",INDEX('Thang 05-2026'!$A$3:$Q$102,MATCH(1,($A10='Thang 05-2026'!$A$3:$A$102)*($G10='Thang 05-2026'!$C$3:$C$102),0),11)=0),1,0))} -> 1 | E10: {=IF(AND(INDEX('Thang 05-2026'!$A$3:$Q$102,MATCH(1,($A10='Thang 05-2026'!$A$3:$A$102)*($G10='Thang 05-2026'!$C$3:$C$102),0),15)=1,$B10="Triều Xuống"),1,IF(AND(INDEX('Thang 05-2026'!$A$3:$Q$102,MATCH(1,($A10='Thang 05-2026'!$A$3:$A$102)*($G10='Thang 05-2026'!$C$3:$C$102),0),14)=1,$B10="Triều Lên",INDEX('Thang 05-2026'!$A$3:$Q$102,MATCH(1,($A10='Thang 05-2026'!$A$3:$A$102)*($G10='Thang 05-2026'!$C$3:$C$102),0),15)=0),1,0))} -> 0 | F10: =D10+E10 -> 1 | G10: =INDEX('Thang 05-2026'!$A$3:$C$102,MATCH(A10,'Thang 05-2026'!$A$3:$A$102,0),3) -> 4
A11: TBNM11 | B11: Triều Lên | C11: 1 | D11: {=IF(AND(INDEX('Thang 05-2026'!$A$3:$Q$102,MATCH(1,($A11='Thang 05-2026'!$A$3:$A$102)*($G11='Thang 05-2026'!$C$3:$C$102),0),11)=1,$B11="Triều Xuống"),1,IF(AND(INDEX('Thang 05-2026'!$A$3:$Q$102,MATCH(1,($A11='Thang 05-2026'!$A$3:$A$102)*($G11='Thang 05-2026'!$C$3:$C$102),0),10)=1,$B11="Triều Lên",INDEX('Thang 05-2026'!$A$3:$Q$102,MATCH(1,($A11='Thang 05-2026'!$A$3:$A$102)*($G11='Thang 05-2026'!$C$3:$C$102),0),11)=0),1,0))} -> 0 | E11: {=IF(AND(INDEX('Thang 05-2026'!$A$3:$Q$102,MATCH(1,($A11='Thang 05-2026'!$A$3:$A$102)*($G11='Thang 05-2026'!$C$3:$C$102),0),15)=1,$B11="Triều Xuống"),1,IF(AND(INDEX('Thang 05-2026'!$A$3:$Q$102,MATCH(1,($A11='Thang 05-2026'!$A$3:$A$102)*($G11='Thang 05-2026'!$C$3:$C$102),0),14)=1,$B11="Triều Lên",INDEX('Thang 05-2026'!$A$3:$Q$102,MATCH(1,($A11='Thang 05-2026'!$A$3:$A$102)*($G11='Thang 05-2026'!$C$3:$C$102),0),15)=0),1,0))} -> 0 | F11: =D11+E11 -> 0 | G11: =INDEX('Thang 05-2026'!$A$3:$C$102,MATCH(A11,'Thang 05-2026'!$A$3:$A$102,0),3) -> 4
A12: TBNM1 | B12: Triều Lên | C12: 1 | D12: {=IF(AND(INDEX('Thang 05-2026'!$A$3:$Q$102,MATCH(1,($A12='Thang 05-2026'!$A$3:$A$102)*($G12='Thang 05-2026'!$C$3:$C$102),0),11)=1,$B12="Triều Xuống"),1,IF(AND(INDEX('Thang 05-2026'!$A$3:$Q$102,MATCH(1,($A12='Thang 05-2026'!$A$3:$A$102)*($G12='Thang 05-2026'!$C$3:$C$102),0),10)=1,$B12="Triều Lên",INDEX('Thang 05-2026'!$A$3:$Q$102,MATCH(1,($A12='Thang 05-2026'!$A$3:$A$102)*($G12='Thang 05-2026'!$C$3:$C$102),0),11)=0),1,0))} -> 0 | E12: {=IF(AND(INDEX('Thang 05-2026'!$A$3:$Q$102,MATCH(1,($A12='Thang 05-2026'!$A$3:$A$102)*($G12='Thang 05-2026'!$C$3:$C$102),0),15)=1,$B12="Triều Xuống"),1,IF(AND(INDEX('Thang 05-2026'!$A$3:$Q$102,MATCH(1,($A12='Thang 05-2026'!$A$3:$A$102)*($G12='Thang 05-2026'!$C$3:$C$102),0),14)=1,$B12="Triều Lên",INDEX('Thang 05-2026'!$A$3:$Q$102,MATCH(1,($A12='Thang 05-2026'!$A$3:$A$102)*($G12='Thang 05-2026'!$C$3:$C$102),0),15)=0),1,0))} -> 0 | F12: =D12+E12 -> 0 | G12: =INDEX('Thang 05-2026'!$A$3:$C$102,MATCH(A12,'Thang 05-2026'!$A$3:$A$102,0),3) -> 4
A13: Thầy Cai | B13: Triều Lên | C13: 1 | D13: {=IF(AND(INDEX('Thang 05-2026'!$A$3:$Q$102,MATCH(1,($A13='Thang 05-2026'!$A$3:$A$102)*($G13='Thang 05-2026'!$C$3:$C$102),0),11)=1,$B13="Triều Xuống"),1,IF(AND(INDEX('Thang 05-2026'!$A$3:$Q$102,MATCH(1,($A13='Thang 05-2026'!$A$3:$A$102)*($G13='Thang 05-2026'!$C$3:$C$102),0),10)=1,$B13="Triều Lên",INDEX('Thang 05-2026'!$A$3:$Q$102,MATCH(1,($A13='Thang 05-2026'!$A$3:$A$102)*($G13='Thang 05-2026'!$C$3:$C$102),0),11)=0),1,0))} -> 0 | E13: {=IF(AND(INDEX('Thang 05-2026'!$A$3:$Q$102,MATCH(1,($A13='Thang 05-2026'!$A$3:$A$102)*($G13='Thang 05-2026'!$C$3:$C$102),0),15)=1,$B13="Triều Xuống"),1,IF(AND(INDEX('Thang 05-2026'!$A$3:$Q$102,MATCH(1,($A13='Thang 05-2026'!$A$3:$A$102)*($G13='Thang 05-2026'!$C$3:$C$102),0),14)=1,$B13="Triều Lên",INDEX('Thang 05-2026'!$A$3:$Q$102,MATCH(1,($A13='Thang 05-2026'!$A$3:$A$102)*($G13='Thang 05-2026'!$C$3:$C$102),0),15)=0),1,0))} -> 0 | F13: =D13+E13 -> 0 | G13: =INDEX('Thang 05-2026'!$A$3:$C$102,MATCH(A13,'Thang 05-2026'!$A$3:$A$102,0),3) -> 4
... A145: Cần Giuộc | B145: Triều Xuống | C145: 1 | D145: {=IF(AND(INDEX('Thang 05-2026'!$A$3:$Q$102,MATCH(1,($A145='Thang 05-2026'!$A$3:$A$102)*($G145='Thang 05-2026'!$C$3:$C$102),0),11)=1,$B145="Triều Xuống"),1,IF(AND(INDEX('Thang 05-2026'!$A$3:$Q$102,MATCH(1,($A145='Thang 05-2026'!$A$3:$A$102)*($G145='Thang 05-2026'!$C$3:$C$102),0),10)=1,$B145="Triều Lên",INDEX('Thang 05-2026'!$A$3:$Q$102,MATCH(1,($A145='Thang 05-2026'!$A$3:$A$102)*($G145='Thang 05-2026'!$C$3:$C$102),0),11)=0),1,0))} -> 0 | E145: {=IF(AND(INDEX('Thang 05-2026'!$A$3:$Q$102,MATCH(1,($A145='Thang 05-2026'!$A$3:$A$102)*($G145='Thang 05-2026'!$C$3:$C$102),0),15)=1,$B145="Triều Xuống"),1,IF(AND(INDEX('Thang 05-2026'!$A$3:$Q$102,MATCH(1,($A145='Thang 05-2026'!$A$3:$A$102)*($G145='Thang 05-2026'!$C$3:$C$102),0),14)=1,$B145="Triều Lên",INDEX('Thang 05-2026'!$A$3:$Q$102,MATCH(1,($A145='Thang 05-2026'!$A$3:$A$102)*($G145='Thang 05-2026'!$C$3:$C$102),0),15)=0),1,0))} -> 0 | F145: =D145+E145 -> 0 | G145: =INDEX('Thang 05-2026'!$A$3:$C$102,MATCH(A145,'Thang 05-2026'!$A$3:$A$102,0),3) -> 21
A146: ĐPNM1 | B146: Triều Lên | C146: 1 | D146: {=IF(AND(INDEX('Thang 05-2026'!$A$3:$Q$102,MATCH(1,($A146='Thang 05-2026'!$A$3:$A$102)*($G146='Thang 05-2026'!$C$3:$C$102),0),11)=1,$B146="Triều Xuống"),1,IF(AND(INDEX('Thang 05-2026'!$A$3:$Q$102,MATCH(1,($A146='Thang 05-2026'!$A$3:$A$102)*($G146='Thang 05-2026'!$C$3:$C$102),0),10)=1,$B146="Triều Lên",INDEX('Thang 05-2026'!$A$3:$Q$102,MATCH(1,($A146='Thang 05-2026'!$A$3:$A$102)*($G146='Thang 05-2026'!$C$3:$C$102),0),11)=0),1,0))} -> 0 | E146: {=IF(AND(INDEX('Thang 05-2026'!$A$3:$Q$102,MATCH(1,($A146='Thang 05-2026'!$A$3:$A$102)*($G146='Thang 05-2026'!$C$3:$C$102),0),15)=1,$B146="Triều Xuống"),1,IF(AND(INDEX('Thang 05-2026'!$A$3:$Q$102,MATCH(1,($A146='Thang 05-2026'!$A$3:$A$102)*($G146='Thang 05-2026'!$C$3:$C$102),0),14)=1,$B146="Triều Lên",INDEX('Thang 05-2026'!$A$3:$Q$102,MATCH(1,($A146='Thang 05-2026'!$A$3:$A$102)*($G146='Thang 05-2026'!$C$3:$C$102),0),15)=0),1,0))} -> 0 | F146: =D146+E146 -> 0 | G146: 22
A147: ĐPNM4 | B147: Triều Lên | C147: 1 | D147: {=IF(AND(INDEX('Thang 05-2026'!$A$3:$Q$102,MATCH(1,($A147='Thang 05-2026'!$A$3:$A$102)*($G147='Thang 05-2026'!$C$3:$C$102),0),11)=1,$B147="Triều Xuống"),1,IF(AND(INDEX('Thang 05-2026'!$A$3:$Q$102,MATCH(1,($A147='Thang 05-2026'!$A$3:$A$102)*($G147='Thang 05-2026'!$C$3:$C$102),0),10)=1,$B147="Triều Lên",INDEX('Thang 05-2026'!$A$3:$Q$102,MATCH(1,($A147='Thang 05-2026'!$A$3:$A$102)*($G147='Thang 05-2026'!$C$3:$C$102),0),11)=0),1,0))} -> 0 | E147: {=IF(AND(INDEX('Thang 05-2026'!$A$3:$Q$102,MATCH(1,($A147='Thang 05-2026'!$A$3:$A$102)*($G147='Thang 05-2026'!$C$3:$C$102),0),15)=1,$B147="Triều Xuống"),1,IF(AND(INDEX('Thang 05-2026'!$A$3:$Q$102,MATCH(1,($A147='Thang 05-2026'!$A$3:$A$102)*($G147='Thang 05-2026'!$C$3:$C$102),0),14)=1,$B147="Triều Lên",INDEX('Thang 05-2026'!$A$3:$Q$102,MATCH(1,($A147='Thang 05-2026'!$A$3:$A$102)*($G147='Thang 05-2026'!$C$3:$C$102),0),15)=0),1,0))} -> 0 | F147: =D147+E147 -> 0 | G147: 22
A148: ĐPNM5 | B148: Triều Lên | C148: 1 | D148: {=IF(AND(INDEX('Thang 05-2026'!$A$3:$Q$102,MATCH(1,($A148='Thang 05-2026'!$A$3:$A$102)*($G148='Thang 05-2026'!$C$3:$C$102),0),11)=1,$B148="Triều Xuống"),1,IF(AND(INDEX('Thang 05-2026'!$A$3:$Q$102,MATCH(1,($A148='Thang 05-2026'!$A$3:$A$102)*($G148='Thang 05-2026'!$C$3:$C$102),0),10)=1,$B148="Triều Lên",INDEX('Thang 05-2026'!$A$3:$Q$102,MATCH(1,($A148='Thang 05-2026'!$A$3:$A$102)*($G148='Thang 05-2026'!$C$3:$C$102),0),11)=0),1,0))} -> 0 | E148: {=IF(AND(INDEX('Thang 05-2026'!$A$3:$Q$102,MATCH(1,($A148='Thang 05-2026'!$A$3:$A$102)*($G148='Thang 05-2026'!$C$3:$C$102),0),15)=1,$B148="Triều Xuống"),1,IF(AND(INDEX('Thang 05-2026'!$A$3:$Q$102,MATCH(1,($A148='Thang 05-2026'!$A$3:$A$102)*($G148='Thang 05-2026'!$C$3:$C$102),0),14)=1,$B148="Triều Lên",INDEX('Thang 05-2026'!$A$3:$Q$102,MATCH(1,($A148='Thang 05-2026'!$A$3:$A$102)*($G148='Thang 05-2026'!$C$3:$C$102),0),15)=0),1,0))} -> 0 | F148: =D148+E148 -> 0 | G148: 22
A149: ĐPNM8 | B149: Triều Lên | C149: 1 | D149: {=IF(AND(INDEX('Thang 05-2026'!$A$3:$Q$102,MATCH(1,($A149='Thang 05-2026'!$A$3:$A$102)*($G149='Thang 05-2026'!$C$3:$C$102),0),11)=1,$B149="Triều Xuống"),1,IF(AND(INDEX('Thang 05-2026'!$A$3:$Q$102,MATCH(1,($A149='Thang 05-2026'!$A$3:$A$102)*($G149='Thang 05-2026'!$C$3:$C$102),0),10)=1,$B149="Triều Lên",INDEX('Thang 05-2026'!$A$3:$Q$102,MATCH(1,($A149='Thang 05-2026'!$A$3:$A$102)*($G149='Thang 05-2026'!$C$3:$C$102),0),11)=0),1,0))} -> 0 | E149: {=IF(AND(INDEX('Thang 05-2026'!$A$3:$Q$102,MATCH(1,($A149='Thang 05-2026'!$A$3:$A$102)*($G149='Thang 05-2026'!$C$3:$C$102),0),15)=1,$B149="Triều Xuống"),1,IF(AND(INDEX('Thang 05-2026'!$A$3:$Q$102,MATCH(1,($A149='Thang 05-2026'!$A$3:$A$102)*($G149='Thang 05-2026'!$C$3:$C$102),0),14)=1,$B149="Triều Lên",INDEX('Thang 05-2026'!$A$3:$Q$102,MATCH(1,($A149='Thang 05-2026'!$A$3:$A$102)*($G149='Thang 05-2026'!$C$3:$C$102),0),15)=0),1,0))} -> 0 | F149: =D149+E149 -> 0 | G149: 22
A150: ĐPNM1 | B150: Triều Xuống | C150: 1 | D150: {=IF(AND(INDEX('Thang 05-2026'!$A$3:$Q$102,MATCH(1,($A150='Thang 05-2026'!$A$3:$A$102)*($G150='Thang 05-2026'!$C$3:$C$102),0),11)=1,$B150="Triều Xuống"),1,IF(AND(INDEX('Thang 05-2026'!$A$3:$Q$102,MATCH(1,($A150='Thang 05-2026'!$A$3:$A$102)*($G150='Thang 05-2026'!$C$3:$C$102),0),10)=1,$B150="Triều Lên",INDEX('Thang 05-2026'!$A$3:$Q$102,MATCH(1,($A150='Thang 05-2026'!$A$3:$A$102)*($G150='Thang 05-2026'!$C$3:$C$102),0),11)=0),1,0))} -> 0 | E150: {=IF(AND(INDEX('Thang 05-2026'!$A$3:$Q$102,MATCH(1,($A150='Thang 05-2026'!$A$3:$A$102)*($G150='Thang 05-2026'!$C$3:$C$102),0),15)=1,$B150="Triều Xuống"),1,IF(AND(INDEX('Thang 05-2026'!$A$3:$Q$102,MATCH(1,($A150='Thang 05-2026'!$A$3:$A$102)*($G150='Thang 05-2026'!$C$3:$C$102),0),14)=1,$B150="Triều Lên",INDEX('Thang 05-2026'!$A$3:$Q$102,MATCH(1,($A150='Thang 05-2026'!$A$3:$A$102)*($G150='Thang 05-2026'!$C$3:$C$102),0),15)=0),1,0))} -> 0 | F150: =D150+E150 -> 0 | G150: 22
A151: ĐPNM4 | B151: Triều Xuống | C151: 1 | D151: {=IF(AND(INDEX('Thang 05-2026'!$A$3:$Q$102,MATCH(1,($A151='Thang 05-2026'!$A$3:$A$102)*($G151='Thang 05-2026'!$C$3:$C$102),0),11)=1,$B151="Triều Xuống"),1,IF(AND(INDEX('Thang 05-2026'!$A$3:$Q$102,MATCH(1,($A151='Thang 05-2026'!$A$3:$A$102)*($G151='Thang 05-2026'!$C$3:$C$102),0),10)=1,$B151="Triều Lên",INDEX('Thang 05-2026'!$A$3:$Q$102,MATCH(1,($A151='Thang 05-2026'!$A$3:$A$102)*($G151='Thang 05-2026'!$C$3:$C$102),0),11)=0),1,0))} -> 0 | E151: {=IF(AND(INDEX('Thang 05-2026'!$A$3:$Q$102,MATCH(1,($A151='Thang 05-2026'!$A$3:$A$102)*($G151='Thang 05-2026'!$C$3:$C$102),0),15)=1,$B151="Triều Xuống"),1,IF(AND(INDEX('Thang 05-2026'!$A$3:$Q$102,MATCH(1,($A151='Thang 05-2026'!$A$3:$A$102)*($G151='Thang 05-2026'!$C$3:$C$102),0),14)=1,$B151="Triều Lên",INDEX('Thang 05-2026'!$A$3:$Q$102,MATCH(1,($A151='Thang 05-2026'!$A$3:$A$102)*($G151='Thang 05-2026'!$C$3:$C$102),0),15)=0),1,0))} -> 0 | F151: =D151+E151 -> 0 | G151: 22
A152: ĐPNM5 | B152: Triều Xuống | C152: 1 | D152: {=IF(AND(INDEX('Thang 05-2026'!$A$3:$Q$102,MATCH(1,($A152='Thang 05-2026'!$A$3:$A$102)*($G152='Thang 05-2026'!$C$3:$C$102),0),11)=1,$B152="Triều Xuống"),1,IF(AND(INDEX('Thang 05-2026'!$A$3:$Q$102,MATCH(1,($A152='Thang 05-2026'!$A$3:$A$102)*($G152='Thang 05-2026'!$C$3:$C$102),0),10)=1,$B152="Triều Lên",INDEX('Thang 05-2026'!$A$3:$Q$102,MATCH(1,($A152='Thang 05-2026'!$A$3:$A$102)*($G152='Thang 05-2026'!$C$3:$C$102),0),11)=0),1,0))} -> 0 | E152: {=IF(AND(INDEX('Thang 05-2026'!$A$3:$Q$102,MATCH(1,($A152='Thang 05-2026'!$A$3:$A$102)*($G152='Thang 05-2026'!$C$3:$C$102),0),15)=1,$B152="Triều Xuống"),1,IF(AND(INDEX('Thang 05-2026'!$A$3:$Q$102,MATCH(1,($A152='Thang 05-2026'!$A$3:$A$102)*($G152='Thang 05-2026'!$C$3:$C$102),0),14)=1,$B152="Triều Lên",INDEX('Thang 05-2026'!$A$3:$Q$102,MATCH(1,($A152='Thang 05-2026'!$A$3:$A$102)*($G152='Thang 05-2026'!$C$3:$C$102),0),15)=0),1,0))} -> 0 | F152: =D152+E152 -> 0 | G152: 22
A153: ĐPNM8 | B153: Triều Xuống | C153: 1 | D153: {=IF(AND(INDEX('Thang 05-2026'!$A$3:$Q$102,MATCH(1,($A153='Thang 05-2026'!$A$3:$A$102)*($G153='Thang 05-2026'!$C$3:$C$102),0),11)=1,$B153="Triều Xuống"),1,IF(AND(INDEX('Thang 05-2026'!$A$3:$Q$102,MATCH(1,($A153='Thang 05-2026'!$A$3:$A$102)*($G153='Thang 05-2026'!$C$3:$C$102),0),10)=1,$B153="Triều Lên",INDEX('Thang 05-2026'!$A$3:$Q$102,MATCH(1,($A153='Thang 05-2026'!$A$3:$A$102)*($G153='Thang 05-2026'!$C$3:$C$102),0),11)=0),1,0))} -> 0 | E153: {=IF(AND(INDEX('Thang 05-2026'!$A$3:$Q$102,MATCH(1,($A153='Thang 05-2026'!$A$3:$A$102)*($G153='Thang 05-2026'!$C$3:$C$102),0),15)=1,$B153="Triều Xuống"),1,IF(AND(INDEX('Thang 05-2026'!$A$3:$Q$102,MATCH(1,($A153='Thang 05-2026'!$A$3:$A$102)*($G153='Thang 05-2026'!$C$3:$C$102),0),14)=1,$B153="Triều Lên",INDEX('Thang 05-2026'!$A$3:$Q$102,MATCH(1,($A153='Thang 05-2026'!$A$3:$A$102)*($G153='Thang 05-2026'!$C$3:$C$102),0),15)=0),1,0))} -> 0 | F153: =D153+E153 -> 0 | G153: 22
A154: Cầu Gò Công | B154: Triều Lên | C154: 1 | D154: {=IF(AND(INDEX('Thang 05-2026'!$A$3:$Q$102,MATCH(1,($A154='Thang 05-2026'!$A$3:$A$102)*($G154='Thang 05-2026'!$C$3:$C$102),0),11)=1,$B154="Triều Xuống"),1,IF(AND(INDEX('Thang 05-2026'!$A$3:$Q$102,MATCH(1,($A154='Thang 05-2026'!$A$3:$A$102)*($G154='Thang 05-2026'!$C$3:$C$102),0),10)=1,$B154="Triều Lên",INDEX('Thang 05-2026'!$A$3:$Q$102,MATCH(1,($A154='Thang 05-2026'!$A$3:$A$102)*($G154='Thang 05-2026'!$C$3:$C$102),0),11)=0),1,0))} -> 0 | E154: {=IF(AND(INDEX('Thang 05-2026'!$A$3:$Q$102,MATCH(1,($A154='Thang 05-2026'!$A$3:$A$102)*($G154='Thang 05-2026'!$C$3:$C$102),0),15)=1,$B154="Triều Xuống"),1,IF(AND(INDEX('Thang 05-2026'!$A$3:$Q$102,MATCH(1,($A154='Thang 05-2026'!$A$3:$A$102)*($G154='Thang 05-2026'!$C$3:$C$102),0),14)=1,$B154="Triều Lên",INDEX('Thang 05-2026'!$A$3:$Q$102,MATCH(1,($A154='Thang 05-2026'!$A$3:$A$102)*($G154='Thang 05-2026'!$C$3:$C$102),0),15)=0),1,0))} -> 0 | F154: =D154+E154 -> 0 | G154: =INDEX('Thang 05-2026'!$A$3:$C$102,MATCH(A154,'Thang 05-2026'!$A$3:$A$102,0),3) -> 26
A155: Cầu Gò Công | B155: Triều Xuống | C155: 1 | D155: {=IF(AND(INDEX('Thang 05-2026'!$A$3:$Q$102,MATCH(1,($A155='Thang 05-2026'!$A$3:$A$102)*($G155='Thang 05-2026'!$C$3:$C$102),0),11)=1,$B155="Triều Xuống"),1,IF(AND(INDEX('Thang 05-2026'!$A$3:$Q$102,MATCH(1,($A155='Thang 05-2026'!$A$3:$A$102)*($G155='Thang 05-2026'!$C$3:$C$102),0),10)=1,$B155="Triều Lên",INDEX('Thang 05-2026'!$A$3:$Q$102,MATCH(1,($A155='Thang 05-2026'!$A$3:$A$102)*($G155='Thang 05-2026'!$C$3:$C$102),0),11)=0),1,0))} -> 0 | E155: {=IF(AND(INDEX('Thang 05-2026'!$A$3:$Q$102,MATCH(1,($A155='Thang 05-2026'!$A$3:$A$102)*($G155='Thang 05-2026'!$C$3:$C$102),0),15)=1,$B155="Triều Xuống"),1,IF(AND(INDEX('Thang 05-2026'!$A$3:$Q$102,MATCH(1,($A155='Thang 05-2026'!$A$3:$A$102)*($G155='Thang 05-2026'!$C$3:$C$102),0),14)=1,$B155="Triều Lên",INDEX('Thang 05-2026'!$A$3:$Q$102,MATCH(1,($A155='Thang 05-2026'!$A$3:$A$102)*($G155='Thang 05-2026'!$C$3:$C$102),0),15)=0),1,0))} -> 0 | F155: =D155+E155 -> 0 | G155: =INDEX('Thang 05-2026'!$A$3:$C$102,MATCH(A155,'Thang 05-2026'!$A$3:$A$102,0),3) -> 26
A156: Hồ Ngọc Lãm | B156: Triều Lên | C156: 1 | D156: {=IF(AND(INDEX('Thang 05-2026'!$A$3:$Q$102,MATCH(1,($A156='Thang 05-2026'!$A$3:$A$102)*($G156='Thang 05-2026'!$C$3:$C$102),0),11)=1,$B156="Triều Xuống"),1,IF(AND(INDEX('Thang 05-2026'!$A$3:$Q$102,MATCH(1,($A156='Thang 05-2026'!$A$3:$A$102)*($G156='Thang 05-2026'!$C$3:$C$102),0),10)=1,$B156="Triều Lên",INDEX('Thang 05-2026'!$A$3:$Q$102,MATCH(1,($A156='Thang 05-2026'!$A$3:$A$102)*($G156='Thang 05-2026'!$C$3:$C$102),0),11)=0),1,0))} -> 0 | E156: {=IF(AND(INDEX('Thang 05-2026'!$A$3:$Q$102,MATCH(1,($A156='Thang 05-2026'!$A$3:$A$102)*($G156='Thang 05-2026'!$C$3:$C$102),0),15)=1,$B156="Triều Xuống"),1,IF(AND(INDEX('Thang 05-2026'!$A$3:$Q$102,MATCH(1,($A156='Thang 05-2026'!$A$3:$A$102)*($G156='Thang 05-2026'!$C$3:$C$102),0),14)=1,$B156="Triều Lên",INDEX('Thang 05-2026'!$A$3:$Q$102,MATCH(1,($A156='Thang 05-2026'!$A$3:$A$102)*($G156='Thang 05-2026'!$C$3:$C$102),0),15)=0),1,0))} -> 0 | F156: =D156+E156 -> 0 | G156: =INDEX('Thang 05-2026'!$A$3:$C$102,MATCH(A156,'Thang 05-2026'!$A$3:$A$102,0),3) -> 27
A157: Bình Ðiền | B157: Triều Lên | C157: 1 | D157: {=IF(AND(INDEX('Thang 05-2026'!$A$3:$Q$102,MATCH(1,($A157='Thang 05-2026'!$A$3:$A$102)*($G157='Thang 05-2026'!$C$3:$C$102),0),11)=1,$B157="Triều Xuống"),1,IF(AND(INDEX('Thang 05-2026'!$A$3:$Q$102,MATCH(1,($A157='Thang 05-2026'!$A$3:$A$102)*($G157='Thang 05-2026'!$C$3:$C$102),0),10)=1,$B157="Triều Lên",INDEX('Thang 05-2026'!$A$3:$Q$102,MATCH(1,($A157='Thang 05-2026'!$A$3:$A$102)*($G157='Thang 05-2026'!$C$3:$C$102),0),11)=0),1,0))} -> 0 | E157: {=IF(AND(INDEX('Thang 05-2026'!$A$3:$Q$102,MATCH(1,($A157='Thang 05-2026'!$A$3:$A$102)*($G157='Thang 05-2026'!$C$3:$C$102),0),15)=1,$B157="Triều Xuống"),1,IF(AND(INDEX('Thang 05-2026'!$A$3:$Q$102,MATCH(1,($A157='Thang 05-2026'!$A$3:$A$102)*($G157='Thang 05-2026'!$C$3:$C$102),0),14)=1,$B157="Triều Lên",INDEX('Thang 05-2026'!$A$3:$Q$102,MATCH(1,($A157='Thang 05-2026'!$A$3:$A$102)*($G157='Thang 05-2026'!$C$3:$C$102),0),15)=0),1,0))} -> 0 | F157: =D157+E157 -> 0 | G157: =INDEX('Thang 05-2026'!$A$3:$C$102,MATCH(A157,'Thang 05-2026'!$A$3:$A$102,0),3) -> 27
A158: Chợ Đệm | B158: Triều Lên | C158: 1 | D158: {=IF(AND(INDEX('Thang 05-2026'!$A$3:$Q$102,MATCH(1,($A158='Thang 05-2026'!$A$3:$A$102)*($G158='Thang 05-2026'!$C$3:$C$102),0),11)=1,$B158="Triều Xuống"),1,IF(AND(INDEX('Thang 05-2026'!$A$3:$Q$102,MATCH(1,($A158='Thang 05-2026'!$A$3:$A$102)*($G158='Thang 05-2026'!$C$3:$C$102),0),10)=1,$B158="Triều Lên",INDEX('Thang 05-2026'!$A$3:$Q$102,MATCH(1,($A158='Thang 05-2026'!$A$3:$A$102)*($G158='Thang 05-2026'!$C$3:$C$102),0),11)=0),1,0))} -> 0 | E158: {=IF(AND(INDEX('Thang 05-2026'!$A$3:$Q$102,MATCH(1,($A158='Thang 05-2026'!$A$3:$A$102)*($G158='Thang 05-2026'!$C$3:$C$102),0),15)=1,$B158="Triều Xuống"),1,IF(AND(INDEX('Thang 05-2026'!$A$3:$Q$102,MATCH(1,($A158='Thang 05-2026'!$A$3:$A$102)*($G158='Thang 05-2026'!$C$3:$C$102),0),14)=1,$B158="Triều Lên",INDEX('Thang 05-2026'!$A$3:$Q$102,MATCH(1,($A158='Thang 05-2026'!$A$3:$A$102)*($G158='Thang 05-2026'!$C$3:$C$102),0),15)=0),1,0))} -> 0 | F158: =D158+E158 -> 0 | G158: =INDEX('Thang 05-2026'!$A$3:$C$102,MATCH(A158,'Thang 05-2026'!$A$3:$A$102,0),3) -> 27
A159: Hồ Ngọc Lãm | B159: Triều Xuống | C159: 1 | D159: {=IF(AND(INDEX('Thang 05-2026'!$A$3:$Q$102,MATCH(1,($A159='Thang 05-2026'!$A$3:$A$102)*($G159='Thang 05-2026'!$C$3:$C$102),0),11)=1,$B159="Triều Xuống"),1,IF(AND(INDEX('Thang 05-2026'!$A$3:$Q$102,MATCH(1,($A159='Thang 05-2026'!$A$3:$A$102)*($G159='Thang 05-2026'!$C$3:$C$102),0),10)=1,$B159="Triều Lên",INDEX('Thang 05-2026'!$A$3:$Q$102,MATCH(1,($A159='Thang 05-2026'!$A$3:$A$102)*($G159='Thang 05-2026'!$C$3:$C$102),0),11)=0),1,0))} -> 0 | E159: {=IF(AND(INDEX('Thang 05-2026'!$A$3:$Q$102,MATCH(1,($A159='Thang 05-2026'!$A$3:$A$102)*($G159='Thang 05-2026'!$C$3:$C$102),0),15)=1,$B159="Triều Xuống"),1,IF(AND(INDEX('Thang 05-2026'!$A$3:$Q$102,MATCH(1,($A159='Thang 05-2026'!$A$3:$A$102)*($G159='Thang 05-2026'!$C$3:$C$102),0),14)=1,$B159="Triều Lên",INDEX('Thang 05-2026'!$A$3:$Q$102,MATCH(1,($A159='Thang 05-2026'!$A$3:$A$102)*($G159='Thang 05-2026'!$C$3:$C$102),0),15)=0),1,0))} -> 0 | F159: =D159+E159 -> 0 | G159: =INDEX('Thang 05-2026'!$A$3:$C$102,MATCH(A159,'Thang 05-2026'!$A$3:$A$102,0),3) -> 27
A160: Bình Ðiền | B160: Triều Xuống | C160: 1 | D160: {=IF(AND(INDEX('Thang 05-2026'!$A$3:$Q$102,MATCH(1,($A160='Thang 05-2026'!$A$3:$A$102)*($G160='Thang 05-2026'!$C$3:$C$102),0),11)=1,$B160="Triều Xuống"),1,IF(AND(INDEX('Thang 05-2026'!$A$3:$Q$102,MATCH(1,($A160='Thang 05-2026'!$A$3:$A$102)*($G160='Thang 05-2026'!$C$3:$C$102),0),10)=1,$B160="Triều Lên",INDEX('Thang 05-2026'!$A$3:$Q$102,MATCH(1,($A160='Thang 05-2026'!$A$3:$A$102)*($G160='Thang 05-2026'!$C$3:$C$102),0),11)=0),1,0))} -> 0 | E160: {=IF(AND(INDEX('Thang 05-2026'!$A$3:$Q$102,MATCH(1,($A160='Thang 05-2026'!$A$3:$A$102)*($G160='Thang 05-2026'!$C$3:$C$102),0),15)=1,$B160="Triều Xuống"),1,IF(AND(INDEX('Thang 05-2026'!$A$3:$Q$102,MATCH(1,($A160='Thang 05-2026'!$A$3:$A$102)*($G160='Thang 05-2026'!$C$3:$C$102),0),14)=1,$B160="Triều Lên",INDEX('Thang 05-2026'!$A$3:$Q$102,MATCH(1,($A160='Thang 05-2026'!$A$3:$A$102)*($G160='Thang 05-2026'!$C$3:$C$102),0),15)=0),1,0))} -> 0 | F160: =D160+E160 -> 0 | G160: =INDEX('Thang 05-2026'!$A$3:$C$102,MATCH(A160,'Thang 05-2026'!$A$3:$A$102,0),3) -> 27
A161: Chợ Đệm | B161: Triều Xuống | C161: 1 | D161: {=IF(AND(INDEX('Thang 05-2026'!$A$3:$Q$102,MATCH(1,($A161='Thang 05-2026'!$A$3:$A$102)*($G161='Thang 05-2026'!$C$3:$C$102),0),11)=1,$B161="Triều Xuống"),1,IF(AND(INDEX('Thang 05-2026'!$A$3:$Q$102,MATCH(1,($A161='Thang 05-2026'!$A$3:$A$102)*($G161='Thang 05-2026'!$C$3:$C$102),0),10)=1,$B161="Triều Lên",INDEX('Thang 05-2026'!$A$3:$Q$102,MATCH(1,($A161='Thang 05-2026'!$A$3:$A$102)*($G161='Thang 05-2026'!$C$3:$C$102),0),11)=0),1,0))} -> 0 | E161: {=IF(AND(INDEX('Thang 05-2026'!$A$3:$Q$102,MATCH(1,($A161='Thang 05-2026'!$A$3:$A$102)*($G161='Thang 05-2026'!$C$3:$C$102),0),15)=1,$B161="Triều Xuống"),1,IF(AND(INDEX('Thang 05-2026'!$A$3:$Q$102,MATCH(1,($A161='Thang 05-2026'!$A$3:$A$102)*($G161='Thang 05-2026'!$C$3:$C$102),0),14)=1,$B161="Triều Lên",INDEX('Thang 05-2026'!$A$3:$Q$102,MATCH(1,($A161='Thang 05-2026'!$A$3:$A$102)*($G161='Thang 05-2026'!$C$3:$C$102),0),15)=0),1,0))} -> 0 | F161: =D161+E161 -> 0 | G161: =INDEX('Thang 05-2026'!$A$3:$C$102,MATCH(A161,'Thang 05-2026'!$A$3:$A$102,0),3) -> 27
A162: TBNM15 | B162: Triều Lên | C162: 1 | D162: {=IF(AND(INDEX('Thang 05-2026'!$A$3:$Q$102,MATCH(1,($A162='Thang 05-2026'!$A$3:$A$102)*($G162='Thang 05-2026'!$C$3:$C$102),0),11)=1,$B162="Triều Xuống"),1,IF(AND(INDEX('Thang 05-2026'!$A$3:$Q$102,MATCH(1,($A162='Thang 05-2026'!$A$3:$A$102)*($G162='Thang 05-2026'!$C$3:$C$102),0),10)=1,$B162="Triều Lên",INDEX('Thang 05-2026'!$A$3:$Q$102,MATCH(1,($A162='Thang 05-2026'!$A$3:$A$102)*($G162='Thang 05-2026'!$C$3:$C$102),0),11)=0),1,0))} -> 0 | E162: {=IF(AND(INDEX('Thang 05-2026'!$A$3:$Q$102,MATCH(1,($A162='Thang 05-2026'!$A$3:$A$102)*($G162='Thang 05-2026'!$C$3:$C$102),0),15)=1,$B162="Triều Xuống"),1,IF(AND(INDEX('Thang 05-2026'!$A$3:$Q$102,MATCH(1,($A162='Thang 05-2026'!$A$3:$A$102)*($G162='Thang 05-2026'!$C$3:$C$102),0),14)=1,$B162="Triều Lên",INDEX('Thang 05-2026'!$A$3:$Q$102,MATCH(1,($A162='Thang 05-2026'!$A$3:$A$102)*($G162='Thang 05-2026'!$C$3:$C$102),0),15)=0),1,0))} -> 0 | F162: =D162+E162 -> 0 | G162: 28
A163: TBNM5 | B163: Triều Lên | C163: 1 | D163: {=IF(AND(INDEX('Thang 05-2026'!$A$3:$Q$102,MATCH(1,($A163='Thang 05-2026'!$A$3:$A$102)*($G163='Thang 05-2026'!$C$3:$C$102),0),11)=1,$B163="Triều Xuống"),1,IF(AND(INDEX('Thang 05-2026'!$A$3:$Q$102,MATCH(1,($A163='Thang 05-2026'!$A$3:$A$102)*($G163='Thang 05-2026'!$C$3:$C$102),0),10)=1,$B163="Triều Lên",INDEX('Thang 05-2026'!$A$3:$Q$102,MATCH(1,($A163='Thang 05-2026'!$A$3:$A$102)*($G163='Thang 05-2026'!$C$3:$C$102),0),11)=0),1,0))} -> 0 | E163: {=IF(AND(INDEX('Thang 05-2026'!$A$3:$Q$102,MATCH(1,($A163='Thang 05-2026'!$A$3:$A$102)*($G163='Thang 05-2026'!$C$3:$C$102),0),15)=1,$B163="Triều Xuống"),1,IF(AND(INDEX('Thang 05-2026'!$A$3:$Q$102,MATCH(1,($A163='Thang 05-2026'!$A$3:$A$102)*($G163='Thang 05-2026'!$C$3:$C$102),0),14)=1,$B163="Triều Lên",INDEX('Thang 05-2026'!$A$3:$Q$102,MATCH(1,($A163='Thang 05-2026'!$A$3:$A$102)*($G163='Thang 05-2026'!$C$3:$C$102),0),15)=0),1,0))} -> 0 | F163: =D163+E163 -> 0 | G163: 28
A164: TBNM14 | B164: Triều Lên | C164: 1 | D164: {=IF(AND(INDEX('Thang 05-2026'!$A$3:$Q$102,MATCH(1,($A164='Thang 05-2026'!$A$3:$A$102)*($G164='Thang 05-2026'!$C$3:$C$102),0),11)=1,$B164="Triều Xuống"),1,IF(AND(INDEX('Thang 05-2026'!$A$3:$Q$102,MATCH(1,($A164='Thang 05-2026'!$A$3:$A$102)*($G164='Thang 05-2026'!$C$3:$C$102),0),10)=1,$B164="Triều Lên",INDEX('Thang 05-2026'!$A$3:$Q$102,MATCH(1,($A164='Thang 05-2026'!$A$3:$A$102)*($G164='Thang 05-2026'!$C$3:$C$102),0),11)=0),1,0))} -> 0 | E164: {=IF(AND(INDEX('Thang 05-2026'!$A$3:$Q$102,MATCH(1,($A164='Thang 05-2026'!$A$3:$A$102)*($G164='Thang 05-2026'!$C$3:$C$102),0),15)=1,$B164="Triều Xuống"),1,IF(AND(INDEX('Thang 05-2026'!$A$3:$Q$102,MATCH(1,($A164='Thang 05-2026'!$A$3:$A$102)*($G164='Thang 05-2026'!$C$3:$C$102),0),14)=1,$B164="Triều Lên",INDEX('Thang 05-2026'!$A$3:$Q$102,MATCH(1,($A164='Thang 05-2026'!$A$3:$A$102)*($G164='Thang 05-2026'!$C$3:$C$102),0),15)=0),1,0))} -> 0 | F164: =D164+E164 -> 0 | G164: 28
A165: TBNM9 | B165: Triều Lên | C165: 1 | D165: {=IF(AND(INDEX('Thang 05-2026'!$A$3:$Q$102,MATCH(1,($A165='Thang 05-2026'!$A$3:$A$102)*($G165='Thang 05-2026'!$C$3:$C$102),0),11)=1,$B165="Triều Xuống"),1,IF(AND(INDEX('Thang 05-2026'!$A$3:$Q$102,MATCH(1,($A165='Thang 05-2026'!$A$3:$A$102)*($G165='Thang 05-2026'!$C$3:$C$102),0),10)=1,$B165="Triều Lên",INDEX('Thang 05-2026'!$A$3:$Q$102,MATCH(1,($A165='Thang 05-2026'!$A$3:$A$102)*($G165='Thang 05-2026'!$C$3:$C$102),0),11)=0),1,0))} -> 1 | E165: {=IF(AND(INDEX('Thang 05-2026'!$A$3:$Q$102,MATCH(1,($A165='Thang 05-2026'!$A$3:$A$102)*($G165='Thang 05-2026'!$C$3:$C$102),0),15)=1,$B165="Triều Xuống"),1,IF(AND(INDEX('Thang 05-2026'!$A$3:$Q$102,MATCH(1,($A165='Thang 05-2026'!$A$3:$A$102)*($G165='Thang 05-2026'!$C$3:$C$102),0),14)=1,$B165="Triều Lên",INDEX('Thang 05-2026'!$A$3:$Q$102,MATCH(1,($A165='Thang 05-2026'!$A$3:$A$102)*($G165='Thang 05-2026'!$C$3:$C$102),0),15)=0),1,0))} -> 0 | F165: =D165+E165 -> 1 | G165: 28
A166: TBNM11 | B166: Triều Lên | C166: 1 | D166: {=IF(AND(INDEX('Thang 05-2026'!$A$3:$Q$102,MATCH(1,($A166='Thang 05-2026'!$A$3:$A$102)*($G166='Thang 05-2026'!$C$3:$C$102),0),11)=1,$B166="Triều Xuống"),1,IF(AND(INDEX('Thang 05-2026'!$A$3:$Q$102,MATCH(1,($A166='Thang 05-2026'!$A$3:$A$102)*($G166='Thang 05-2026'!$C$3:$C$102),0),10)=1,$B166="Triều Lên",INDEX('Thang 05-2026'!$A$3:$Q$102,MATCH(1,($A166='Thang 05-2026'!$A$3:$A$102)*($G166='Thang 05-2026'!$C$3:$C$102),0),11)=0),1,0))} -> 0 | E166: {=IF(AND(INDEX('Thang 05-2026'!$A$3:$Q$102,MATCH(1,($A166='Thang 05-2026'!$A$3:$A$102)*($G166='Thang 05-2026'!$C$3:$C$102),0),15)=1,$B166="Triều Xuống"),1,IF(AND(INDEX('Thang 05-2026'!$A$3:$Q$102,MATCH(1,($A166='Thang 05-2026'!$A$3:$A$102)*($G166='Thang 05-2026'!$C$3:$C$102),0),14)=1,$B166="Triều Lên",INDEX('Thang 05-2026'!$A$3:$Q$102,MATCH(1,($A166='Thang 05-2026'!$A$3:$A$102)*($G166='Thang 05-2026'!$C$3:$C$102),0),15)=0),1,0))} -> 0 | F166: =D166+E166 -> 0 | G166: 28
A167: TBNM1 | B167: Triều Lên | C167: 1 | D167: {=IF(AND(INDEX('Thang 05-2026'!$A$3:$Q$102,MATCH(1,($A167='Thang 05-2026'!$A$3:$A$102)*($G167='Thang 05-2026'!$C$3:$C$102),0),11)=1,$B167="Triều Xuống"),1,IF(AND(INDEX('Thang 05-2026'!$A$3:$Q$102,MATCH(1,($A167='Thang 05-2026'!$A$3:$A$102)*($G167='Thang 05-2026'!$C$3:$C$102),0),10)=1,$B167="Triều Lên",INDEX('Thang 05-2026'!$A$3:$Q$102,MATCH(1,($A167='Thang 05-2026'!$A$3:$A$102)*($G167='Thang 05-2026'!$C$3:$C$102),0),11)=0),1,0))} -> 0 | E167: {=IF(AND(INDEX('Thang 05-2026'!$A$3:$Q$102,MATCH(1,($A167='Thang 05-2026'!$A$3:$A$102)*($G167='Thang 05-2026'!$C$3:$C$102),0),15)=1,$B167="Triều Xuống"),1,IF(AND(INDEX('Thang 05-2026'!$A$3:$Q$102,MATCH(1,($A167='Thang 05-2026'!$A$3:$A$102)*($G167='Thang 05-2026'!$C$3:$C$102),0),14)=1,$B167="Triều Lên",INDEX('Thang 05-2026'!$A$3:$Q$102,MATCH(1,($A167='Thang 05-2026'!$A$3:$A$102)*($G167='Thang 05-2026'!$C$3:$C$102),0),15)=0),1,0))} -> 0 | F167: =D167+E167 -> 0 | G167: 28
A168: TBNM15 | B168: Triều Xuống | C168: 1 | D168: {=IF(AND(INDEX('Thang 05-2026'!$A$3:$Q$102,MATCH(1,($A168='Thang 05-2026'!$A$3:$A$102)*($G168='Thang 05-2026'!$C$3:$C$102),0),11)=1,$B168="Triều Xuống"),1,IF(AND(INDEX('Thang 05-2026'!$A$3:$Q$102,MATCH(1,($A168='Thang 05-2026'!$A$3:$A$102)*($G168='Thang 05-2026'!$C$3:$C$102),0),10)=1,$B168="Triều Lên",INDEX('Thang 05-2026'!$A$3:$Q$102,MATCH(1,($A168='Thang 05-2026'!$A$3:$A$102)*($G168='Thang 05-2026'!$C$3:$C$102),0),11)=0),1,0))} -> 0 | E168: {=IF(AND(INDEX('Thang 05-2026'!$A$3:$Q$102,MATCH(1,($A168='Thang 05-2026'!$A$3:$A$102)*($G168='Thang 05-2026'!$C$3:$C$102),0),15)=1,$B168="Triều Xuống"),1,IF(AND(INDEX('Thang 05-2026'!$A$3:$Q$102,MATCH(1,($A168='Thang 05-2026'!$A$3:$A$102)*($G168='Thang 05-2026'!$C$3:$C$102),0),14)=1,$B168="Triều Lên",INDEX('Thang 05-2026'!$A$3:$Q$102,MATCH(1,($A168='Thang 05-2026'!$A$3:$A$102)*($G168='Thang 05-2026'!$C$3:$C$102),0),15)=0),1,0))} -> 1 | F168: =D168+E168 -> 1 | G168: 28
A169: TBNM5 | B169: Triều Xuống | C169: 1 | D169: {=IF(AND(INDEX('Thang 05-2026'!$A$3:$Q$102,MATCH(1,($A169='Thang 05-2026'!$A$3:$A$102)*($G169='Thang 05-2026'!$C$3:$C$102),0),11)=1,$B169="Triều Xuống"),1,IF(AND(INDEX('Thang 05-2026'!$A$3:$Q$102,MATCH(1,($A169='Thang 05-2026'!$A$3:$A$102)*($G169='Thang 05-2026'!$C$3:$C$102),0),10)=1,$B169="Triều Lên",INDEX('Thang 05-2026'!$A$3:$Q$102,MATCH(1,($A169='Thang 05-2026'!$A$3:$A$102)*($G169='Thang 05-2026'!$C$3:$C$102),0),11)=0),1,0))} -> 0 | E169: {=IF(AND(INDEX('Thang 05-2026'!$A$3:$Q$102,MATCH(1,($A169='Thang 05-2026'!$A$3:$A$102)*($G169='Thang 05-2026'!$C$3:$C$102),0),15)=1,$B169="Triều Xuống"),1,IF(AND(INDEX('Thang 05-2026'!$A$3:$Q$102,MATCH(1,($A169='Thang 05-2026'!$A$3:$A$102)*($G169='Thang 05-2026'!$C$3:$C$102),0),14)=1,$B169="Triều Lên",INDEX('Thang 05-2026'!$A$3:$Q$102,MATCH(1,($A169='Thang 05-2026'!$A$3:$A$102)*($G169='Thang 05-2026'!$C$3:$C$102),0),15)=0),1,0))} -> 0 | F169: =D169+E169 -> 0 | G169: 28
A170: TBNM14 | B170: Triều Xuống | C170: 1 | D170: {=IF(AND(INDEX('Thang 05-2026'!$A$3:$Q$102,MATCH(1,($A170='Thang 05-2026'!$A$3:$A$102)*($G170='Thang 05-2026'!$C$3:$C$102),0),11)=1,$B170="Triều Xuống"),1,IF(AND(INDEX('Thang 05-2026'!$A$3:$Q$102,MATCH(1,($A170='Thang 05-2026'!$A$3:$A$102)*($G170='Thang 05-2026'!$C$3:$C$102),0),10)=1,$B170="Triều Lên",INDEX('Thang 05-2026'!$A$3:$Q$102,MATCH(1,($A170='Thang 05-2026'!$A$3:$A$102)*($G170='Thang 05-2026'!$C$3:$C$102),0),11)=0),1,0))} -> 0 | E170: {=IF(AND(INDEX('Thang 05-2026'!$A$3:$Q$102,MATCH(1,($A170='Thang 05-2026'!$A$3:$A$102)*($G170='Thang 05-2026'!$C$3:$C$102),0),15)=1,$B170="Triều Xuống"),1,IF(AND(INDEX('Thang 05-2026'!$A$3:$Q$102,MATCH(1,($A170='Thang 05-2026'!$A$3:$A$102)*($G170='Thang 05-2026'!$C$3:$C$102),0),14)=1,$B170="Triều Lên",INDEX('Thang 05-2026'!$A$3:$Q$102,MATCH(1,($A170='Thang 05-2026'!$A$3:$A$102)*($G170='Thang 05-2026'!$C$3:$C$102),0),15)=0),1,0))} -> 0 | F170: =D170+E170 -> 0 | G170: 28
A171: TBNM9 | B171: Triều Xuống | C171: 1 | D171: {=IF(AND(INDEX('Thang 05-2026'!$A$3:$Q$102,MATCH(1,($A171='Thang 05-2026'!$A$3:$A$102)*($G171='Thang 05-2026'!$C$3:$C$102),0),11)=1,$B171="Triều Xuống"),1,IF(AND(INDEX('Thang 05-2026'!$A$3:$Q$102,MATCH(1,($A171='Thang 05-2026'!$A$3:$A$102)*($G171='Thang 05-2026'!$C$3:$C$102),0),10)=1,$B171="Triều Lên",INDEX('Thang 05-2026'!$A$3:$Q$102,MATCH(1,($A171='Thang 05-2026'!$A$3:$A$102)*($G171='Thang 05-2026'!$C$3:$C$102),0),11)=0),1,0))} -> 0 | E171: {=IF(AND(INDEX('Thang 05-2026'!$A$3:$Q$102,MATCH(1,($A171='Thang 05-2026'!$A$3:$A$102)*($G171='Thang 05-2026'!$C$3:$C$102),0),15)=1,$B171="Triều Xuống"),1,IF(AND(INDEX('Thang 05-2026'!$A$3:$Q$102,MATCH(1,($A171='Thang 05-2026'!$A$3:$A$102)*($G171='Thang 05-2026'!$C$3:$C$102),0),14)=1,$B171="Triều Lên",INDEX('Thang 05-2026'!$A$3:$Q$102,MATCH(1,($A171='Thang 05-2026'!$A$3:$A$102)*($G171='Thang 05-2026'!$C$3:$C$102),0),15)=0),1,0))} -> 0 | F171: =D171+E171 -> 0 | G171: 28
...

Sheet CS3_OLD
A1: Nơi thực hiện | B1: Vị trí quan trắc | C1: Số lượng mẫu | D1: Số lượng mẫu QC lặp | E1: Số lượng mẫu QC trắng | F1: Số lượng mẫu QC | G1: Ngày
A2: Lòng Tàu 1 | B2: Triều Lên | C2: 1 | D2: {=IF(AND(INDEX('Thang 05-2026'!$A$3:$Q$102,MATCH(1,($A2='Thang 05-2026'!$A$3:$A$102)*($G2='Thang 05-2026'!$C$3:$C$102),0),11)=1,$B2="Triều Xuống"),1,IF(AND(INDEX('Thang 05-2026'!$A$3:$Q$102,MATCH(1,($A2='Thang 05-2026'!$A$3:$A$102)*($G2='Thang 05-2026'!$C$3:$C$102),0),10)=1,$B2="Triều Lên",INDEX('Thang 05-2026'!$A$3:$Q$102,MATCH(1,($A2='Thang 05-2026'!$A$3:$A$102)*($G2='Thang 05-2026'!$C$3:$C$102),0),11)=0),1,0))} -> 0 | E2: {=IF(AND(INDEX('Thang 05-2026'!$A$3:$Q$102,MATCH(1,($A2='Thang 05-2026'!$A$3:$A$102)*($G2='Thang 05-2026'!$C$3:$C$102),0),15)=1,$B2="Triều Xuống"),1,IF(AND(INDEX('Thang 05-2026'!$A$3:$Q$102,MATCH(1,($A2='Thang 05-2026'!$A$3:$A$102)*($G2='Thang 05-2026'!$C$3:$C$102),0),14)=1,$B2="Triều Lên",INDEX('Thang 05-2026'!$A$3:$Q$102,MATCH(1,($A2='Thang 05-2026'!$A$3:$A$102)*($G2='Thang 05-2026'!$C$3:$C$102),0),15)=0),1,0))} -> 0 | F2: =D2+E2 -> 0 | G2: =INDEX('Thang 05-2026'!$A$3:$C$102,MATCH(A2,'Thang 05-2026'!$A$3:$A$102,0),3) -> 25
A3: Lòng Tàu | B3: Triều Lên | C3: 1 | D3: {=IF(AND(INDEX('Thang 05-2026'!$A$3:$Q$102,MATCH(1,($A3='Thang 05-2026'!$A$3:$A$102)*($G3='Thang 05-2026'!$C$3:$C$102),0),11)=1,$B3="Triều Xuống"),1,IF(AND(INDEX('Thang 05-2026'!$A$3:$Q$102,MATCH(1,($A3='Thang 05-2026'!$A$3:$A$102)*($G3='Thang 05-2026'!$C$3:$C$102),0),10)=1,$B3="Triều Lên",INDEX('Thang 05-2026'!$A$3:$Q$102,MATCH(1,($A3='Thang 05-2026'!$A$3:$A$102)*($G3='Thang 05-2026'!$C$3:$C$102),0),11)=0),1,0))} -> 0 | E3: {=IF(AND(INDEX('Thang 05-2026'!$A$3:$Q$102,MATCH(1,($A3='Thang 05-2026'!$A$3:$A$102)*($G3='Thang 05-2026'!$C$3:$C$102),0),15)=1,$B3="Triều Xuống"),1,IF(AND(INDEX('Thang 05-2026'!$A$3:$Q$102,MATCH(1,($A3='Thang 05-2026'!$A$3:$A$102)*($G3='Thang 05-2026'!$C$3:$C$102),0),14)=1,$B3="Triều Lên",INDEX('Thang 05-2026'!$A$3:$Q$102,MATCH(1,($A3='Thang 05-2026'!$A$3:$A$102)*($G3='Thang 05-2026'!$C$3:$C$102),0),15)=0),1,0))} -> 0 | F3: =D3+E3 -> 0 | G3: =INDEX('Thang 05-2026'!$A$3:$C$102,MATCH(A3,'Thang 05-2026'!$A$3:$A$102,0),3) -> 25
A4: Tam Thôn Hiệp | B4: Triều Lên | C4: 1 | D4: {=IF(AND(INDEX('Thang 05-2026'!$A$3:$Q$102,MATCH(1,($A4='Thang 05-2026'!$A$3:$A$102)*($G4='Thang 05-2026'!$C$3:$C$102),0),11)=1,$B4="Triều Xuống"),1,IF(AND(INDEX('Thang 05-2026'!$A$3:$Q$102,MATCH(1,($A4='Thang 05-2026'!$A$3:$A$102)*($G4='Thang 05-2026'!$C$3:$C$102),0),10)=1,$B4="Triều Lên",INDEX('Thang 05-2026'!$A$3:$Q$102,MATCH(1,($A4='Thang 05-2026'!$A$3:$A$102)*($G4='Thang 05-2026'!$C$3:$C$102),0),11)=0),1,0))} -> 0 | E4: {=IF(AND(INDEX('Thang 05-2026'!$A$3:$Q$102,MATCH(1,($A4='Thang 05-2026'!$A$3:$A$102)*($G4='Thang 05-2026'!$C$3:$C$102),0),15)=1,$B4="Triều Xuống"),1,IF(AND(INDEX('Thang 05-2026'!$A$3:$Q$102,MATCH(1,($A4='Thang 05-2026'!$A$3:$A$102)*($G4='Thang 05-2026'!$C$3:$C$102),0),14)=1,$B4="Triều Lên",INDEX('Thang 05-2026'!$A$3:$Q$102,MATCH(1,($A4='Thang 05-2026'!$A$3:$A$102)*($G4='Thang 05-2026'!$C$3:$C$102),0),15)=0),1,0))} -> 0 | F4: =D4+E4 -> 0 | G4: =INDEX('Thang 05-2026'!$A$3:$C$102,MATCH(A4,'Thang 05-2026'!$A$3:$A$102,0),3) -> 25
A5: Đồng Tranh 1 | B5: Triều Lên | C5: 1 | D5: {=IF(AND(INDEX('Thang 05-2026'!$A$3:$Q$102,MATCH(1,($A5='Thang 05-2026'!$A$3:$A$102)*($G5='Thang 05-2026'!$C$3:$C$102),0),11)=1,$B5="Triều Xuống"),1,IF(AND(INDEX('Thang 05-2026'!$A$3:$Q$102,MATCH(1,($A5='Thang 05-2026'!$A$3:$A$102)*($G5='Thang 05-2026'!$C$3:$C$102),0),10)=1,$B5="Triều Lên",INDEX('Thang 05-2026'!$A$3:$Q$102,MATCH(1,($A5='Thang 05-2026'!$A$3:$A$102)*($G5='Thang 05-2026'!$C$3:$C$102),0),11)=0),1,0))} -> 0 | E5: {=IF(AND(INDEX('Thang 05-2026'!$A$3:$Q$102,MATCH(1,($A5='Thang 05-2026'!$A$3:$A$102)*($G5='Thang 05-2026'!$C$3:$C$102),0),15)=1,$B5="Triều Xuống"),1,IF(AND(INDEX('Thang 05-2026'!$A$3:$Q$102,MATCH(1,($A5='Thang 05-2026'!$A$3:$A$102)*($G5='Thang 05-2026'!$C$3:$C$102),0),14)=1,$B5="Triều Lên",INDEX('Thang 05-2026'!$A$3:$Q$102,MATCH(1,($A5='Thang 05-2026'!$A$3:$A$102)*($G5='Thang 05-2026'!$C$3:$C$102),0),15)=0),1,0))} -> 0 | F5: =D5+E5 -> 0 | G5: =INDEX('Thang 05-2026'!$A$3:$C$102,MATCH(A5,'Thang 05-2026'!$A$3:$A$102,0),3) -> 25
A6: Lòng Tàu 1 | B6: Triều Xuống | C6: 1 | D6: {=IF(AND(INDEX('Thang 05-2026'!$A$3:$Q$102,MATCH(1,($A6='Thang 05-2026'!$A$3:$A$102)*($G6='Thang 05-2026'!$C$3:$C$102),0),11)=1,$B6="Triều Xuống"),1,IF(AND(INDEX('Thang 05-2026'!$A$3:$Q$102,MATCH(1,($A6='Thang 05-2026'!$A$3:$A$102)*($G6='Thang 05-2026'!$C$3:$C$102),0),10)=1,$B6="Triều Lên",INDEX('Thang 05-2026'!$A$3:$Q$102,MATCH(1,($A6='Thang 05-2026'!$A$3:$A$102)*($G6='Thang 05-2026'!$C$3:$C$102),0),11)=0),1,0))} -> 0 | E6: {=IF(AND(INDEX('Thang 05-2026'!$A$3:$Q$102,MATCH(1,($A6='Thang 05-2026'!$A$3:$A$102)*($G6='Thang 05-2026'!$C$3:$C$102),0),15)=1,$B6="Triều Xuống"),1,IF(AND(INDEX('Thang 05-2026'!$A$3:$Q$102,MATCH(1,($A6='Thang 05-2026'!$A$3:$A$102)*($G6='Thang 05-2026'!$C$3:$C$102),0),14)=1,$B6="Triều Lên",INDEX('Thang 05-2026'!$A$3:$Q$102,MATCH(1,($A6='Thang 05-2026'!$A$3:$A$102)*($G6='Thang 05-2026'!$C$3:$C$102),0),15)=0),1,0))} -> 0 | F6: =D6+E6 -> 0 | G6: =INDEX('Thang 05-2026'!$A$3:$C$102,MATCH(A6,'Thang 05-2026'!$A$3:$A$102,0),3) -> 25
A7: Lòng Tàu | B7: Triều Xuống | C7: 1 | D7: {=IF(AND(INDEX('Thang 05-2026'!$A$3:$Q$102,MATCH(1,($A7='Thang 05-2026'!$A$3:$A$102)*($G7='Thang 05-2026'!$C$3:$C$102),0),11)=1,$B7="Triều Xuống"),1,IF(AND(INDEX('Thang 05-2026'!$A$3:$Q$102,MATCH(1,($A7='Thang 05-2026'!$A$3:$A$102)*($G7='Thang 05-2026'!$C$3:$C$102),0),10)=1,$B7="Triều Lên",INDEX('Thang 05-2026'!$A$3:$Q$102,MATCH(1,($A7='Thang 05-2026'!$A$3:$A$102)*($G7='Thang 05-2026'!$C$3:$C$102),0),11)=0),1,0))} -> 0 | E7: {=IF(AND(INDEX('Thang 05-2026'!$A$3:$Q$102,MATCH(1,($A7='Thang 05-2026'!$A$3:$A$102)*($G7='Thang 05-2026'!$C$3:$C$102),0),15)=1,$B7="Triều Xuống"),1,IF(AND(INDEX('Thang 05-2026'!$A$3:$Q$102,MATCH(1,($A7='Thang 05-2026'!$A$3:$A$102)*($G7='Thang 05-2026'!$C$3:$C$102),0),14)=1,$B7="Triều Lên",INDEX('Thang 05-2026'!$A$3:$Q$102,MATCH(1,($A7='Thang 05-2026'!$A$3:$A$102)*($G7='Thang 05-2026'!$C$3:$C$102),0),15)=0),1,0))} -> 0 | F7: =D7+E7 -> 0 | G7: =INDEX('Thang 05-2026'!$A$3:$C$102,MATCH(A7,'Thang 05-2026'!$A$3:$A$102,0),3) -> 25
A8: Tam Thôn Hiệp | B8: Triều Xuống | C8: 1 | D8: {=IF(AND(INDEX('Thang 05-2026'!$A$3:$Q$102,MATCH(1,($A8='Thang 05-2026'!$A$3:$A$102)*($G8='Thang 05-2026'!$C$3:$C$102),0),11)=1,$B8="Triều Xuống"),1,IF(AND(INDEX('Thang 05-2026'!$A$3:$Q$102,MATCH(1,($A8='Thang 05-2026'!$A$3:$A$102)*($G8='Thang 05-2026'!$C$3:$C$102),0),10)=1,$B8="Triều Lên",INDEX('Thang 05-2026'!$A$3:$Q$102,MATCH(1,($A8='Thang 05-2026'!$A$3:$A$102)*($G8='Thang 05-2026'!$C$3:$C$102),0),11)=0),1,0))} -> 0 | E8: {=IF(AND(INDEX('Thang 05-2026'!$A$3:$Q$102,MATCH(1,($A8='Thang 05-2026'!$A$3:$A$102)*($G8='Thang 05-2026'!$C$3:$C$102),0),15)=1,$B8="Triều Xuống"),1,IF(AND(INDEX('Thang 05-2026'!$A$3:$Q$102,MATCH(1,($A8='Thang 05-2026'!$A$3:$A$102)*($G8='Thang 05-2026'!$C$3:$C$102),0),14)=1,$B8="Triều Lên",INDEX('Thang 05-2026'!$A$3:$Q$102,MATCH(1,($A8='Thang 05-2026'!$A$3:$A$102)*($G8='Thang 05-2026'!$C$3:$C$102),0),15)=0),1,0))} -> 0 | F8: =D8+E8 -> 0 | G8: =INDEX('Thang 05-2026'!$A$3:$C$102,MATCH(A8,'Thang 05-2026'!$A$3:$A$102,0),3) -> 25
A9: Đồng Tranh 1 | B9: Triều Xuống | C9: 1 | D9: {=IF(AND(INDEX('Thang 05-2026'!$A$3:$Q$102,MATCH(1,($A9='Thang 05-2026'!$A$3:$A$102)*($G9='Thang 05-2026'!$C$3:$C$102),0),11)=1,$B9="Triều Xuống"),1,IF(AND(INDEX('Thang 05-2026'!$A$3:$Q$102,MATCH(1,($A9='Thang 05-2026'!$A$3:$A$102)*($G9='Thang 05-2026'!$C$3:$C$102),0),10)=1,$B9="Triều Lên",INDEX('Thang 05-2026'!$A$3:$Q$102,MATCH(1,($A9='Thang 05-2026'!$A$3:$A$102)*($G9='Thang 05-2026'!$C$3:$C$102),0),11)=0),1,0))} -> 0 | E9: {=IF(AND(INDEX('Thang 05-2026'!$A$3:$Q$102,MATCH(1,($A9='Thang 05-2026'!$A$3:$A$102)*($G9='Thang 05-2026'!$C$3:$C$102),0),15)=1,$B9="Triều Xuống"),1,IF(AND(INDEX('Thang 05-2026'!$A$3:$Q$102,MATCH(1,($A9='Thang 05-2026'!$A$3:$A$102)*($G9='Thang 05-2026'!$C$3:$C$102),0),14)=1,$B9="Triều Lên",INDEX('Thang 05-2026'!$A$3:$Q$102,MATCH(1,($A9='Thang 05-2026'!$A$3:$A$102)*($G9='Thang 05-2026'!$C$3:$C$102),0),15)=0),1,0))} -> 0 | F9: =D9+E9 -> 0 | G9: =INDEX('Thang 05-2026'!$A$3:$C$102,MATCH(A9,'Thang 05-2026'!$A$3:$A$102,0),3) -> 25
A10: Bình Lợi | B10: Triều Lên | C10: 1 | D10: {=IF(AND(INDEX('Thang 05-2026'!$A$3:$Q$102,MATCH(1,($A10='Thang 05-2026'!$A$3:$A$102)*($G10='Thang 05-2026'!$C$3:$C$102),0),11)=1,$B10="Triều Xuống"),1,IF(AND(INDEX('Thang 05-2026'!$A$3:$Q$102,MATCH(1,($A10='Thang 05-2026'!$A$3:$A$102)*($G10='Thang 05-2026'!$C$3:$C$102),0),10)=1,$B10="Triều Lên",INDEX('Thang 05-2026'!$A$3:$Q$102,MATCH(1,($A10='Thang 05-2026'!$A$3:$A$102)*($G10='Thang 05-2026'!$C$3:$C$102),0),11)=0),1,0))} -> 0 | E10: {=IF(AND(INDEX('Thang 05-2026'!$A$3:$Q$102,MATCH(1,($A10='Thang 05-2026'!$A$3:$A$102)*($G10='Thang 05-2026'!$C$3:$C$102),0),15)=1,$B10="Triều Xuống"),1,IF(AND(INDEX('Thang 05-2026'!$A$3:$Q$102,MATCH(1,($A10='Thang 05-2026'!$A$3:$A$102)*($G10='Thang 05-2026'!$C$3:$C$102),0),14)=1,$B10="Triều Lên",INDEX('Thang 05-2026'!$A$3:$Q$102,MATCH(1,($A10='Thang 05-2026'!$A$3:$A$102)*($G10='Thang 05-2026'!$C$3:$C$102),0),15)=0),1,0))} -> 0 | F10: =D10+E10 -> 0 | G10: =INDEX('Thang 05-2026'!$A$3:$C$102,MATCH(A10,'Thang 05-2026'!$A$3:$A$102,0),3) -> 25
A11: Sài Gòn | B11: Triều Lên | C11: 1 | D11: {=IF(AND(INDEX('Thang 05-2026'!$A$3:$Q$102,MATCH(1,($A11='Thang 05-2026'!$A$3:$A$102)*($G11='Thang 05-2026'!$C$3:$C$102),0),11)=1,$B11="Triều Xuống"),1,IF(AND(INDEX('Thang 05-2026'!$A$3:$Q$102,MATCH(1,($A11='Thang 05-2026'!$A$3:$A$102)*($G11='Thang 05-2026'!$C$3:$C$102),0),10)=1,$B11="Triều Lên",INDEX('Thang 05-2026'!$A$3:$Q$102,MATCH(1,($A11='Thang 05-2026'!$A$3:$A$102)*($G11='Thang 05-2026'!$C$3:$C$102),0),11)=0),1,0))} -> 0 | E11: {=IF(AND(INDEX('Thang 05-2026'!$A$3:$Q$102,MATCH(1,($A11='Thang 05-2026'!$A$3:$A$102)*($G11='Thang 05-2026'!$C$3:$C$102),0),15)=1,$B11="Triều Xuống"),1,IF(AND(INDEX('Thang 05-2026'!$A$3:$Q$102,MATCH(1,($A11='Thang 05-2026'!$A$3:$A$102)*($G11='Thang 05-2026'!$C$3:$C$102),0),14)=1,$B11="Triều Lên",INDEX('Thang 05-2026'!$A$3:$Q$102,MATCH(1,($A11='Thang 05-2026'!$A$3:$A$102)*($G11='Thang 05-2026'!$C$3:$C$102),0),15)=0),1,0))} -> 0 | F11: =D11+E11 -> 0 | G11: =INDEX('Thang 05-2026'!$A$3:$C$102,MATCH(A11,'Thang 05-2026'!$A$3:$A$102,0),3) -> 25
A12: Bình Lợi | B12: Triều Xuống | C12: 1 | D12: {=IF(AND(INDEX('Thang 05-2026'!$A$3:$Q$102,MATCH(1,($A12='Thang 05-2026'!$A$3:$A$102)*($G12='Thang 05-2026'!$C$3:$C$102),0),11)=1,$B12="Triều Xuống"),1,IF(AND(INDEX('Thang 05-2026'!$A$3:$Q$102,MATCH(1,($A12='Thang 05-2026'!$A$3:$A$102)*($G12='Thang 05-2026'!$C$3:$C$102),0),10)=1,$B12="Triều Lên",INDEX('Thang 05-2026'!$A$3:$Q$102,MATCH(1,($A12='Thang 05-2026'!$A$3:$A$102)*($G12='Thang 05-2026'!$C$3:$C$102),0),11)=0),1,0))} -> 0 | E12: {=IF(AND(INDEX('Thang 05-2026'!$A$3:$Q$102,MATCH(1,($A12='Thang 05-2026'!$A$3:$A$102)*($G12='Thang 05-2026'!$C$3:$C$102),0),15)=1,$B12="Triều Xuống"),1,IF(AND(INDEX('Thang 05-2026'!$A$3:$Q$102,MATCH(1,($A12='Thang 05-2026'!$A$3:$A$102)*($G12='Thang 05-2026'!$C$3:$C$102),0),14)=1,$B12="Triều Lên",INDEX('Thang 05-2026'!$A$3:$Q$102,MATCH(1,($A12='Thang 05-2026'!$A$3:$A$102)*($G12='Thang 05-2026'!$C$3:$C$102),0),15)=0),1,0))} -> 0 | F12: =D12+E12 -> 0 | G12: =INDEX('Thang 05-2026'!$A$3:$C$102,MATCH(A12,'Thang 05-2026'!$A$3:$A$102,0),3) -> 25
A13: Sài Gòn | B13: Triều Xuống | C13: 1 | D13: {=IF(AND(INDEX('Thang 05-2026'!$A$3:$Q$102,MATCH(1,($A13='Thang 05-2026'!$A$3:$A$102)*($G13='Thang 05-2026'!$C$3:$C$102),0),11)=1,$B13="Triều Xuống"),1,IF(AND(INDEX('Thang 05-2026'!$A$3:$Q$102,MATCH(1,($A13='Thang 05-2026'!$A$3:$A$102)*($G13='Thang 05-2026'!$C$3:$C$102),0),10)=1,$B13="Triều Lên",INDEX('Thang 05-2026'!$A$3:$Q$102,MATCH(1,($A13='Thang 05-2026'!$A$3:$A$102)*($G13='Thang 05-2026'!$C$3:$C$102),0),11)=0),1,0))} -> 0 | E13: {=IF(AND(INDEX('Thang 05-2026'!$A$3:$Q$102,MATCH(1,($A13='Thang 05-2026'!$A$3:$A$102)*($G13='Thang 05-2026'!$C$3:$C$102),0),15)=1,$B13="Triều Xuống"),1,IF(AND(INDEX('Thang 05-2026'!$A$3:$Q$102,MATCH(1,($A13='Thang 05-2026'!$A$3:$A$102)*($G13='Thang 05-2026'!$C$3:$C$102),0),14)=1,$B13="Triều Lên",INDEX('Thang 05-2026'!$A$3:$Q$102,MATCH(1,($A13='Thang 05-2026'!$A$3:$A$102)*($G13='Thang 05-2026'!$C$3:$C$102),0),15)=0),1,0))} -> 1 | F13: =D13+E13 -> 1 | G13: =INDEX('Thang 05-2026'!$A$3:$C$102,MATCH(A13,'Thang 05-2026'!$A$3:$A$102,0),3) -> 25
... A29: Phú Mỹ | B29: Triều Xuống | C29: 1 | D29: {=IF(AND(INDEX('Thang 05-2026'!$A$3:$Q$102,MATCH(1,($A29='Thang 05-2026'!$A$3:$A$102)*($G29='Thang 05-2026'!$C$3:$C$102),0),11)=1,$B29="Triều Xuống"),1,IF(AND(INDEX('Thang 05-2026'!$A$3:$Q$102,MATCH(1,($A29='Thang 05-2026'!$A$3:$A$102)*($G29='Thang 05-2026'!$C$3:$C$102),0),10)=1,$B29="Triều Lên",INDEX('Thang 05-2026'!$A$3:$Q$102,MATCH(1,($A29='Thang 05-2026'!$A$3:$A$102)*($G29='Thang 05-2026'!$C$3:$C$102),0),11)=0),1,0))} -> 0 | E29: {=IF(AND(INDEX('Thang 05-2026'!$A$3:$Q$102,MATCH(1,($A29='Thang 05-2026'!$A$3:$A$102)*($G29='Thang 05-2026'!$C$3:$C$102),0),15)=1,$B29="Triều Xuống"),1,IF(AND(INDEX('Thang 05-2026'!$A$3:$Q$102,MATCH(1,($A29='Thang 05-2026'!$A$3:$A$102)*($G29='Thang 05-2026'!$C$3:$C$102),0),14)=1,$B29="Triều Lên",INDEX('Thang 05-2026'!$A$3:$Q$102,MATCH(1,($A29='Thang 05-2026'!$A$3:$A$102)*($G29='Thang 05-2026'!$C$3:$C$102),0),15)=0),1,0))} -> 0 | F29: =D29+E29 -> 0 | G29: =INDEX('Thang 05-2026'!$A$3:$C$102,MATCH(A29,'Thang 05-2026'!$A$3:$A$102,0),3) -> 27

Sheet TONG HOP DIA DIEM
A1: Địa điểm quan trắc | B1: Triều | C1: Ký hiệu | D1: Tên viết tắt | E1: Địa chỉ | F1: Tên nơi lấy mẫu | G1: Tên vị trí | H1: Tên vị trí mẫu lặp | I1: Tên vị trí mẫu trắng hiện trường | J1: Tên vị trí mẫu trắng vận chuyển | K1: Tên vị trí mẫu trắng thiết bị
A2: Cầu số 1 | B2: Triều Lên | C2: HCM_NM_CS1 | D2: HCM_NM_CS1_L | E2: Khu vực Cầu số 1, đầu tuyến kênh Nhiêu Lộc – Thị Nghè | F2: Cầu số 1 - HCM_NM_CS1 - Triều Lên | G2: Cầu số 1 - Triều Lên | H2: Cầu số 1 - Triều Lên (QC - Mẫu lặp hiện trường) | I2: Cầu số 1 - Triều Lên (QC - Mẫu trắng hiện trường) | J2: Cầu số 1 - Triều Lên (QC - Mẫu trắng vận chuyển) | K2: Cầu số 1 - Triều Lên (QC - Mẫu trắng thiết bị)
A3: Lê Văn Sỹ | B3: Triều Lên | C3: HCM_NM_LVS | D3: HCM_NM_LVS_L | E3: Khu vực cầu Lê Văn Sỹ, nối đường Lê Văn Sỹ và đường Trần Quốc Thảo | F3: Lê Văn Sỹ - HCM_NM_LVS - Triều Lên | G3: Lê Văn Sỹ - Triều Lên | H3: Lê Văn Sỹ - Triều Lên (QC - Mẫu lặp hiện trường) | I3: Lê Văn Sỹ - Triều Lên (QC - Mẫu trắng hiện trường) | J3: Lê Văn Sỹ - Triều Lên (QC - Mẫu trắng vận chuyển) | K3: Lê Văn Sỹ - Triều Lên (QC - Mẫu trắng thiết bị)
A4: Hải Đức | B4: Triều Lên | C4: HCM_NM_HĐ | D4: HCM_NM_HĐ_L | E4: Đoạn kênh khu vực gần Chùa Hải Đức, phường Cầu Kiệu | F4: Hải Đức - HCM_NM_HĐ - Triều Lên | G4: Hải Đức - Triều Lên | H4: Hải Đức - Triều Lên (QC - Mẫu lặp hiện trường) | I4: Hải Đức - Triều Lên (QC - Mẫu trắng hiện trường) | J4: Hải Đức - Triều Lên (QC - Mẫu trắng vận chuyển) | K4: Hải Đức - Triều Lên (QC - Mẫu trắng thiết bị)
A5: Điện Biên Phủ | B5: Triều Lên | C5: HCM_NM_ĐBP | D5: HCM_NM_ĐBP_L | E5: Khu vực cầu Điện Biên Phủ, gần Vòng xoay Điện Biên Phủ | F5: Điện Biên Phủ - HCM_NM_ĐBP - Triều Lên | G5: Điện Biên Phủ - Triều Lên | H5: Điện Biên Phủ - Triều Lên (QC - Mẫu lặp hiện trường) | I5: Điện Biên Phủ - Triều Lên (QC - Mẫu trắng hiện trường) | J5: Điện Biên Phủ - Triều Lên (QC - Mẫu trắng vận chuyển) | K5: Điện Biên Phủ - Triều Lên (QC - Mẫu trắng thiết bị)
A6: Bùi Đình Túy | B6: Triều Lên | C6: HCM_NM_BĐT | D6: HCM_NM_BĐT_L | E6: Khu vực gần công viên đường số 4, giáp bờ sông, gần đường Chu Văn An, phường Bình Thạnh | F6: Bùi Đình Túy - HCM_NM_BĐT - Triều Lên | G6: Bùi Đình Túy - Triều Lên | H6: Bùi Đình Túy - Triều Lên (QC - Mẫu lặp hiện trường) | I6: Bùi Đình Túy - Triều Lên (QC - Mẫu trắng hiện trường) | J6: Bùi Đình Túy - Triều Lên (QC - Mẫu trắng vận chuyển) | K6: Bùi Đình Túy - Triều Lên (QC - Mẫu trắng thiết bị)
A7: Cầu Đỏ | B7: Triều Lên | C7: HCM_NM_CĐ | D7: HCM_NM_CĐ_L | E7: Khu vực Cầu Đỏ trên đường Nguyễn Xí, đoạn qua rạch Cầu Sơn | F7: Cầu Đỏ - HCM_NM_CĐ - Triều Lên | G7: Cầu Đỏ - Triều Lên | H7: Cầu Đỏ - Triều Lên (QC - Mẫu lặp hiện trường) | I7: Cầu Đỏ - Triều Lên (QC - Mẫu trắng hiện trường) | J7: Cầu Đỏ - Triều Lên (QC - Mẫu trắng vận chuyển) | K7: Cầu Đỏ - Triều Lên (QC - Mẫu trắng thiết bị)
A8: Thị Nghè 2 | B8: Triều Lên | C8: HCM_NM_TN2 | D8: HCM_NM_TN2_L | E8: Khu vực cầu Thị Nghè 2 trên đường Nguyễn Hữu Cảnh, gần Thảo Cầm Viên | F8: Thị Nghè 2 - HCM_NM_TN2 - Triều Lên | G8: Thị Nghè 2 - Triều Lên | H8: Thị Nghè 2 - Triều Lên (QC - Mẫu lặp hiện trường) | I8: Thị Nghè 2 - Triều Lên (QC - Mẫu trắng hiện trường) | J8: Thị Nghè 2 - Triều Lên (QC - Mẫu trắng vận chuyển) | K8: Thị Nghè 2 - Triều Lên (QC - Mẫu trắng thiết bị)
A9: Bùi Hữu Nghĩa | B9: Triều Lên | C9: HCM_NM_BHN | D9: HCM_NM_BHN_L | E9: Khu vực cầu Bùi Hữu Nghĩa, đoạn rạch Cầu Bông đổ ra kênh Nhiêu Lộc – Thị Nghè | F9: Bùi Hữu Nghĩa - HCM_NM_BHN - Triều Lên | G9: Bùi Hữu Nghĩa - Triều Lên | H9: Bùi Hữu Nghĩa - Triều Lên (QC - Mẫu lặp hiện trường) | I9: Bùi Hữu Nghĩa - Triều Lên (QC - Mẫu trắng hiện trường) | J9: Bùi Hữu Nghĩa - Triều Lên (QC - Mẫu trắng vận chuyển) | K9: Bùi Hữu Nghĩa - Triều Lên (QC - Mẫu trắng thiết bị)
A10: Cầu Văn Thánh | B10: Triều Lên | C10: HCM_NM_RVT | D10: HCM_NM_RVT_L | E10: Khu vực cầu Văn Thánh trên đường Điện Biên Phủ | F10: Cầu Văn Thánh - HCM_NM_RVT - Triều Lên | G10: Cầu Văn Thánh - Triều Lên | H10: Cầu Văn Thánh - Triều Lên (QC - Mẫu lặp hiện trường) | I10: Cầu Văn Thánh - Triều Lên (QC - Mẫu trắng hiện trường) | J10: Cầu Văn Thánh - Triều Lên (QC - Mẫu trắng vận chuyển) | K10: Cầu Văn Thánh - Triều Lên (QC - Mẫu trắng thiết bị)
